Workbook
Name Cargo: #REF!
Name Cargo: #REF!
Name Cargo: #REF!
Name CARRO: #REF!
Name CARRO: #REF!
Name CESAR: #REF!
Name Clase: #REF!
Name Clase: #REF!
Name Codigo: #REF!
Name Codigo: #REF!
Name División_de_verificación: #REF!
Name División_de_verificación: #REF!
Name Excentricidad: #REF!
Name Excentricidad: #REF!
Name Max: #REF!
Name Max: #REF!
Name Min: #REF!
Name Min: #REF!
Name MOTO: #REF!
Name Nombres: #REF!
Name Nombres: #REF!
Name Patrón: #REF!
Name Patrón: #REF!
Name Repetibilidad: #REF!
Name Repetibilidad: #REF!
Name Resolucion: #REF!
Name Resolucion: #REF!
Name Resolución: #REF!
Name Resolución: #REF!
Name Temperatura: #REF!
Name Temperatura: #REF!
Name U0: #REF!
Name U0: #REF!
Name Umax: #REF!
Name Umax: #REF!
Name Unidades: #REF!
Name Unidades: #REF!

Sheet DATOS GENERALES
F1: CALIBRACIÓN DE EQUIPOS VOLUMÉTRICOS ACCIONADOS POR PISTON, LC-FR-60 V13
F2: CD438-25
A4: Revisado Director Técnico, 2025-09-20 - Aprobado Gerente General, 2025-09-22
A7: Certificado de calibración No. | F7: TVO005-26A | K7: Hora inicial | O7: 0.3375
A9: Fecha de recepción: | F9: 46042 | K9: Hora final | O9: 0.36666667
A11: Fecha de calibración: | F11: 46049
A13: Información del cliente
A14: Cliente: | C14: Tecservice S.A.S. | I14: Dirección: | K14: Av 4AN No. 45-56 | P14: Ciudad: | R14: Cali
A15: Contacto: | C15: Hector Fabio Carabali Herrera | I15: Teléfono | K15: 318 712 6566 - 602 654 0608
A16: Información del instrumento | AC16: =F22 -> 0.00024
A17: Nombre: | C17: Micropipeta | H17: Fabricante: | J17: BRAND | N17: Modelo: | P17: Transferpette
A18: No. serie: | C18: 08Y7018 | H18: Código: | J18: TEC-LAB-V-03 | N18: Ubicación: | P18: N.I.
A19: lugar de calibración: | E19: Tecservice S.A.S. Laboratorio de Volumen | N19: Resolución: | P19: 1 | T19: µL | U19: =LEN(P19) -> 1
A20: Características metrológicas del instrumento
A21: Tipo de material: | D21: Plástico (polipropileno) | H21: Intervalo de medición | K21: 100 | L21: Hasta | M21: 1000 | N21: µL | O21: Densidad pesas | R21: 7.96 | S21: g/cm3
A22: Coeficiente de expansión [°C-1]: | F22: =IF(D21="","",VLOOKUP(D21,Z164:AB178,3,FALSE)) -> 0.00024 | H22: Temperatura de referencia: | M22: 20 | N22: °C | O22: EMP: | P22: =CONCATENATE("E"," ",N21) -> E µL | Q22: 8 | R22: E % | T22: 0.8 | W22: =LEN(Q22) -> 1 | X22: =W22-1 -> 0
A23: Base de Ajuste: | D23: Expulsar (Ex) | H23: Liquido de Ensayo: | K23: Agua Des-ionizada grado 3 | P23: =CONCATENATE("CV"," ",N21) -> CV µL | Q23: 3 | R23: CV % | T23: 0.3 | W23: =LEN(Q23) -> 1 | X23: =W23-1 -> 0
A24: ¿Tipo Selección Volumen ? | D24: Variable | L24: Regla de Decisión ? | P24: Especificar probabilidad de Conformidad ? | U24: ← Seleccionar
A25: ¿ Colchón de Aire ? | D25: Si | L25: =IF($N$24="Simple","Aceptación simple (ILAC G8), evaluando tanto el error sistematico como el error aleatorio,",IF($N$24="Conservadora","Declaración Binaria con zona de seguridad (ILAC G8), zona de seguridad igual a la incertidumbre expandida, evaluando tanto el error sistematico como el error aleatorio, ","N.A. No fue requeridad declaracion de conformidad.")) -> N.A. No fue requeridad declaracion de conformidad. | P25: Especificación:(Norma, SOP. Manual Fab. etc.) $
A26: ¿Las mediciones dependen de la lectura directa del volumen de salida? Ej. Buretas | E26: No | L26: =IF(T24="No","",IF(T24="N.A.","",IF(T24="","",IF($N$24="Simple"," con probabilidad de no conformidad menor al 50 %.",IF($N$24="Conservadora","con probabilidad de no conformidad menor al 2,3 %.","")))))
A27: Evaluación visual de las características de funcionamiento instrumento
A28: Características a evaluar: | J28: Cumple | M28: Observaciones
J29: Si | K29: No | L29: N.A
A30: ¿ El instrumento presenta partículas de agua ? | K30: X
A31: ¿ El instrumento esta despicado, quebrado o fisurado ? | K31: X
A32: ¿ La Lectura es legible ? | J32: X
A33: ¿ El instrumento presenta contaminación con partículas extrañas? | K33: X
F35: Trazabilidad
D36: linealidad fabricante (g) | F36: Código | J36: Descripción | P36: Fecha Cal | Q36: Vigencia
D37: 0.0002 | F37: TEC-LAB-BA-07 | J37: =VLOOKUP(F37,Trazabilidad!$T$5:$Z$14,2,FALSE) -> Balanza semimicro | P37: =VLOOKUP(F37,Trazabilidad!$T$5:$Z$14,5,FALSE) -> 45832 | Q37: =VLOOKUP(F37,Trazabilidad!$T$5:$Z$14,6,FALSE) -> 46197 | S37: =IF(Q37<TODAY(),"OJO EQ PATRON FUERA DE SERVICIO","")
D38: desves fabricante (g) | F38: TEC-LAB-PTHRI-03 | J38: =VLOOKUP(F38,Trazabilidad!$T$5:$Z$14,2,FALSE) -> Termo higrómetro barómetro digital | P38: =VLOOKUP(F38,Trazabilidad!$T$5:$Z$14,5,FALSE) -> 45343 | Q38: =VLOOKUP(F38,Trazabilidad!$T$5:$Z$14,6,FALSE) -> 46074 | S38: =IF(Q38<TODAY(),"OJO EQ PATRON FUERA DE SERVICIO","")
D39: 0.0001 | F39: TEC-LAB-TH-01 | J39: =VLOOKUP(F39,Trazabilidad!$T$5:$Z$14,2,FALSE) -> Termo higrómetro digital | P39: =VLOOKUP(F39,Trazabilidad!$T$5:$Z$14,5,FALSE) -> 45337 | Q39: =VLOOKUP(F39,Trazabilidad!$T$5:$Z$14,6,FALSE) -> 46068 | S39: =IF(Q39<TODAY(),"OJO EQ PATRON FUERA DE SERVICIO","")
D40: perdida por evaporación (g) | F40: TEC-LAB-TEM-33 | J40: =VLOOKUP(F40,Trazabilidad!$T$5:$Z$14,2,FALSE) -> Termómetro digital | P40: =VLOOKUP(F40,Trazabilidad!$T$5:$Z$14,5,FALSE) -> 45695 | Q40: =VLOOKUP(F40,Trazabilidad!$T$5:$Z$14,6,FALSE) -> 46060 | S40: =IF(Q40<TODAY(),"OJO EQ PATRON FUERA DE SERVICIO","")
D41: -2e-06 | F41: N.A. | J41: =VLOOKUP(F41,Trazabilidad!$T$5:$Z$16,2,FALSE) | P41: =VLOOKUP(F41,Trazabilidad!$T$5:$Z$16,5,FALSE) | Q41: =VLOOKUP(F41,Trazabilidad!$T$5:$Z$16,6,FALSE) | S41: =IF(Q41<TODAY(),"OJO Auxiliar FUERA DE SERVICIO","")
A43: Condiciones ambientales originales | K43: Condiciones ambientales corregidas | V43: Limites
A44: Mediciones | C44: Temperatura [°C] | F44: Humedad relativa [% hr] | I44: Presión atmosférica [hPa] | K44: Mediciones | M44: Temperatura [°C] | P44: Humedad relativa [% hr] | S44: Presión atmosférica [hPa] | V44: T. Agua | W44: T. Aire | X44: Hr | Y44: P Atm
A45: Mínimas: | C45: =IF(ISBLANK(G70),"",MIN(G70:H79,G86:H95,G102:H111,G118:H127)) -> 20.6 | F45: =IF(ISBLANK(I70),"",MIN(I70:J79,I86:J95,I102:J111,I118:J127)) -> 54.5 | I45: =IF(ISBLANK(K70),"",MIN(K70:L79,K86:L95,K102:L111,K118:L127)) -> 910 | K45: Iniciales: | M45: =IF(ISBLANK(G70),"",C45+'DATOS CORRECCIONES EQUIPOS EMPL'!AA105) -> 20.786417 | P45: =IF(ISBLANK(I70),"",F45+'DATOS CORRECCIONES EQUIPOS EMPL'!AH105) -> 54.291418 | S45: =IF(ISBLANK(K70),"",I45+'DATOS CORRECCIONES EQUIPOS EMPL'!AO105) -> 910.34413 | V45: 0.5 | W45: 0.5 | X45: 5 | Y45: 5
A46: Máximas: | C46: =IF(ISBLANK(G70),"",MAX(G70:H79,G86:H95,G102:H111,G118:H127)) -> 20.8 | F46: =IF(ISBLANK(I70),"",MAX(I70:J79,I86:J95,I102:J111,I118:J127)) -> 56 | I46: =IF(ISBLANK(K70),"",MAX(K70:L79,K86:L95,K102:L111)) -> 911 | K46: Finales: | M46: =IF(ISBLANK(G70),"",C46+'DATOS CORRECCIONES EQUIPOS EMPL'!AA106) -> 20.983065 | P46: =IF(ISBLANK(I70),"",F46+'DATOS CORRECCIONES EQUIPOS EMPL'!AH106) -> 55.900794 | S46: =IF(ISBLANK(K70),"",I46+'DATOS CORRECCIONES EQUIPOS EMPL'!AO106) -> 911.3404
A47: Variación | C47: =ABS(C45-C46) -> 0.2 | K47: Variación | M47: =ABS(M45-M46) -> 0.19664857
A48: Temperatura del dispositivo.
...

Sheet Certificado de calibración
A1: CALIBRACIÓN DE EQUIPOS VOLUMÉTRICOS ACCIONADOS POR PISTON, LC-FR-60 V13
A2: CD438-25
A4: Revisado Director Técnico, 2025-09-20 - Aprobado Gerente General, 2025-09-22
A5: CERTIFICADO DE CALIBRACIÓN | AD5: Se ajusto pie de pagina
A6: Certifícate of calibración | AD6: Se adiccion metrologo L Rios
U8: CERTIFICADO No: | X8: =IF(ISBLANK('DATOS GENERALES'!F7),"",'DATOS GENERALES'!F7) -> TVO005-26A
A9: Magnitud | C9: Volumen | U9: Certifícate number
A10: Número de páginas del certificado incluyendo anexos: Dos (2)
A11: Datos del Cliente:
A12: Solicitante: | E12: =IF(ISBLANK('DATOS GENERALES'!C14),"",CONCATENATE("",'DATOS GENERALES'!C14," ",'DATOS GENERALES'!A15," ",'DATOS GENERALES'!C15," ",'DATOS GENERALES'!I15,": ",'DATOS GENERALES'!K15)) -> Tecservice S.A.S. Contacto: Hector Fabio Carabali Herrera Teléfono: 318 712 6566 - 602 654 0608
A13: Dirección: * | E13: =IF(ISBLANK('DATOS GENERALES'!K14),"",CONCATENATE('DATOS GENERALES'!K14," - ",'DATOS GENERALES'!R14," - ","Colombia")) -> Av 4AN No. 45-56 - Cali - Colombia
A14: Datos del Instrumento:
A15: Instrumento:* | E15: =IF(ISBLANK('DATOS GENERALES'!C17),"",'DATOS GENERALES'!C17) -> Micropipeta
A16: Fabricante:* | E16: =IF(ISBLANK('DATOS GENERALES'!J17),"",'DATOS GENERALES'!J17) -> BRAND | M16: Identificación:* | R16: =IF(ISBLANK('DATOS GENERALES'!J18),"",'DATOS GENERALES'!J18) -> TEC-LAB-V-03
A17: Modelo:* | E17: =IF(ISBLANK('DATOS GENERALES'!P17),"",'DATOS GENERALES'!P17) -> Transferpette | M17: Fecha de recepción: | R17: =IF(ISBLANK('DATOS GENERALES'!F9),"",'DATOS GENERALES'!F9) -> 46042
A18: Número de serie:* | E18: =IF(ISBLANK('DATOS GENERALES'!C18),"",'DATOS GENERALES'!C18) -> 08Y7018 | M18: Fecha de calibración: | R18: =IF(ISBLANK('DATOS GENERALES'!F11),"",'DATOS GENERALES'!F11) -> 46049
A19: Ubicación:* | E19: =IF(ISBLANK('DATOS GENERALES'!P18),"",'DATOS GENERALES'!P18) -> N.I.
A23: Características Metrológicas del instrumento de medida
A24: ='DATOS GENERALES'!H21 -> Intervalo de medición | F24: =IF('DATOS GENERALES'!H21='DATOS GENERALES'!Q163,CONCATENATE('DATOS GENERALES'!K21," ",'DATOS GENERALES'!N21," ",'DATOS GENERALES'!L21," ",'DATOS GENERALES'!M21," ",'DATOS GENERALES'!N21),IF('DATOS GENERALES'!H21='DATOS GENERALES'!Q164,CONCATENATE('DATOS GENERALES'!K21," ",'DATOS GENERALES'!N21),"OJO")) -> 100 µL Hasta 1000 µL | M24: =IF(A24="Valor nominal","Punto de calibracion:","Intervalo de Calibración") -> Intervalo de Calibración | T24: =IF(ISBLANK('DATOS GENERALES'!F68),"",IF('DATOS GENERALES'!H21="Intervalo de medición",CONCATENATE('DATOS GENERALES'!F68," ",'DATOS GENERALES'!H68," Hasta "," ",'DATOS GENERALES'!M21," ",'DATOS GENERALES'!H68),IF(,'DATOS GENERALES'!H21="Valor nominal",CONCATENATE('DATOS GENERALES'!F68," ",'DATOS GENERALES'!H68)))) -> 100 µL Hasta 1000 µL
A25: Resolución: | F25: =IF(ISBLANK('DATOS GENERALES'!P19),"N.A",IF(OR('DATOS GENERALES'!P19=1,'DATOS GENERALES'!P19=2,'DATOS GENERALES'!P19=3,'DATOS GENERALES'!P19=4,'DATOS GENERALES'!P19=5),FIXED('DATOS GENERALES'!P19,0),FIXED('DATOS GENERALES'!P19,'DATOS GENERALES'!U19-2))) -> 1 | G25: =IF(ISBLANK('DATOS GENERALES'!P19),"",'DATOS GENERALES'!T19) -> µL | M25: Error máximo permitido Sistemático | T25: =IF(ISBLANK('DATOS GENERALES'!Q22),"",CONCATENATE('DATOS GENERALES'!Q22," ",'DATOS GENERALES'!N21)) -> 8 µL | U25: → | V25: =IF(ISBLANK('DATOS GENERALES'!T22),"",CONCATENATE('DATOS GENERALES'!T22," ","%")) -> 0,8 %
A26: Coeficiente de expansión: | F26: =IF(ISBLANK('DATOS GENERALES'!F22),"N.I.",'DATOS GENERALES'!F22) -> 0.00024 | H26: °C-1 | M26: Error máximo permitido Aleatorio | T26: =IF(ISBLANK('DATOS GENERALES'!Q23),"",CONCATENATE('DATOS GENERALES'!Q23," ",'DATOS GENERALES'!N21)) -> 3 µL | U26: → | V26: =IF(ISBLANK('DATOS GENERALES'!T23),"",CONCATENATE('DATOS GENERALES'!T23," ","%")) -> 0,3 %
A27: Bases de ajuste: | F27: =IF('DATOS GENERALES'!D23="","",'DATOS GENERALES'!D23) -> Expulsar (Ex) | M27: Temperatura de referencia: | T27: =IF('DATOS GENERALES'!M22="","",CONCATENATE('DATOS GENERALES'!M22," ",'DATOS GENERALES'!N22)) -> 20 °C
A28: Tipo de punta: | F28: =IF('DATOS GENERALES'!D21="","",'DATOS GENERALES'!D21) -> Plástico (polipropileno) | M28: Liquido de ensayo: | T28: =IF('DATOS GENERALES'!K23="","",'DATOS GENERALES'!K23) -> Agua Des-ionizada grado 3
A31: Este certificado expresa fielmente el resultado de las mediciones realizadas única y exclusivamente al instrumento bajo calibración, aquí relacionado. No podrá ser reproducido parcialmente sin la debida autorización del emisor, excepto cuando se reproduce en su totalidad.
A34: Este certificado es emitido de acuerdo con los requerimientos de la norma ISO/IEC 17025:2017 (Requisitos generales para la competencia de los laboratorios de ensayo y calibración). El usuario es responsable de la calibración de sus instrumentos a intervalos apropiados.
A38: Método de calibración utilizado:
A39: El equipo fue calibrado utilizando el método gravimétrico, el cual consiste en determinar el volumen de agua contenida o entregada por el recipiente.
A43: Procedimiento de calibración:
A44: LC-PR-16 Procedimiento calibración para equipos volumétricos accionados mediante pistón, norma NTC-ISO 8655-6
A47: Lugar de calibración:
A48: La calibración se realizó en las instalaciones de | I48: ='DATOS GENERALES'!E19 -> Tecservice S.A.S. Laboratorio de Volumen
A51: Descripción de la trazabilidad Metrológica
A52: Esta calibración es trazable al Sistema Internacional de Unidades (SI), a través de una cadena ininterrumpida de comparaciones, cada eslabón de la cadena esta documentado y la incertidumbre de medición ha sido estimada en cada paso.
A54: Código | E54: Descripción | K54: Marca | O54: Certificado No. | V54: Vigencia de calibración | AH54: Proxima Cal
A55: =IF(ISBLANK('DATOS GENERALES'!F37),"",'DATOS GENERALES'!F37) -> TEC-LAB-BA-07 | E55: =VLOOKUP(A55,Trazabilidad!$T$5:$Z$14,2,FALSE) -> Balanza semimicro | K55: =VLOOKUP(A55,Trazabilidad!$T$5:$Z$14,3,FALSE) -> Ohaus | O55: =IF(A55="","",'Chequeo Balanza '!J5) -> TM463-25A | V55: =VLOOKUP(A55,Trazabilidad!$T$5:$Z$14,6,FALSE) -> 46197 | AH55: 45142
A56: =IF(ISBLANK('DATOS GENERALES'!F38),"",'DATOS GENERALES'!F38) -> TEC-LAB-PTHRI-03 | E56: =VLOOKUP(A56,Trazabilidad!$T$5:$Z$14,2,FALSE) -> Termo higrómetro barómetro digital | K56: =VLOOKUP(A56,Trazabilidad!$T$5:$Z$14,3,FALSE) -> Control Company | O56: =VLOOKUP(A56,Trazabilidad!$T$5:$Z$14,4,FALSE) -> TLM-P-4418 | V56: =VLOOKUP(A56,Trazabilidad!$T$5:$Z$14,6,FALSE) -> 46074
A57: =IF(ISBLANK('DATOS GENERALES'!F39),"",'DATOS GENERALES'!F39) -> TEC-LAB-TH-01 | E57: =VLOOKUP(A57,Trazabilidad!$T$5:$Z$14,2,FALSE) -> Termo higrómetro digital | K57: =VLOOKUP(A57,Trazabilidad!$T$5:$Z$14,3,FALSE) -> Full Gauge | O57: =VLOOKUP(A57,Trazabilidad!$T$5:$Z$14,4,FALSE) -> TLM-TH-1859C | V57: =VLOOKUP(A57,Trazabilidad!$T$5:$Z$14,6,FALSE) -> 46068
A58: =IF(ISBLANK('DATOS GENERALES'!F40),"",'DATOS GENERALES'!F40) -> TEC-LAB-TEM-33 | E58: =VLOOKUP(A58,Trazabilidad!$T$5:$Z$14,2,FALSE) -> Termómetro digital | K58: =VLOOKUP(A58,Trazabilidad!$T$5:$Z$14,3,FALSE) -> Control company | O58: =VLOOKUP(A58,Trazabilidad!$T$5:$Z$14,4,FALSE) -> TLM-T-3124 | V58: =VLOOKUP(A58,Trazabilidad!$T$5:$Z$14,6,FALSE) -> 46060 | AH58: 44972
AH59: 44948
AH60: 44944
...

Sheet Trazabilidad
AC3: Deriva
A4: Equipo | B4: TEC-LAB-BA-07 | E4: Valor nominal (g) | H4: Valor Promedio de la Indicacion del Instrumento (g ) | L4: Error (g) | P4: Incertidumbre expandida (g) | Q4: ± Incertidumbre excentricidad (g) | T4: código | U4: descripción | V4: Marca | W4: Certificado No | X4: Fecha de calibración | Y4: F. Proxima | Z4: Calibrado Por | AA4: Resolucion 1 | AB4: Resolucion 2 | AD4: Cal X | AE4: Cal X-1 | AF4: Cal X-2 | AG4: Cal X
A5: Intervalo | B5: 0 a 50 g | E5: 0 | H5: 0 | L5: 0 | P5: 2e-05 | Q5: 2.8867513e-05 | T5: TEC-LAB-BA-07 | U5: Balanza semimicro | V5: Ohaus | W5: =IF('Chequeo Balanza '!K13<=50,B9,B24) -> TM463-25A | X5: =IF(W5=B9,B10,IF(W5=B24,B25,"revisar")) -> 45832 | Y5: =IF(W5=B9,B11,IF(W5=B24,B26,"revisar")) -> 46197 | Z5: Tecservice S.A.S | AA5: 1e-05 | AB5: 0.001 | AC5: =AE5-AD5 -> 0
A6: Descripción: | B6: =U5 -> Balanza semimicro | E6: 0.009999 | H6: 0.01 | L6: 1e-06 | P6: 2e-05 | T6: TEC-LAB-BA-04 | U6: Balanza | V6: Mettler Toledo | W6: TM465-25A | X6: 45832 | Y6: 46197 | Z6: Tecservice S.A.S | AA6: 0.001 | AB6: 0.001 | AC6: =AE6-AD6 -> 0
A7: Marca: | B7: =V5 -> Ohaus | E7: 4.999988 | H7: 4.99999 | L7: 2e-06 | P7: 3.2e-05 | T7: TEC-LAB-BA-05 | U7: Balanza | V7: Mettler Toledo | W7: TM466-25A | X7: 45832 | Y7: 46197 | Z7: Tecservice S.A.S | AA7: 0.01 | AB7: 0.01 | AC7: =AE7-AD7 -> 0
A8: calibrado por: | E8: 10.000015 | H8: 10 | L8: -1.5e-05 | P8: 3.9e-05 | T8: TEC-LAB-BA-08 | U8: Bascula | V8: Mettler Toledo | W8: TM467-25A | X8: 45832 | Y8: 46197 | Z8: Tecservice S.A.S | AA8: 0.1 | AB8: 0.1 | AC8: =AE8-AD8 -> 0
A9: certificado No: | B9: TM463-25A | E9: 15.000003 | H9: 14.99999 | L9: -1.3e-05 | P9: 6.3e-05 | T9: N.A. | U9: =IF($T$9="N.A.","","") | V9: =IF($T$9="N.A.","","") | W9: =IF($T$9="N.A.","","") | X9: =IF($T$9="N.A.","","") | Y9: =IF($T$9="N.A.","","") | Z9: =IF($T$9="N.A.","","") | AC9: =AE9-AD9 -> 0
A10: fecha de calibración: | B10: 45832 | E10: 19.999998 | H10: 20.00001 | L10: 1.2e-05 | P10: 5.2e-05 | T10: TEC-LAB-TEM-33 | U10: Termómetro digital | V10: Control company | W10: TLM-T-3124 | X10: 45695 | Y10: 46060 | Z10: Tesla | AA10: 0.01 | AB10: 0.01 | AC10: =AE10-AD10 -> -0.146 | AD10: 0.156 | AE10: 0.01
A11: Prox. Calibracion: | B11: 46197 | E11: 24.999986 | H11: 24.99999 | L11: 4e-06 | P11: 7.7e-05 | T11: TEC-LAB-TEM-11 | U11: Termómetro digital | V11: Oakton | W11: TLM-T-2258 | X11: 45359 | Y11: 45724 | Z11: Tesla | AA11: 0.01 | AB11: 0.1 | AC11: =AE11-AD11 -> 0
E12: 30.000013 | H12: 30.00001 | L12: -3e-06 | P12: 8.6e-05 | T12: TEC-LAB-TH-01 | U12: Termo higrómetro digital | V12: Full Gauge | W12: TLM-TH-1859C | X12: 45337 | Y12: 46068 | Z12: Tesla | AA12: 0.1 | AB12: 0.1 | AC12: =AE12-AD12 -> 0
E13: 35 | H13: 34.99999 | L13: -1e-05 | P13: 0.00011 | T13: TEC-LAB-PTHRI-01 | U13: Termo higrómetro barómetro digital | V13: Control Company | W13: TLM-P-3401 | X13: 45082 | Y13: 45813 | Z13: Tesla | AA13: 1 | AB13: 1 | AC13: =AE13-AD13 -> 0
E14: 40.00001 | H14: 40.00001 | L14: 0 | P14: 0.0001 | T14: TEC-LAB-PTHRI-03 | U14: Termo higrómetro barómetro digital | V14: Control Company | W14: TLM-P-4418 | X14: 45343 | Y14: 46074 | Z14: Tesla | AA14: 0.1 | AB14: 0.1 | AC14: =AE14-AD14 -> 0
E15: 45 | H15: 45.00002 | L15: 2e-05 | P15: 0.00013 | T15: TEC-LAB-LI-01 | U15: Pie de rey digital | V15: Mitutoyo | W15: L27531 | X15: 45356 | Y15: 45905 | Z15: SUMINCOL | AA15: 0.1 | AB15: 0.1 | AC15: =AE15-AD15 -> 0
E16: 50 | H16: 50.00002 | L16: 2e-05 | P16: 9e-05 | T16: TEC-LAB-LI-02 | U16: Pie de rey digital | V16: Shahe | W16: L28887 | X16: 45505 | Y16: 46054 | Z16: SUMINCOL | AA16: 0.1 | AB16: 0.1 | AC16: =AE16-AD16 -> 0
T17: TEC-LAB-PTHRI-01 | U17: Termo higrómetro barómetro digital | V17: Control Company | W17: TLM-TH-1251 | X17: 45078 | Y17: 45809 | Z17: Tesla | AA17: 0.1 | AB17: 0.1 | AC17: =AE17-AD17 -> 0
A19: Equipo | B19: TEC-LAB-BA-07 | E19: Valor nominal (g) | H19: Valor Promedio de la Indicacion del Instrumento (g ) | L19: Error (g) | P19: Incertidumbre expandida (g) | Q19: ± Incertidumbre excentricidad (g)
A20: Intervalo | B20: 0 a 210 g | E20: 0 | H20: 0 | L20: 0 | P20: 8.3e-05 | Q20: 0.00011431535
A21: Descripción: | B21: Balanza semimicro | E21: 51.00004 | H21: 51 | L21: -4e-05 | P21: 0.00012
A22: Marca: | B22: Ohaus | E22: 65.00005 | H22: 65 | L22: -5e-05 | P22: 0.00015
A23: calibrado por: | E23: 85.00005 | H23: 85 | L23: -5e-05 | P23: 0.0002
A24: certificado No: | B24: TM464-25A | E24: 99.99999 | H24: 100 | L24: 1e-05 | P24: 0.00016
A25: fecha de calibración: | B25: 45832 | E25: 119.99999 | H25: 120.0001 | L25: 0.00011 | P25: 0.0002
A26: Prox. Calibracion: | B26: 46197 | E26: 130.00002 | H26: 130 | L26: -2e-05 | P26: 0.00023
E27: 150.00002 | H27: 150.0001 | L27: 8e-05 | P27: 0.00023
E28: 170.00003 | H28: 170 | L28: -3e-05 | P28: 0.00027
E29: 180.00005 | H29: 180.0001 | L29: 5e-05 | P29: 0.0003
E30: 209.99997 | H30: 209.9999 | L30: -7e-05 | P30: 0.00031
E31: 219.99996 | H31: 219.9999 | L31: -6e-05 | P31: 0.00033
A34: Equipo | B34: TEC-LAB-BA-04 | E34: Valor nominal (g) | H34: Valor Promedio de la Indicacion del Instrumento (g ) | L34: Error (g) | P34: Incertidumbre expandida (g) | Q34: ± Incertidumbre excentricidad (g)
A35: Intervalo | B35: 0 a 1200 g | E35: 0 | H35: 0 | L35: 0 | P35: 0.0013 | Q35: 0.00069282032
A36: Descripción: | B36: Balanza | E36: 0.1 | H36: 0.1 | L36: 0 | P36: 0.0013
A37: Marca: | B37: Mettler | E37: 120 | H37: 120.001 | L37: 0.001 | P37: 0.0014
A38: calibrado por: | E38: 249.9999 | H38: 250 | L38: 0.0001 | P38: 0.0015
A39: certificado No: | B39: =W6 -> TM465-25A | E39: 349.9999 | H39: 350 | L39: 0.0001 | P39: 0.0016
A40: fecha de calibración: | B40: =X6 -> 45832 | E40: 500 | H40: 500 | L40: 0 | P40: 0.0019
A41: Prox. Calibracion: | B41: =Y6 -> 46197 | E41: 600.0001 | H41: 600 | L41: -0.0001 | P41: 0.0021
E42: 700 | H42: 700 | L42: 0 | P42: 0.0023
E43: 800 | H43: 800 | L43: 0 | P43: 0.0026
E44: 999.9993 | H44: 1000 | L44: 0.0007 | P44: 0.0031
E45: 1099.9993 | H45: 1100 | L45: 0.0007 | P45: 0.0034
...

Sheet Calculo P Conformidad
K2: Límite de tolerancia superior único | X2: Otro Info
X3: https://youtu.be/WtRRT4YwAyM?si=vyZ179gciL1UpRil
X4: Minuto | Y4: 2:01:45
M6: = | N6: Pc
K7: Intervalos de tolerancia bilaterales con FDP normales
AF42: PC | AH42: PC
K43: Valor de referencia | L43: EMP | M43: Tu | N43: TL | O43: y | P43: u | Q43: U | R43: k | S43: Pcu | U43: PcL | W43: PC | Y43: PC | AB43: Ztu | AC43: =CONCATENATE("ɸ(",ROUND(AB44,2)," ) ") -> ɸ(1,67 ) | AD43: ZTL | AE43: =CONCATENATE("ɸ(",ROUND(AD44,2)," ) ") -> ɸ(-1,67 ) | AF43: =CONCATENATE("ɸ(",ROUND(AB44,2)," ) - ","ɸ(",ROUND(AD44,2)," ) ") -> ɸ(1,67 ) - ɸ(-1,67 )
K44: 1500 | L44: 0.2 | M44: 1500.2 | N44: 1499.8 | O44: 1500 | P44: 0.12 | Q44: =P44/R44 -> 0.058536585 | R44: 2.05 | S44: =_xlfn.NORM.DIST(M44,O44,P44,1) -> 0.95220965 | U44: =_xlfn.NORM.DIST(N44,O44,P44,1) -> 0.047790352 | W44: =S44-U44 -> 0.9044193 | X44: =W44 -> 0.9044193 | Y44: =1-W44 -> 0.095580705 | Z44: =Y44 -> 0.095580705 | AB44: =(M44-O44)/P44 -> 1.6666667 | AC44: =_xlfn.NORM.S.DIST(AB44,1) -> 0.95220965 | AD44: =(N44-O44)/P44 -> -1.6666667 | AE44: =_xlfn.NORM.S.DIST(AD44,1) -> 0.047790352 | AF44: =AC44-AE44 -> 0.9044193 | AG44: =AF44 -> 0.9044193 | AH44: =1-AF44 -> 0.095580705 | AI44: =AH44 -> 0.095580705
K46: Valor de referencia | L46: EMP | M46: Tu | N46: TL | O46: y | P46: s | S46: Pcu | U46: PcL | W46: PC | Y46: PC
K47: 1500 | L47: 0.2 | M47: 1500.2 | N47: 1499.8 | O47: 1500 | P47: 0.12 | S47: =_xlfn.NORM.DIST(M47,O47,P47,1) -> 0.95220965 | U47: =_xlfn.NORM.DIST(N47,O47,P47,1) -> 0.047790352 | W47: =S47-U47 -> 0.9044193 | X47: =W47 -> 0.9044193 | Y47: =1-W47 -> 0.095580705 | Z47: =Y47 -> 0.095580705
J52: Prueba con datos de calibraciones
O54: TEC-LAB-BA-07
N55: Indicación | O55: Corrección | P55: U | Q55: EMP | AM55: PC | AO55: PC
N56: g | O56: g | P56: g | Q56: g | R56: Valor de referencia | S56: EMP | U56: Tu | W56: TL | X56: y | Y56: U | Z56: uc | AA56: k | AB56: Pcu | AC56: PcL | AD56: PC | AF56: PC | AI56: Ztu | AJ56: =CONCATENATE("ɸ(",ROUND(AI57,2)," ) ") -> ɸ(9,62 ) | AK56: ZTL | AL56: =CONCATENATE("ɸ(",ROUND(AK57,2)," ) ") -> ɸ(-9,62 ) | AM56: =CONCATENATE("ɸ(",ROUND(AI57,2)," ) - ","ɸ(",ROUND(AK57,2)," ) ") -> ɸ(9,62 ) - ɸ(-9,62 )
N57: 50 | O57: 9e-05 | P57: 0.00021 | Q57: 0.001 | R57: =N57+O57 -> 50.00009 | S57: =Q57 -> 0.001 | U57: =R57+S57 -> 50.00109 | W57: =R57-S57 -> 49.99909 | X57: =R57 -> 50.00009 | Y57: =P57 -> 0.00021 | Z57: =Y57/AA57 -> 0.0001039604 | AA57: 2.02 | AB57: =_xlfn.NORM.DIST(U57,X57,Z57,1) -> 1 | AC57: =_xlfn.NORM.DIST(W57,X57,Z57,1) -> 3.3221743e-22 | AD57: =AB57-AC57 -> 1 | AE57: =AD57 -> 1 | AF57: =1-AD57 -> 0 | AG57: =AF57 -> 0 | AI57: =(U57-X57)/Z57 -> 9.6190476 | AJ57: =_xlfn.NORM.S.DIST(AI57,1) -> 1 | AK57: =(W57-X57)/Z57 -> -9.6190476 | AL57: =_xlfn.NORM.S.DIST(AK57,1) -> 3.3221743e-22 | AM57: =AJ57-AL57 -> 1 | AN57: =AM57 -> 1 | AO57: =1-AM57 -> 0 | AP57: =AO57 -> 0
N58: 65 | O58: 0.00013 | P58: 0.00022 | Q58: 0.001 | R58: =N58+O58 -> 65.00013 | S58: =Q58 -> 0.001 | U58: =R58+S58 -> 65.00113 | W58: =R58-S58 -> 64.99913 | X58: =R58 -> 65.00013 | Y58: =P58 -> 0.00022 | Z58: =Y58/AA58 -> 0.00010891089 | AA58: 2.02 | AB58: =_xlfn.NORM.DIST(U58,X58,Z58,1) -> 1 | AC58: =_xlfn.NORM.DIST(W58,X58,Z58,1) -> 2.1193653e-20 | AD58: =AB58-AC58 -> 1 | AE58: =AD58 -> 1 | AF58: =1-AD58 -> 0 | AG58: =AF58 -> 0 | AI58: =(U58-X58)/Z58 -> 9.1818182 | AJ58: =_xlfn.NORM.S.DIST(AI58,1) -> 1 | AK58: =(W58-X58)/Z58 -> -9.1818182 | AL58: =_xlfn.NORM.S.DIST(AK58,1) -> 2.1193653e-20 | AM58: =AJ58-AL58 -> 1 | AN58: =AM58 -> 1 | AO58: =1-AM58 -> 0 | AP58: =AO58 -> 0
N59: 80 | O59: 0.00018 | P59: 0.00023 | Q59: 0.001 | R59: =N59+O59 -> 80.00018 | S59: =Q59 -> 0.001 | U59: =R59+S59 -> 80.00118 | W59: =R59-S59 -> 79.99918 | X59: =R59 -> 80.00018 | Y59: =P59 -> 0.00023 | Z59: =Y59/AA59 -> 0.00011386139 | AA59: 2.02 | AB59: =_xlfn.NORM.DIST(U59,X59,Z59,1) -> 1 | AC59: =_xlfn.NORM.DIST(W59,X59,Z59,1) -> 7.9863045e-19 | AD59: =AB59-AC59 -> 1 | AE59: =AD59 -> 1 | AF59: =1-AD59 -> 0 | AG59: =AF59 -> 0 | AI59: =(U59-X59)/Z59 -> 8.7826087 | AJ59: =_xlfn.NORM.S.DIST(AI59,1) -> 1 | AK59: =(W59-X59)/Z59 -> -8.7826087 | AL59: =_xlfn.NORM.S.DIST(AK59,1) -> 7.9863045e-19 | AM59: =AJ59-AL59 -> 1 | AN59: =AM59 -> 1 | AO59: =1-AM59 -> 0 | AP59: =AO59 -> 0
N60: 95 | O60: 0.00024 | P60: 0.00025 | Q60: 0.001 | R60: =N60+O60 -> 95.00024 | S60: =Q60 -> 0.001 | U60: =R60+S60 -> 95.00124 | W60: =R60-S60 -> 94.99924 | X60: =R60 -> 95.00024 | Y60: =P60 -> 0.00025 | Z60: =Y60/AA60 -> 0.00012376238 | AA60: 2.02 | AB60: =_xlfn.NORM.DIST(U60,X60,Z60,1) -> 1 | AC60: =_xlfn.NORM.DIST(W60,X60,Z60,1) -> 3.2383387e-16 | AD60: =AB60-AC60 -> 1 | AE60: =AD60 -> 1 | AF60: =1-AD60 -> 0 | AG60: =AF60 -> 0 | AI60: =(U60-X60)/Z60 -> 8.08 | AJ60: =_xlfn.NORM.S.DIST(AI60,1) -> 1 | AK60: =(W60-X60)/Z60 -> -8.08 | AL60: =_xlfn.NORM.S.DIST(AK60,1) -> 3.2383387e-16 | AM60: =AJ60-AL60 -> 1 | AN60: =AM60 -> 1 | AO60: =1-AM60 -> 0 | AP60: =AO60 -> 0
N61: 110 | O61: 0.00013 | P61: 0.00023 | Q61: 0.001 | R61: =N61+O61 -> 110.00013 | S61: =Q61 -> 0.001 | U61: =R61+S61 -> 110.00113 | W61: =R61-S61 -> 109.99913 | X61: =R61 -> 110.00013 | Y61: =P61 -> 0.00023 | Z61: =Y61/AA61 -> 0.00011386139 | AA61: 2.02 | AB61: =_xlfn.NORM.DIST(U61,X61,Z61,1) -> 1 | AC61: =_xlfn.NORM.DIST(W61,X61,Z61,1) -> 7.9863045e-19 | AD61: =AB61-AC61 -> 1 | AE61: =AD61 -> 1 | AF61: =1-AD61 -> 0 | AG61: =AF61 -> 0 | AI61: =(U61-X61)/Z61 -> 8.7826087 | AJ61: =_xlfn.NORM.S.DIST(AI61,1) -> 1 | AK61: =(W61-X61)/Z61 -> -8.7826087 | AL61: =_xlfn.NORM.S.DIST(AK61,1) -> 7.9863045e-19 | AM61: =AJ61-AL61 -> 1 | AN61: =AM61 -> 1 | AO61: =1-AM61 -> 0 | AP61: =AO61 -> 0
N62: 130 | O62: 0.0002 | P62: 0.00026 | Q62: 0.001 | R62: =N62+O62 -> 130.0002 | S62: =Q62 -> 0.001 | U62: =R62+S62 -> 130.0012 | W62: =R62-S62 -> 129.9992 | X62: =R62 -> 130.0002 | Y62: =P62 -> 0.00026 | Z62: =Y62/AA62 -> 0.00012871287 | AA62: 2.02 | AB62: =_xlfn.NORM.DIST(U62,X62,Z62,1) -> 1 | AC62: =_xlfn.NORM.DIST(W62,X62,Z62,1) -> 3.9482095e-15 | AD62: =AB62-AC62 -> 1 | AE62: =AD62 -> 1 | AF62: =1-AD62 -> 7.9936058e-15 | AG62: =AF62 -> 7.9936058e-15 | AI62: =(U62-X62)/Z62 -> 7.7692308 | AJ62: =_xlfn.NORM.S.DIST(AI62,1) -> 1 | AK62: =(W62-X62)/Z62 -> -7.7692308 | AL62: =_xlfn.NORM.S.DIST(AK62,1) -> 3.9482095e-15 | AM62: =AJ62-AL62 -> 1 | AN62: =AM62 -> 1 | AO62: =1-AM62 -> 7.9936058e-15 | AP62: =AO62 -> 7.9936058e-15
N63: 149.9999 | O63: 0.00029 | P63: 0.00026 | Q63: 0.001 | R63: =N63+O63 -> 150.00019 | S63: =Q63 -> 0.001 | U63: =R63+S63 -> 150.00119 | W63: =R63-S63 -> 149.99919 | X63: =R63 -> 150.00019 | Y63: =P63 -> 0.00026 | Z63: =Y63/AA63 -> 0.00012871287 | AA63: 2.02 | AB63: =_xlfn.NORM.DIST(U63,X63,Z63,1) -> 1 | AC63: =_xlfn.NORM.DIST(W63,X63,Z63,1) -> 3.9482095e-15 | AD63: =AB63-AC63 -> 1 | AE63: =AD63 -> 1 | AF63: =1-AD63 -> 7.9936058e-15 | AG63: =AF63 -> 7.9936058e-15 | AI63: =(U63-X63)/Z63 -> 7.7692308 | AJ63: =_xlfn.NORM.S.DIST(AI63,1) -> 1 | AK63: =(W63-X63)/Z63 -> -7.7692308 | AL63: =_xlfn.NORM.S.DIST(AK63,1) -> 3.9482095e-15 | AM63: =AJ63-AL63 -> 1 | AN63: =AM63 -> 1 | AO63: =1-AM63 -> 7.9936058e-15 | AP63: =AO63 -> 7.9936058e-15
N64: 164.9999 | O64: 0.00034 | P64: 0.0003 | Q64: 0.001 | R64: =N64+O64 -> 165.00024 | S64: =Q64 -> 0.001 | U64: =R64+S64 -> 165.00124 | W64: =R64-S64 -> 164.99924 | X64: =R64 -> 165.00024 | Y64: =P64 -> 0.0003 | Z64: =Y64/AA64 -> 0.00014851485 | AA64: 2.02 | AB64: =_xlfn.NORM.DIST(U64,X64,Z64,1) -> 1 | AC64: =_xlfn.NORM.DIST(W64,X64,Z64,1) -> 8.2909791e-12 | AD64: =AB64-AC64 -> 1 | AE64: =AD64 -> 1 | AF64: =1-AD64 -> 1.6582069e-11 | AG64: =AF64 -> 1.6582069e-11 | AI64: =(U64-X64)/Z64 -> 6.7333333 | AJ64: =_xlfn.NORM.S.DIST(AI64,1) -> 1 | AK64: =(W64-X64)/Z64 -> -6.7333333 | AL64: =_xlfn.NORM.S.DIST(AK64,1) -> 8.2909791e-12 | AM64: =AJ64-AL64 -> 1 | AN64: =AM64 -> 1 | AO64: =1-AM64 -> 1.6582069e-11 | AP64: =AO64 -> 1.6582069e-11
N65: 179.9999 | O65: 0.00038 | P65: 0.00031 | Q65: 0.001 | R65: =N65+O65 -> 180.00028 | S65: =Q65 -> 0.001 | U65: =R65+S65 -> 180.00128 | W65: =R65-S65 -> 179.99928 | X65: =R65 -> 180.00028 | Y65: =P65 -> 0.00031 | Z65: =Y65/AA65 -> 0.00015346535 | AA65: 2.02 | AB65: =_xlfn.NORM.DIST(U65,X65,Z65,1) -> 1 | AC65: =_xlfn.NORM.DIST(W65,X65,Z65,1) -> 3.6072461e-11 | AD65: =AB65-AC65 -> 1 | AE65: =AD65 -> 1 | AF65: =1-AD65 -> 7.2144957e-11 | AG65: =AF65 -> 7.2144957e-11 | AI65: =(U65-X65)/Z65 -> 6.516129 | AJ65: =_xlfn.NORM.S.DIST(AI65,1) -> 1 | AK65: =(W65-X65)/Z65 -> -6.516129 | AL65: =_xlfn.NORM.S.DIST(AK65,1) -> 3.6072461e-11 | AM65: =AJ65-AL65 -> 1 | AN65: =AM65 -> 1 | AO65: =1-AM65 -> 7.2144957e-11 | AP65: =AO65 -> 7.2144957e-11
N66: 195 | O66: 0.00034 | P66: 0.00034 | Q66: 0.001 | R66: =N66+O66 -> 195.00034 | S66: =Q66 -> 0.001 | U66: =R66+S66 -> 195.00134 | W66: =R66-S66 -> 194.99934 | X66: =R66 -> 195.00034 | Y66: =P66 -> 0.00034 | Z66: =Y66/AA66 -> 0.00016831683 | AA66: 2.02 | AB66: =_xlfn.NORM.DIST(U66,X66,Z66,1) -> 1 | AC66: =_xlfn.NORM.DIST(W66,X66,Z66,1) -> 1.4149189e-09 | AD66: =AB66-AC66 -> 1 | AE66: =AD66 -> 1 | AF66: =1-AD66 -> 2.8298377e-09 | AG66: =AF66 -> 2.8298377e-09 | AI66: =(U66-X66)/Z66 -> 5.9411765 | AJ66: =_xlfn.NORM.S.DIST(AI66,1) -> 1 | AK66: =(W66-X66)/Z66 -> -5.9411765 | AL66: =_xlfn.NORM.S.DIST(AK66,1) -> 1.4149189e-09 | AM66: =AJ66-AL66 -> 1 | AN66: =AM66 -> 1 | AO66: =1-AM66 -> 2.8298377e-09 | AP66: =AO66 -> 2.8298377e-09
N67: 210 | O67: 0.00019 | P67: 0.0003 | Q67: 0.001 | R67: =N67+O67 -> 210.00019 | S67: =Q67 -> 0.001 | U67: =R67+S67 -> 210.00119 | W67: =R67-S67 -> 209.99919 | X67: =R67 -> 210.00019 | Y67: =P67 -> 0.0003 | Z67: =Y67/AA67 -> 0.00014851485 | AA67: 2.02 | AB67: =_xlfn.NORM.DIST(U67,X67,Z67,1) -> 1 | AC67: =_xlfn.NORM.DIST(W67,X67,Z67,1) -> 8.2909791e-12 | AD67: =AB67-AC67 -> 1 | AE67: =AD67 -> 1 | AF67: =1-AD67 -> 1.6582069e-11 | AG67: =AF67 -> 1.6582069e-11 | AI67: =(U67-X67)/Z67 -> 6.7333333 | AJ67: =_xlfn.NORM.S.DIST(AI67,1) -> 1 | AK67: =(W67-X67)/Z67 -> -6.7333333 | AL67: =_xlfn.NORM.S.DIST(AK67,1) -> 8.2909791e-12 | AM67: =AJ67-AL67 -> 1 | AN67: =AM67 -> 1 | AO67: =1-AM67 -> 1.6582069e-11 | AP67: =AO67 -> 1.6582069e-11
C69: Simple
C70: Conservadora | M70: Sistematico | O70: ='DATOS GENERALES'!C17 -> Micropipeta | P70: =CONCATENATE('DATOS GENERALES'!K21," a ",'DATOS GENERALES'!M21," ", 'DATOS GENERALES'!N21) -> 100 a 1000 µL | Q70: ='DATOS GENERALES'!F7 -> TVO005-26A | R70: con w=0
N71: Indicación | O71: Error | P71: U | Q71: EMP=TL | R71: Regla Decisión Simple | T71: [EMP] | U71: TU | V71: [-EMP] | W71: TL | AM71: PC | AO71: PC | AV71: PC | AX71: PC
B72: =S72 -> TL | C72: =IF(AND(B73=C73,B74=C74,B75=C75),"AL=TL",T72) -> AL=TL | D72: =IF(AND(D73=E73,E74=D74,E75=D75),"- AL= -TL",V72) -> - AL= -TL | E72: =CONCATENATE("-",S72) -> -TL | F72: Pc | G72: Conformidad | H72: Pc | I72: Lim inf | J72: Lim Sup | N72: ='DATOS GENERALES'!H68 -> µL | O72: =N72 -> µL | P72: =O72 -> µL | Q72: =P72 -> µL | R72: Volumen calculado | S72: TL | T72: AL | U72: TL | V72: AL- | W72: TL- | X72: y | Y72: U | Z72: uc | AA72: k | AB72: Pcu | AC72: PcL | AD72: PC | AF72: PC | AI72: Ztu | AJ72: =CONCATENATE("ɸ(",ROUND(AI73,2)," ) ") -> ɸ(15,24 ) | AK72: ZTL | AL72: =CONCATENATE("ɸ(",ROUND(AK73,2)," ) ") -> ɸ(-34,46 ) | AM72: =CONCATENATE("ɸ(",ROUND(AI73,2)," ) - ","ɸ(",ROUND(AK73,2)," ) ") -> ɸ(15,24 ) - ɸ(-34,46 ) | AR72: Ztu | AS72: =CONCATENATE("ɸ(",ROUND(AR73,2)," ) ") -> ɸ(15,24 ) | AT72: ZTL | AU72: =CONCATENATE("ɸ(",ROUND(AT73,2)," ) ") -> ɸ(-34,46 ) | AV72: =CONCATENATE("ɸ(",ROUND(AR73,2)," ) - ","ɸ(",ROUND(AT73,2)," ) ") -> ɸ(15,24 ) - ɸ(-34,46 )
B73: =IF('DATOS GENERALES'!$N$24=$C$70,S81,S73) -> 8 | C73: =IF('DATOS GENERALES'!$N$24=$C$70,T81,T73) -> 8 | D73: =IF('DATOS GENERALES'!$N$24=$C$70,V81,V73) -> -8 | E73: =IF('DATOS GENERALES'!$N$24=$C$70,-S81,-S73) -> -8 | F73: =IF('DATOS GENERALES'!$N$24=$C$70,AG81,AG73) -> 0 | G73: ='DATOS GENERALES'!S83 -> N.A. | H73: =IF(G73="Cumple",F73,"") | I73: =-Q73+P73 -> -7.3501988 | J73: =Q73-P73 -> 7.3501988 | K73: =O73>I73 -> TRUE | L73: =O73<J73 -> TRUE | N73: ='DATOS GENERALES'!F68 -> 100 | O73: ='DATOS GENERALES'!S82 -> 3.0935875 | P73: ='DATOS GENERALES'!V80 -> 0.6498012 | Q73: ='DATOS GENERALES'!Q22 -> 8 | R73: =N73+O73 -> 103.09359 | S73: =Q73 -> 8 | T73: =S73 -> 8 | U73: =N73+S73 -> 108 | V73: =-S73 -> -8 | W73: =N73-S73 -> 92 | X73: =R73 -> 103.09359 | Y73: =P73 -> 0.6498012 | Z73: =Y73/AA73 -> 0.32195785 | AA73: ='Certificado de calibración'!Y92 -> 2.0182803 | AB73: =_xlfn.NORM.DIST(U73,X73,Z73,1) -> 1 | AC73: =_xlfn.NORM.DIST(W73,X73,Z73,1) -> 1.7903759e-260 | AD73: =AB73-AC73 -> 1 | AE73: =AD73 -> 1 | AF73: =1-AD73 -> 0 | AG73: =AF73 -> 0 | AI73: =(U73-X73)/Z73 -> 15.239301 | AJ73: =_xlfn.NORM.S.DIST(AI73,1) -> 1 | AK73: =(W73-X73)/Z73 -> -34.456646 | AL73: =_xlfn.NORM.S.DIST(AK73,1) -> 1.7903759e-260 | AM73: =AJ73-AL73 -> 1 | AN73: =AM73 -> 1 | AO73: =1-AM73 -> 0 | AP73: =AO73 -> 0 | AR73: =(U73-X73)/Z73 -> 15.239301 | AS73: =NORMSDIST(AR73) -> 1 | AT73: =(W73-X73)/Z73 -> -34.456646 | AU73: =NORMSDIST(AT73) -> 1.7903759e-260 | AV73: =AS73-AU73 -> 1 | AW73: =AV73 -> 1 | AX73: =1-AV73 -> 0 | AY73: =AX73 -> 0
B74: =IF('DATOS GENERALES'!$N$24=$C$70,S82,S74) -> 8 | C74: =IF('DATOS GENERALES'!$N$24=$C$70,T82,T74) -> 8 | D74: =IF('DATOS GENERALES'!$N$24=$C$70,V82,V74) -> -8 | E74: =IF('DATOS GENERALES'!$N$24=$C$70,-S82,-S74) -> -8 | F74: =IF('DATOS GENERALES'!$N$24=$C$70,AG82,AG74) -> 0 | G74: ='DATOS GENERALES'!S99 -> N.A. | H74: =IF(G74="Cumple",F74,"") | I74: =-Q74+P74 -> -7.0642764 | J74: =Q74-P74 -> 7.0642764 | K74: =O74>I74 -> TRUE | L74: =O74<J74 -> TRUE | N74: ='DATOS GENERALES'!F84 -> 500 | O74: ='DATOS GENERALES'!S98 -> 3.4518238 | P74: ='DATOS GENERALES'!V96 -> 0.9357236 | Q74: ='DATOS GENERALES'!Q22 -> 8 | R74: =N74+O74 -> 503.45182 | S74: =Q74 -> 8 | T74: =S74 -> 8 | U74: =N74+S74 -> 508 | V74: =-S74 -> -8 | W74: =N74-S74 -> 492 | X74: =R74 -> 503.45182 | Y74: =P74 -> 0.9357236 | Z74: =Y74/AA74 -> 0.46583076 | AA74: ='Certificado de calibración'!Y93 -> 2.0087201 | AB74: =_xlfn.NORM.DIST(U74,X74,Z74,1) -> 1 | AC74: =_xlfn.NORM.DIST(W74,X74,Z74,1) -> 9.4463773e-134 | AD74: =AB74-AC74 -> 1 | AE74: =AD74 -> 1 | AF74: =1-AD74 -> 0 | AG74: =AF74 -> 0 | AI74: =(U74-X74)/Z74 -> 9.7635806 | AJ74: =_xlfn.NORM.S.DIST(AI74,1) -> 1 | AK74: =(W74-X74)/Z74 -> -24.583657 | AL74: =_xlfn.NORM.S.DIST(AK74,1) -> 9.4463773e-134 | AM74: =AJ74-AL74 -> 1 | AN74: =AM74 -> 1 | AO74: =1-AM74 -> 0 | AP74: =AO74 -> 0 | AR74: =(U74-X74)/Z74 -> 9.7635806 | AS74: =NORMSDIST(AR74) -> 1 | AT74: =(W74-X74)/Z74 -> -24.583657 | AU74: =NORMSDIST(AT74) -> 9.4463773e-134 | AV74: =AS74-AU74 -> 1 | AW74: =AV74 -> 1 | AX74: =1-AV74 -> 0 | AY74: =AX74 -> 0
B75: =IF('DATOS GENERALES'!$N$24=$C$70,S83,S75) -> 8 | C75: =IF('DATOS GENERALES'!$N$24=$C$70,T83,T75) -> 8 | D75: =IF('DATOS GENERALES'!$N$24=$C$70,V83,V75) -> -8 | E75: =IF('DATOS GENERALES'!$N$24=$C$70,-S83,-S75) -> -8 | F75: =IF('DATOS GENERALES'!$N$24=$C$70,AG83,AG75) -> 4.4999263e-06 | G75: ='DATOS GENERALES'!S115 -> N.A. | H75: =IF(G75="Cumple",F75,"") | I75: =-Q75+P75 -> -6.3868851 | J75: =Q75-P75 -> 6.3868851 | K75: =O75>I75 -> TRUE | L75: =O75<J75 -> TRUE | N75: ='DATOS GENERALES'!F100 -> 1000 | O75: ='DATOS GENERALES'!S114 -> 4.4438304 | P75: ='DATOS GENERALES'!V112 -> 1.6131149 | Q75: ='DATOS GENERALES'!Q22 -> 8 | R75: =N75+O75 -> 1004.4438 | S75: =Q75 -> 8 | T75: =S75 -> 8 | U75: =N75+S75 -> 1008 | V75: =-S75 -> -8 | W75: =N75-S75 -> 992 | X75: =R75 -> 1004.4438 | Y75: =P75 -> 1.6131149 | Z75: =Y75/AA75 -> 0.80095621 | AA75: ='Certificado de calibración'!Y94 -> 2.0139864 | AB75: =_xlfn.NORM.DIST(U75,X75,Z75,1) -> 0.9999955 | AC75: =_xlfn.NORM.DIST(W75,X75,Z75,1) -> 9.8643644e-55 | AD75: =AB75-AC75 -> 0.9999955 | AE75: =AD75 -> 0.9999955 | AF75: =1-AD75 -> 4.4999263e-06 | AG75: =AF75 -> 4.4999263e-06 | AI75: =(U75-X75)/Z75 -> 4.4399052 | AJ75: =_xlfn.NORM.S.DIST(AI75,1) -> 0.9999955 | AK75: =(W75-X75)/Z75 -> -15.536218 | AL75: =_xlfn.NORM.S.DIST(AK75,1) -> 9.8643644e-55 | AM75: =AJ75-AL75 -> 0.9999955 | AN75: =AM75 -> 0.9999955 | AO75: =1-AM75 -> 4.4999263e-06 | AP75: =AO75 -> 4.4999263e-06 | AR75: =(U75-X75)/Z75 -> 4.4399052 | AS75: =NORMSDIST(AR75) -> 0.9999955 | AT75: =(W75-X75)/Z75 -> -15.536218 | AU75: =NORMSDIST(AT75) -> 9.8643644e-55 | AV75: =AS75-AU75 -> 0.9999955 | AW75: =AV75 -> 0.9999955 | AX75: =1-AV75 -> 4.4999263e-06 | AY75: =AX75 -> 4.4999263e-06
G76: Maxima Pc = | H76: =MAX(H73:H75) -> 0
O78: =O70 -> Micropipeta | P78: =P70 -> 100 a 1000 µL | Q78: =Q70 -> TVO005-26A | R78: con w=U | U78: Se hace con Tu y TL siempre, de lo contario castigas el sistema
N79: Indicación | O79: Error | P79: U | Q79: EMP | R79: Regla Decisión Conservadora | T79: [EMP-U] | U79: V+[EMP-U] | V79: [-EMP+U] | W79: V-[EMP-U] | AM79: PC | AO79: PC | AV79: PC | AX79: PC
N80: =N72 -> µL | O80: =O72 -> µL | P80: =P72 -> µL | Q80: =Q72 -> µL | R80: Volumen calculado | S80: EMP | T80: =U80 -> TU | U80: TU | V80: =W80 -> TL | W80: TL | X80: y | Y80: U | Z80: uc | AA80: k | AB80: Pcu | AC80: PcL | AD80: PC | AF80: PC | AI80: Ztu | AJ80: =CONCATENATE("ɸ(",ROUND(AI81,2)," ) ") -> ɸ(13,22 ) | AK80: ZTL | AL80: =CONCATENATE("ɸ(",ROUND(AK81,2)," ) ") -> ɸ(-32,44 ) | AM80: =CONCATENATE("ɸ(",ROUND(AI81,2)," ) - ","ɸ(",ROUND(AK81,2)," ) ") -> ɸ(13,22 ) - ɸ(-32,44 ) | AR80: Ztu | AS80: =CONCATENATE("ɸ(",ROUND(AR81,2)," ) ") -> ɸ(13,22 ) | AT80: ZTL | AU80: =CONCATENATE("ɸ(",ROUND(AT81,2)," ) ") -> ɸ(-32,44 ) | AV80: =CONCATENATE("ɸ(",ROUND(AR81,2)," ) - ","ɸ(",ROUND(AT81,2)," ) ") -> ɸ(13,22 ) - ɸ(-32,44 )
N81: =N73 -> 100 | O81: =O73 -> 3.0935875 | P81: =P73 -> 0.6498012 | Q81: =Q73 -> 8 | R81: =N81+O81 -> 103.09359 | S81: =Q81 -> 8 | T81: =S81-P81 -> 7.3501988 | U81: =N81+S81-P81 -> 107.3502 | V81: =-S81+P81 -> -7.3501988 | W81: =N81-S81+P81 -> 92.649801 | X81: =R81 -> 103.09359 | Y81: =P81 -> 0.6498012 | Z81: =Y81/AA81 -> 0.32195785 | AA81: ='Certificado de calibración'!Y92 -> 2.0182803 | AB81: =_xlfn.NORM.DIST(U81,X81,Z81,1) -> 1 | AC81: =_xlfn.NORM.DIST(W81,X81,Z81,1) -> 3.9517303e-231 | AD81: =AB81-AC81 -> 1 | AE81: =AD81 -> 1 | AF81: =1-AD81 -> 0 | AG81: =AF81 -> 0 | AI81: =(U81-X81)/Z81 -> 13.22102 | AJ81: =_xlfn.NORM.S.DIST(AI81,1) -> 1 | AK81: =(W81-X81)/Z81 -> -32.438365 | AL81: =_xlfn.NORM.S.DIST(AK81,1) -> 3.9517303e-231 | AM81: =AJ81-AL81 -> 1 | AN81: =AM81 -> 1 | AO81: =1-AM81 -> 0 | AP81: =AO81 -> 0 | AR81: =(U81-X81)/Z81 -> 13.22102 | AS81: =NORMSDIST(AR81) -> 1 | AT81: =(W81-X81)/Z81 -> -32.438365 | AU81: =NORMSDIST(AT81) -> 3.9517303e-231 | AV81: =AS81-AU81 -> 1 | AW81: =AV81 -> 1 | AX81: =1-AV81 -> 0 | AY81: =AX81 -> 0
N82: =N74 -> 500 | O82: =O74 -> 3.4518238 | P82: =P74 -> 0.9357236 | Q82: =Q74 -> 8 | R82: =N82+O82 -> 503.45182 | S82: =Q82 -> 8 | T82: =S82-P82 -> 7.0642764 | U82: =N82+S82-P82 -> 507.06428 | V82: =-S82+P82 -> -7.0642764 | W82: =N82-S82+P82 -> 492.93572 | X82: =R82 -> 503.45182 | Y82: =P82 -> 0.9357236 | Z82: =Y82/AA82 -> 0.46583076 | AA82: ='Certificado de calibración'!Y93 -> 2.0087201 | AB82: =_xlfn.NORM.DIST(U82,X82,Z82,1) -> 1 | AC82: =_xlfn.NORM.DIST(W82,X82,Z82,1) -> 3.8209104e-113 | AD82: =AB82-AC82 -> 1 | AE82: =AD82 -> 1 | AF82: =1-AD82 -> 4.4408921e-15 | AG82: =AF82 -> 4.4408921e-15 | AI82: =(U82-X82)/Z82 -> 7.7548606 | AJ82: =_xlfn.NORM.S.DIST(AI82,1) -> 1 | AK82: =(W82-X82)/Z82 -> -22.574937 | AL82: =_xlfn.NORM.S.DIST(AK82,1) -> 3.8209104e-113 | AM82: =AJ82-AL82 -> 1 | AN82: =AM82 -> 1 | AO82: =1-AM82 -> 4.4408921e-15 | AP82: =AO82 -> 4.4408921e-15 | AR82: =(U82-X82)/Z82 -> 7.7548606 | AS82: =NORMSDIST(AR82) -> 1 | AT82: =(W82-X82)/Z82 -> -22.574937 | AU82: =NORMSDIST(AT82) -> 3.8209104e-113 | AV82: =AS82-AU82 -> 1 | AW82: =AV82 -> 1 | AX82: =1-AV82 -> 4.4408921e-15 | AY82: =AX82 -> 4.4408921e-15
N83: =N75 -> 1000 | O83: =O75 -> 4.4438304 | P83: =P75 -> 1.6131149 | Q83: =Q75 -> 8 | R83: =N83+O83 -> 1004.4438 | S83: =Q83 -> 8 | T83: =S83-P83 -> 6.3868851 | U83: =N83+S83-P83 -> 1006.3869 | V83: =-S83+P83 -> -6.3868851 | W83: =N83-S83+P83 -> 993.61311 | X83: =R83 -> 1004.4438 | Y83: =P83 -> 1.6131149 | Z83: =Y83/AA83 -> 0.80095621 | AA83: ='Certificado de calibración'!Y94 -> 2.0139864 | AB83: =_xlfn.NORM.DIST(U83,X83,Z83,1) -> 0.99236516 | AC83: =_xlfn.NORM.DIST(W83,X83,Z83,1) -> 5.7807159e-42 | AD83: =AB83-AC83 -> 0.99236516 | AE83: =AD83 -> 0.99236516 | AF83: =1-AD83 -> 0.0076348436 | AG83: =AF83 -> 0.0076348436 | AI83: =(U83-X83)/Z83 -> 2.4259188 | AJ83: =_xlfn.NORM.S.DIST(AI83,1) -> 0.99236516 | AK83: =(W83-X83)/Z83 -> -13.522232 | AL83: =_xlfn.NORM.S.DIST(AK83,1) -> 5.7807159e-42 | AM83: =AJ83-AL83 -> 0.99236516 | AN83: =AM83 -> 0.99236516 | AO83: =1-AM83 -> 0.0076348436 | AP83: =AO83 -> 0.0076348436 | AR83: =(U83-X83)/Z83 -> 2.4259188 | AS83: =NORMSDIST(AR83) -> 0.99236516 | AT83: =(W83-X83)/Z83 -> -13.522232 | AU83: =NORMSDIST(AT83) -> 5.7807159e-42 | AV83: =AS83-AU83 -> 0.99236516 | AW83: =AV83 -> 0.99236516 | AX83: =1-AV83 -> 0.0076348436 | AY83: =AX83 -> 0.0076348436
U84: Cuando lo haces con los limites solo consideras que los valores medicos esten dentro de dichos límites, pero el % de aceptación o de falsa axeptación se calucula siempre con Tu y TL (EMP)
...

Sheet INCERTIDUMBRE DE LA MEDIDA
A1: PLANTILLA DE INCERTIDUMMBRE LC-FR-08 V4
D2: CD388-25
A4: Revisado Director Técnico, 2025-02-03 - Aprobado Gerente General, 2025-02-05
A6: =CONCATENATE("PRESUPUESTO PARA ",'Certificado de calibración'!A1," ",'Certificado de calibración'!D2," v",'Certificado de calibración'!K2) -> PRESUPUESTO PARA CALIBRACIÓN DE EQUIPOS VOLUMÉTRICOS ACCIONADOS POR PISTON, LC-FR-60 V13 v
A7: EVALUACION DE INCERTIDUMBRE
A8: No. | B8: Magnitud de Entrada Xi Fuente de Incertidumbre | D8: Valor estimado Xi | E8: Fuente de Informacion | F8: Unidades | G8: Incertidumbre Origen | H8: Tipo de Distrubucion | I8: incertidumbre Estandar (Xi) | K8: Coeficiente de Sensibilidad Ci | M8: Contribucion ui (y) ml | N8: contribucion ui (y)^2 | O8: Grados de Libertad V | P8: Ui ⁴ | Q8: 1 | R8: CONSTANTES | U8: 1
A9: 0 | B9: Volumen Calibrado a 20 °C | D9: ='DATOS GENERALES'!F68 -> 100 | R9: a0 | S9: =3.4847858/10 -> 0.34847858
A10: 1 | B10: Masa de agua (g) | D10: ='DATOS CORRECCIONES EQUIPOS EMPL'!BB26 -> 0.10281223 | R10: a1 | S10: =9.1748/1000 -> 0.0091748
A11: 1.1 | C11: Lectura recipiente lleno | D11: =AVERAGE('DATOS CORRECCIONES EQUIPOS EMPL'!C14:C23) -> 25.783285 | R11: a2 | S11: =6.2492/100 -> 0.062492
C12: Resolucion | E12: Balanza | F12: g | G12: ='Chequeo Balanza '!$F$12 -> 1e-05 | H12: Rectangular | I12: =G12/SQRT(12) -> 2.8867513e-06 | K12: Rectangular | L12: =+('DATOS GENERALES'!$Q$80/1000)/(D11-D13) -> 1.0025431 | M12: =I12*L12 -> 2.8940928e-06 | N12: =M12^2 -> 8.375773e-12 | O12: 100 | P12: =N12^2/O12 -> 7.0153574e-25 | Q12: Kell | R12: a3 | S12: =- 5.23/100000 -> -5.23e-05
A13: 1.2 | C13: Lectura recipiente vacio | D13: =AVERAGE('DATOS CORRECCIONES EQUIPOS EMPL'!A14:A23) -> 25.680453 | Q13: TANAKA | R13: Cte | S13: 273.15
C14: Resolucion | E14: Balanza | F14: g | G14: ='Chequeo Balanza '!$F$13 -> 1e-05 | H14: Rectangular | I14: =G14/SQRT(12) -> 2.8867513e-06 | K14: Rectangular | L14: =+L12 -> 1.0025431 | M14: =I14*L14 -> 2.8940928e-06 | N14: =M14^2 -> 8.375773e-12 | O14: 100 | P14: =N14^2/O14 -> 7.0153574e-25 | R14: a2Ta+a3*P | S14: =+S11*D25+S12*D33 -> -0.047610998
R15: Exp(a2Ta+a3*P) | S15: =+EXP(S14) -> 0.95350463
A16: 1.3 | C16: Calibracion recipiente vacio | E16: Certificado | F16: g | G16: =IF('Chequeo Balanza '!$N$5='Chequeo Balanza '!$L$6,VLOOKUP('Chequeo Balanza '!$K$12,'INCERTIDUMBRE DE LA MEDIDA'!$R$31:$T$42,3,TRUE),VLOOKUP('Chequeo Balanza '!$K$12,'INCERTIDUMBRE DE LA MEDIDA'!$R$20:$T$30,3,TRUE)) -> 5.3e-05 | H16: normal, k=2 | I16: =G16/2 -> 2.65e-05 | K16: cm³/g | L16: =+L12 -> 1.0025431 | M16: =I16*L16 -> 2.6567393e-05 | N16: =M16^2 -> 7.0582639e-10 | O16: 50 | P16: =N16^2/O16 -> 9.963818e-21 | R16: 273,15+ta | S16: =273.15+D25 -> 273.15
A17: 1.4 | C17: Calibracion recipiente lleno | E17: Certificado | F17: g | G17: =IF('Chequeo Balanza '!$N$5='Chequeo Balanza '!$L$6,VLOOKUP('Chequeo Balanza '!$K$13,'INCERTIDUMBRE DE LA MEDIDA'!$R$31:$T$42,3,TRUE),VLOOKUP('Chequeo Balanza '!$K$13,'INCERTIDUMBRE DE LA MEDIDA'!$R$20:$T$30,3,TRUE)) -> 9.1e-05 | H17: normal, k=2 | I17: =G17/2 -> 4.55e-05 | K17: cm³/g | L17: =+L12 -> 1.0025431 | M17: =I17*L17 -> 4.5615713e-05 | N17: =M17^2 -> 2.0807933e-09 | O17: 50 | P17: =N17^2/O17 -> 8.6594015e-20
A18: 1.5 | C18: linealidad | E18: fabricante | F18: g | G18: =+'DATOS GENERALES'!$D$37 -> 0.0002 | H18: Rectangular | I18: =G18/SQRT(12) -> 5.7735027e-05 | K18: Rectangular | L18: =+L16 -> 1.0025431 | M18: =I18*L18 -> 5.7881856e-05 | N18: =M18^2 -> 3.3503092e-09 | O18: 50 | P18: =N18^2/O18 -> 2.2449144e-19 | Q18: coeficiente de kell
A19: 1.6 | C19: desviacion estandar | E19: fabricante | F19: g | G19: =+'DATOS GENERALES'!$D$39 -> 0.0001 | H19: Rectangular | I19: =G19/SQRT(12) -> 2.8867513e-05 | K19: Rectangular | L19: =+L16 -> 1.0025431 | M19: =I19*L19 -> 2.8940928e-05 | N19: =M19^2 -> 8.375773e-10 | O19: 50 | P19: =N19^2/O19 -> 1.4030715e-20 | Q19: =+(0.0632693-(2*(0.00852329*'DATOS GENERALES'!$E$80))+(3*(0.00006943248*0.00852329*'DATOS GENERALES'!$E$80^2))-(4*(0.0000003821216*'DATOS GENERALES'!$E$80^3)))/1000 -> -0.00030455159 | R19: Valor nominal | S19: Error | T19: Incertidumbre
A20: 1.7 | C20: deriva | E20: mediciones | F20: g | G20: =+G16 -> 5.3e-05 | H20: Rectangular | I20: =G20/SQRT(12) -> 1.5299782e-05 | K20: Rectangular | L20: =+L19 -> 1.0025431 | M20: =I20*L20 -> 1.5338692e-05 | N20: =M20^2 -> 2.3527546e-10 | O20: 51 | P20: =N20^2/O20 -> 1.0853832e-21 | R20: ='Chequeo Balanza '!U11 -> 0 | S20: ='Chequeo Balanza '!V11 -> 0 | T20: ='Chequeo Balanza '!W11 -> 1.6e-05
A21: 2 | C21: densidad del aire (g/cm³) | D21: ='DATOS GENERALES'!M80 -> 0.0010724139 | R21: ='Chequeo Balanza '!U12 -> 1 | S21: ='Chequeo Balanza '!V12 -> 8e-05 | T21: ='Chequeo Balanza '!W12 -> 2.1e-05
B22: temperatura del aire (g/cm3) | D22: =AVERAGE('DATOS CORRECCIONES EQUIPOS EMPL'!G14:G23) -> 20.983065 | R22: ='Chequeo Balanza '!U13 -> 2 | S22: ='Chequeo Balanza '!V13 -> -1.3e-05 | T22: ='Chequeo Balanza '!W13 -> 2.5e-05
R23: ='Chequeo Balanza '!U14 -> 3 | S23: ='Chequeo Balanza '!V14 -> 7e-06 | T23: ='Chequeo Balanza '!W14 -> 3.8e-05
A24: 2.1 | C24: Ecuacion | D24: =0.00068 -> 0.00068 | E24: CIPM | F24: g/cm³ | G24: =D21*D24 -> 7.2924143e-07 | H24: Rectangular | I24: =D24/SQRT(3) -> 0.00039259818 | L24: =('DATOS GENERALES'!$Q$80/1000)*((1/('INCERTIDUMBRE DE LA MEDIDA'!D37-'INCERTIDUMBRE DE LA MEDIDA'!D21))-((1/('INCERTIDUMBRE DE LA MEDIDA'!D43-'INCERTIDUMBRE DE LA MEDIDA'!D21)))) -> 0.090451 | M24: =I24*L24 -> 3.5510898e-05 | N24: =M24^2 -> 1.2610239e-09 | O24: 100 | P24: =N24^2/O24 -> 1.5901813e-20 | R24: ='Chequeo Balanza '!U15 -> 4 | S24: ='Chequeo Balanza '!V15 -> 1.1e-05 | T24: ='Chequeo Balanza '!W15 -> 4.3e-05
A25: 2.2 | C25: Termometro de aire (°C) | R25: ='Chequeo Balanza '!U16 -> 5 | S25: ='Chequeo Balanza '!V16 -> 0 | T25: ='Chequeo Balanza '!W16 -> 3.1e-05
C26: calibracion | E26: Certificado | F26: °C | G26: ='DATOS CORRECCIONES EQUIPOS EMPL'!AB26 -> 0.27974015 | H26: normal, k=2 | I26: =G26/2 -> 0.13987007 | K26: =+K22 -> 0 | L26: =((((-0.00252*D29*(D22+273.15))-(0.34844*D33+D29*(-0.00252*D22+273.15)))/(D22+273.15)^2)/1000)*('DATOS GENERALES'!$Q$80/1000)*((1/('INCERTIDUMBRE DE LA MEDIDA'!D37-'INCERTIDUMBRE DE LA MEDIDA'!D21))-((1/('INCERTIDUMBRE DE LA MEDIDA'!D43-'INCERTIDUMBRE DE LA MEDIDA'!D21)))) -> -1.6004372e-05 | M26: =I26*L26 -> -2.2385328e-06 | N26: =M26^2 -> 5.0110289e-12 | O26: 50 | P26: =N26^2/O26 -> 5.0220821e-25 | R26: ='Chequeo Balanza '!U17 -> 10 | S26: ='Chequeo Balanza '!V17 -> -8e-06 | T26: ='Chequeo Balanza '!W17 -> 3.7e-05
C27: Gradiente (°C) | E27: Mediciones | F27: °C | G27: =MIN('DATOS CORRECCIONES EQUIPOS EMPL'!G14:G23)-MAX('DATOS CORRECCIONES EQUIPOS EMPL'!G14:G23) -> 0 | H27: Rectangular | I27: =G27/SQRT(12) -> 0 | K27: =+K22 -> 0 | L27: =+L26 -> -1.6004372e-05 | M27: =I27*L27 -> 0 | N27: =M27^2 -> 0 | O27: 100 | P27: =N27^2/O27 -> 0 | R27: ='Chequeo Balanza '!U18 -> 20 | S27: ='Chequeo Balanza '!V18 -> 1.5e-05 | T27: ='Chequeo Balanza '!W18 -> 5.3e-05
C28: Resolucion | E28: Intrumento | F28: °C | G28: =Trazabilidad!AA12 -> 0.1 | H28: Rectangular | I28: =G28/SQRT(12) -> 0.028867513 | K28: =+K22 -> 0 | L28: =+L26 -> -1.6004372e-05 | M28: =I28*L28 -> -4.6200644e-07 | N28: =M28^2 -> 2.1344995e-13 | O28: 100 | P28: =N28^2/O28 -> 4.556088e-28 | R28: ='Chequeo Balanza '!U19 -> 30 | S28: ='Chequeo Balanza '!V19 -> -1.3e-05 | T28: ='Chequeo Balanza '!W19 -> 8.6e-05
A29: 2.3 | B29: Humedad (%) | D29: =AVERAGE('DATOS CORRECCIONES EQUIPOS EMPL'!I14:I23) -> 54.742541 | R29: ='Chequeo Balanza '!U20 -> 40 | S29: ='Chequeo Balanza '!V20 -> -2e-05 | T29: ='Chequeo Balanza '!W20 -> 0.0001
C30: calibracion | E30: Certificado | F30: % | G30: ='DATOS CORRECCIONES EQUIPOS EMPL'!AI26 -> 0.7610712 | H30: normal, k=2 | I30: =G30/2 -> 0.3805356 | K30: cm³/% | L30: =('DATOS GENERALES'!Q80/1000)*(((1/(D37-D21))-(1/(D43-D21))))*(((-0.00252*D22+0.020582)/(D22+273.15))/1000) -> -9.9313705e-09 | M30: =I30*L30 -> -3.77924e-09 | N30: =M30^2 -> 1.4282655e-17 | O30: 50 | P30: =N30^2/O30 -> 4.0798847e-36 | R30: ='Chequeo Balanza '!U21 -> 50 | S30: ='Chequeo Balanza '!V21 -> 3.1e-05 | T30: ='Chequeo Balanza '!W21 -> 9.1e-05
C31: Gradiente (%) | E31: Medicion | F31: % | G31: =MIN('DATOS CORRECCIONES EQUIPOS EMPL'!I14:I23)-MAX('DATOS CORRECCIONES EQUIPOS EMPL'!I14:I23) -> -0.8590278 | H31: Rectangular | I31: =G31/SQRT(12) -> -0.24797997 | K31: cm³/% | L31: =+L30 -> -9.9313705e-09 | M31: =I31*L31 -> 2.4627809e-09 | N31: =M31^2 -> 6.0652899e-18 | O31: 100 | P31: =N31^2/O31 -> 3.6787741e-37 | R31: ='Chequeo Balanza '!U22 -> 0 | S31: ='Chequeo Balanza '!V22 -> 0 | T31: ='Chequeo Balanza '!W22 -> 0
C32: Resolucion | E32: Intrumento | F32: % | G32: =Trazabilidad!AB12 -> 0.1 | H32: Rectangular | I32: =G32/SQRT(12) -> 0.028867513 | K32: cm³/% | L32: =+L30 -> -9.9313705e-09 | M32: =I32*L32 -> -2.8669397e-10 | N32: =M32^2 -> 8.2193433e-20 | O32: 100 | P32: =N32^2/O32 -> 6.7557604e-41 | R32: ='Chequeo Balanza '!U23 -> 51 | S32: ='Chequeo Balanza '!V23 -> 7e-05 | T32: ='Chequeo Balanza '!W23 -> 0.00011
A33: 2.4 | B33: Presion (hPa) | D33: =AVERAGE('DATOS CORRECCIONES EQUIPOS EMPL'!K14:K23) -> 910.34413 | R33: ='Chequeo Balanza '!U24 -> 55 | S33: ='Chequeo Balanza '!V24 -> 6e-05 | T33: ='Chequeo Balanza '!W24 -> 0.00012
C34: calibracion | E34: Certificado | F34: hPa | G34: ='DATOS CORRECCIONES EQUIPOS EMPL'!AP26 -> 0.44000001 | H34: normal, k=2 | I34: =G34/2 -> 0.22 | K34: cm³/hPa | L34: =('DATOS GENERALES'!Q80/1000)*(((1/(D37-D21))-(1/(D43-D21))))*((0.34844/(D22+273.15))/1000) -> 1.0715132e-07 | M34: =I34*L34 -> 2.3573291e-08 | N34: =M34^2 -> 5.5570005e-16 | O34: 50 | P34: =N34^2/O34 -> 6.1760509e-33 | R34: ='Chequeo Balanza '!U25 -> 60 | S34: ='Chequeo Balanza '!V25 -> 6e-05 | T34: ='Chequeo Balanza '!W25 -> 0.00013
C35: gradiente (hPa) | E35: Medicion | F35: hPa | G35: =MIN('DATOS CORRECCIONES EQUIPOS EMPL'!K14:K23)-MAX('DATOS CORRECCIONES EQUIPOS EMPL'!K14:K23) -> 0 | H35: Rectangular | I35: =G35/SQRT(12) -> 0 | K35: cm³/hPa | L35: =+L34 -> 1.0715132e-07 | M35: =I35*L35 -> 0 | N35: =M35^2 -> 0 | O35: 100 | P35: =N35^2/O35 -> 0 | R35: ='Chequeo Balanza '!U26 -> 70 | S35: ='Chequeo Balanza '!V26 -> 0.00023 | T35: ='Chequeo Balanza '!W26 -> 0.00013
C36: Resolucion | E36: Intrumento | F36: hPa | G36: =Trazabilidad!AA13 -> 1 | H36: Rectangular | I36: =G36/SQRT(12) -> 0.28867513 | K36: cm³/hPa | L36: =+L34 -> 1.0715132e-07 | M36: =I36*L36 -> 3.0931922e-08 | N36: =M36^2 -> 9.5678381e-16 | O36: 100 | P36: =N36^2/O36 -> 9.1543525e-33 | R36: ='Chequeo Balanza '!U27 -> 100 | S36: ='Chequeo Balanza '!V27 -> 0.0002 | T36: ='Chequeo Balanza '!W27 -> 0.00014
A37: 3 | B37: Densidad del agua (g/cm³) | D37: ='DATOS GENERALES'!O80 -> 0.99806853 | R37: ='Chequeo Balanza '!U28 -> 105 | S37: ='Chequeo Balanza '!V28 -> 9e-05 | T37: ='Chequeo Balanza '!W28 -> 0.00016
A38: 3.1 | C38: Ecuacion (g/cm³) | E38: TANAKA | F38: g/cm³ | G38: =IF(E38="kell",SQRT((SQRT(G40^2+G41^2+G42^2)*Q19)^2),0.00000083) -> 8.3e-07 | H38: Rectangular | I38: =IF(E38="kell",G38/SQRT(3),G38/2) -> 4.15e-07 | K38: cm³/°C | L38: =IF(E38="Kell",-(('DATOS GENERALES'!$A$80-'DATOS GENERALES'!$C$80)/('DATOS GENERALES'!$O$80^2))*'DATOS GENERALES'!U80,((-'DATOS GENERALES'!Q80/1000)/(D37-D21))) -> -0.1034042 | M38: =I38*L38 -> -4.2912744e-08 | N38: =M38^2 -> 1.8415036e-15 | O38: 100 | P38: =N38^2/O38 -> 3.3911354e-32 | R38: ='Chequeo Balanza '!U29 -> 110 | S38: ='Chequeo Balanza '!V29 -> 0.00019 | T38: ='Chequeo Balanza '!W29 -> 0.00016
C39: Termometro de Agua (°C) | D39: =AVERAGE('DATOS CORRECCIONES EQUIPOS EMPL'!E14:E23) -> 20.658299 | R39: ='Chequeo Balanza '!U30 -> 120 | S39: ='Chequeo Balanza '!V30 -> 0.00026 | T39: ='Chequeo Balanza '!W30 -> 0.00018
C40: calibracion | E40: Certificado | F40: °C | G40: ='DATOS CORRECCIONES EQUIPOS EMPL'!U26 -> 0.054 | H40: normal, k=2 | I40: =G40/2 -> 0.027 | K40: cm³/°C | L40: =((-'DATOS GENERALES'!Q80/1000)/(D37-D21))*(0.99997495/522528.9)*(((D39-3.983035)^2*(D39+301.797)/(D39+69.34881)^2)-((D39-3.983035)^2/(D39+69.34881))-(2*(D39-3.983035)*(D39+301.797)/(D39+69.34881))) -> 2.2064706e-05 | M40: =I40*L40 -> 5.9574706e-07 | N40: =M40^2 -> 3.5491456e-13 | O40: 50 | P40: =N40^2/O40 -> 2.5192869e-27 | R40: ='Chequeo Balanza '!U31 -> 150 | S40: ='Chequeo Balanza '!V31 -> 0.00027 | T40: ='Chequeo Balanza '!W31 -> 0.0002 | V40: 1
C41: Gradiente (°C) | E41: Medicion | F41: °C | G41: =MIN('DATOS CORRECCIONES EQUIPOS EMPL'!E14:E23)-MAX('DATOS CORRECCIONES EQUIPOS EMPL'!E14:E23) -> -0.07002362 | H41: Rectangular | I41: =G41/SQRT(12) -> -0.020214078 | K41: cm³/°C | L41: =+L40 -> 2.2064706e-05 | M41: =I41*L41 -> -4.4601768e-07 | N41: =M41^2 -> 1.9893177e-13 | O41: 100 | P41: =N41^2/O41 -> 3.9573851e-28 | R41: ='Chequeo Balanza '!U32 -> 200 | S41: ='Chequeo Balanza '!V32 -> 0.00024 | T41: ='Chequeo Balanza '!W32 -> 0.00024
C42: Resolucion | E42: Intrumento | F42: °C | G42: =Trazabilidad!AA10 -> 0.01 | H42: Rectangular | I42: =G42/SQRT(12) -> 0.0028867513 | K42: cm³/°C | L42: =+L41 -> 2.2064706e-05 | M42: =I42*L42 -> 6.369532e-08 | N42: =M42^2 -> 4.0570937e-15 | O42: 100 | P42: =N42^2/O42 -> 1.646001e-31 | R42: ='Chequeo Balanza '!U33 -> 220 | S42: ='Chequeo Balanza '!V33 -> 0.0001 | T42: ='Chequeo Balanza '!W33 -> 0.00028
...

Sheet DATOS CORRECCIONES EQUIPOS EMPL
A1: DATOS DE ENTRADA EQUIPOS EMPLEADOS PARA LA CALIBRACION
A2: PATRON UTILIZADO | C2: IDENTIFICACIÓN | D2: F CALIBRACIÓN | E2: RESOLUCIÓN | F2: UNIDADES | G2: CORECCION SEGÚN CERTIFICADO | I2: UNIDADADES | J2: INCERTIDUMBRE EXPANDIDA SEGÚN CERTIFICADO | L2: UNIDADES | M2: OBSERVACIONES | P2: IDENTIFICACIÓN | Q2: FECHA DE LA PROXIMA CALIBRACIÓN | R2: RESOLUCIÓN BAJO | S2: RESOLUCIÓN ALTA | T2: UNIDADES | U2: CORECCION SEGÚN CERTIFICADO | V2: INCERTIDUMBRE EXPANDIDA SEGÚN CERTIFICADO BAJA | W2: INCERTIDUMBRE EXPANDIDA SEGÚN CERTIFICADO ALTA | Y2: código | Z2: descripción | AA2: calibrado por | AB2: certificado No | AC2: fecha de calibración
A3: BALANZA PARA MEDICION CARGA MÍNIMA | C3: ='DATOS GENERALES'!F37 -> TEC-LAB-BA-07 | D3: ='Certificado de calibración'!V55 -> 46197 | E3: 1e-05 | F3: g | G3: 2e-05 | I3: g | J3: 3.4e-05 | L3: g | P3: TEC-LAB-BA-07 | Q3: 45142 | R3: 1e-05 | S3: 0.0001 | T3: g | U3: 2e-05 | V3: 3.4e-05 | W3: 0.002 | Y3: =[1]Trazabilidad!T5 -> TEC-LAB-BA-07 | Z3: =[1]Trazabilidad!U5 -> Balanza semimicro | AA3: =[1]Trazabilidad!Z5 -> Tecservice S.A.S | AB3: =[1]Trazabilidad!W5 -> TM704-23A | AC3: =[1]Trazabilidad!X5 -> 45184
A4: BALANZA PARA MEDICION CARGA MÁXIMA | C4: =C3 -> TEC-LAB-BA-07 | D4: =D3 -> 46197 | E4: 1e-05 | F4: g | G4: 0.0001 | I4: g | J4: 0.002 | L4: g | P4: TEC-LAB-BA-04 | Q4: 44936 | R4: 0.001 | S4: 0.001 | T4: g | U4: 0.002 | V4: 0.00098 | W4: 0.0048 | Y4: =[1]Trazabilidad!T6 -> TEC-LAB-BA-04 | Z4: =[1]Trazabilidad!U6 -> Balanza | AA4: =[1]Trazabilidad!Z6 -> Detecto | AB4: =[1]Trazabilidad!W6 -> 56948-C | AC4: =[1]Trazabilidad!X6 -> 45202
A5: TERMÓMETRO PARA MEDICION EN EL AGUA | C5: ='DATOS GENERALES'!F40 -> TEC-LAB-TEM-33 | D5: ='Certificado de calibración'!V58 -> 46060 | E5: 0.01 | F5: ⁰C | G5: -0.164 | I5: ⁰C | J5: 0.036 | L5: ⁰C | P5: TEC-LAB-BA-05 | Q5: 44937 | R5: 0.01 | S5: 0.01 | T5: g | U5: 0.02 | V5: 0.0082 | W5: 0.033 | Y5: =[1]Trazabilidad!T7 -> TEC-LAB-BA-05 | Z5: =[1]Trazabilidad!U7 -> Balanza | AA5: =[1]Trazabilidad!Z7 -> Tecservice S.A.S | AB5: =[1]Trazabilidad!W7 -> TM708-23A | AC5: =[1]Trazabilidad!X7 -> 45184
A6: HIGROMETRO PAR MEDICION DE HUMEDAD RELATIVA | C6: ='DATOS GENERALES'!F38 -> TEC-LAB-PTHRI-03 | D6: ='Certificado de calibración'!V56 -> 46074 | E6: 1 | F6: %Hr | G6: -5.3 | I6: %Hr | J6: 1 | L6: %Hr | P6: TEC-LAB-BA-08 | Q6: 44938 | R6: 0.1 | S6: 0.1 | T6: g | U6: 0.1 | V6: 0.098 | W6: 0.37 | Y6: =[1]Trazabilidad!T8 -> TEC-LAB-BA-08 | Z6: =[1]Trazabilidad!U8 -> Bascula | AA6: =[1]Trazabilidad!Z8 -> Tecservice S.A.S | AB6: =[1]Trazabilidad!W8 -> TM707-23A | AC6: =[1]Trazabilidad!X8 -> 45184
A7: BARÓMETRO | C7: =C6 -> TEC-LAB-PTHRI-03 | D7: =D6 -> 46074 | E7: 1 | F7: hPa | G7: -1 | I7: hPa | J7: 1.6 | L7: hPa | Y7: =[1]Trazabilidad!T9 -> N.A. | Z7: =[1]Trazabilidad!U9 | AA7: =[1]Trazabilidad!Z9 | AB7: =[1]Trazabilidad!W9 | AC7: =[1]Trazabilidad!X9
A8: TERMOMETRO PARA MEDICION EN EL AIRE | C8: =C7 -> TEC-LAB-PTHRI-03 | D8: =D7 -> 46074 | E8: 0.1 | F8: ⁰C | G8: -0.05 | I8: ⁰C | J8: 0.39 | L8: ⁰C | Y8: =[1]Trazabilidad!T10 -> TEC-LAB-TEM-33 | Z8: =[1]Trazabilidad!U10 -> Termómetro digital | AA8: =[1]Trazabilidad!Z10 -> Control Company | AB8: =[1]Trazabilidad!W10 -> 4244-14900637 | AC8: =[1]Trazabilidad!X10 -> 45350
A9: TERMOMETRO PARA MEDICION DE LA TEMPERATURA DEL EQUIPOS DE ENSAYO | C9: TEC-LAB-TEM-24 | D9: 43649 | E9: =E5 -> 0.01 | F9: ⁰C | G9: =G5 -> -0.164 | I9: ⁰C | J9: =J5 -> 0.036 | L9: ⁰C | Y9: =[1]Trazabilidad!T11 -> TEC-LAB-TEM-11 | Z9: =[1]Trazabilidad!U11 -> Termómetro digital | AA9: =[1]Trazabilidad!Z11 -> Tesla | AB9: =[1]Trazabilidad!W11 -> TLM-T-2258 | AC9: =[1]Trazabilidad!X11 -> 45359
G10: , | Y10: =[1]Trazabilidad!T12 -> TEC-LAB-PTHRI-01 | Z10: =[1]Trazabilidad!U12 -> Termo higrómetro barómetro digital | AA10: =[1]Trazabilidad!Z12 -> Tesla | AB10: =[1]Trazabilidad!W12 -> TLM-TH-1251/TLM-P-3401 | AC10: =[1]Trazabilidad!X12 -> 2023-06-01/2023-06-05
Y11: =[1]Trazabilidad!T13 -> TEC-LAB-TH-01 | Z11: =[1]Trazabilidad!U13 -> Termo higrómetro digital | AA11: =[1]Trazabilidad!Z13 -> Tesla | AB11: =[1]Trazabilidad!W13 -> TLM-TH-1859C | AC11: =[1]Trazabilidad!X13 -> 45337 | BF11: coeficientes
P12: Temperatura del agua [°C] | R12: ='DATOS GENERALES'!F40 -> TEC-LAB-TEM-33 | W12: Temperatura del aire [°C] | Y12: ='DATOS GENERALES'!F39 -> TEC-LAB-TH-01 | AD12: Humedad del aire [%] | AF12: ='DATOS GENERALES'!F39 -> TEC-LAB-TH-01 | AK12: presion Atmosferica hPa | AM12: ='DATOS GENERALES'!F38 -> TEC-LAB-PTHRI-03 | AR12: W0 [ g ] | AT12: ='DATOS GENERALES'!F37 -> TEC-LAB-BA-07 | AY12: W1 [ g ] | BA12: ='DATOS GENERALES'!F37 -> TEC-LAB-BA-07 | BF12: ='DATOS GENERALES'!F37 -> TEC-LAB-BA-07 | BG12: p(x) | BH12: u (x) | BL12: TEC-LAB-BA-07 | BM12: c0 | BN12: u (x)
