Workbook
Name Cargo: #REF!
Name Cargo: #REF!
Name Clase: #REF!
Name Clase: #REF!
Name Codigo: #REF!
Name Codigo: #REF!
Name División_de_verificación: #REF!
Name División_de_verificación: #REF!
Name Excentricidad: #REF!
Name Excentricidad: #REF!
Name Max: #REF!
Name Max: #REF!
Name Min: #REF!
Name Min: #REF!
Name Nombres: #REF!
Name Nombres: #REF!
Name Patrón: #REF!
Name Patrón: #REF!
Name Repetibilidad: #REF!
Name Repetibilidad: #REF!
Name Resolucion: #REF!
Name Resolucion: #REF!
Name Resolución: #REF!
Name Resolución: #REF!
Name Temperatura: #REF!
Name Temperatura: #REF!
Name U0: #REF!
Name U0: #REF!
Name Umax: #REF!
Name Umax: #REF!
Name Unidades: #REF!
Name Unidades: #REF!
Name W: #REF!
Name W: #REF!

Sheet Base Patrones Presion
B2: CODIGO | E2: ='TOMA DE DATOS'!F42 -> TEC-LAB-PDI-01 | F2: CI | G2: 0.0005
B3: FABRICANTE | E3: {='TOMA DE DATOS'!P42:Q42} -> Additel | F3: 0
B4: CERTIFICADO DE CALIBRACION | E4: ='TOMA DE DATOS'!R42 -> N25121723
B5: V FECHA DE CALIBRACION | E5: ='TOMA DE DATOS'!S42 -> 46373
B6: calibrado en | C6: =G98 -> psi
A7: Posicion | B7: Presion indicacion | C7: Presion Standar | D7: Desviacion | E7: Incertidumbre
A8: 1 | B8: =IF(C81="","",C81) -> -1.9992 | C8: =IF(D81="","",D81) -> -1.99915 | D8: =IF(B8="","",B8-C8) -> -5e-05 | E8: =IF(F81="","",F81) -> 0.00052
A9: 2 | B9: =IF(C82="","",C82) -> -1.4993 | C9: =IF(D82="","",D82) -> -1.49947 | D9: =IF(B9="","",B9-C9) -> 0.00017 | E9: =IF(F82="","",F82) -> 0.0005
A10: 3 | B10: =IF(C83="","",C83) -> -0.9994 | C10: =IF(D83="","",D83) -> -0.99951 | D10: =IF(B10="","",B10-C10) -> 0.00011 | E10: =IF(F83="","",F83) -> 0.00049
A11: 4 | B11: =IF(C84="","",C84) -> -0.4996 | C11: =IF(D84="","",D84) -> -0.49974 | D11: =IF(B11="","",B11-C11) -> 0.00014 | E11: =IF(F84="","",F84) -> 0.00049
A12: 5 | B12: =IF(C85="","",C85) -> 0.0002 | C12: =IF(D85="","",D85) -> 9e-05 | D12: =IF(B12="","",B12-C12) -> 0.00011 | E12: =IF(F85="","",F85) -> 0.00049
A13: 6 | B13: =IF(C86="","",C86) -> 0.4999 | C13: =IF(D86="","",D86) -> 0.49982 | D13: =IF(B13="","",B13-C13) -> 8e-05 | E13: =IF(F86="","",F86) -> 0.00049
A14: 7 | B14: =IF(C87="","",C87) -> 0.9997 | C14: =IF(D87="","",D87) -> 0.99949 | D14: =IF(B14="","",B14-C14) -> 0.00021 | E14: =IF(F87="","",F87) -> 0.00049
A15: 8 | B15: =IF(C88="","",C88) -> 1.4994 | C15: =IF(D88="","",D88) -> 1.4993 | D15: =IF(B15="","",B15-C15) -> 0.0001 | E15: =IF(F88="","",F88) -> 0.00049
A16: 9 | B16: =IF(C89="","",C89) -> 1.9992 | C16: =IF(D89="","",D89) -> 1.99913 | D16: =IF(B16="","",B16-C16) -> 7e-05 | E16: =IF(F89="","",F89) -> 0.0005
A17: 10 | B17: =IF(C90="","",C90) | C17: =IF(D90="","",D90) | D17: =IF(B17="","",B17-C17) | E17: =IF(F90="","",F90)
A18: 11 | B18: =IF(C91="","",C91) | C18: =IF(D91="","",D91) | D18: =IF(B18="","",B18-C18) | E18: =IF(F91="","",F91)
A19: 12 | B19: =IF(C92="","",C92) | C19: =IF(D92="","",D92) | D19: =IF(B19="","",B19-C19) | E19: =IF(F92="","",F92)
B22: Puntos de medicion indicacion patron | G22: Lectura corregida
C23: Toma Datos IBC | D23: unidades CaL P | E23: Unidades IBC
C24: ='TOMA DE DATOS'!F20 -> InH2O | D24: =F78 -> InH2O | E24: ='TOMA DE DATOS'!F20 -> InH2O | G24: =F78 -> InH2O
A25: =IF('CALCULO DE INCERTIDUMBRES'!D13="","",'CALCULO DE INCERTIDUMBRES'!D13) -> 0.0045 | B25: punto 1 | C25: =IF('CALCULO DE INCERTIDUMBRES'!D13="","",'CALCULO DE INCERTIDUMBRES'!D13) -> 0.0045 | D25: =IF($C$24=$D$24,C25,CONVERSION!$E$31*C25) -> 0.0045 | E25: =IF($D$24=$E$24,D25,C25) -> 0.0045 | G25: =IF(C25="","",H42) -> 0.0043906123
A26: =IF('CALCULO DE INCERTIDUMBRES'!D44="","",'CALCULO DE INCERTIDUMBRES'!D44) -> 0.0508 | B26: punto 2 | C26: =IF('CALCULO DE INCERTIDUMBRES'!D44="","",'CALCULO DE INCERTIDUMBRES'!D44) -> 0.0508 | D26: =IF($C$24=$D$24,C26,CONVERSION!$E$31*C26) -> 0.0508 | E26: =IF($D$24=$E$24,D26,C26) -> 0.0508 | G26: =IF(C26="","",H43) -> 0.050697241
A27: =IF('CALCULO DE INCERTIDUMBRES'!D75="","",'CALCULO DE INCERTIDUMBRES'!D75) -> 0.096 | B27: punto 3 | C27: =IF('CALCULO DE INCERTIDUMBRES'!D75="","",'CALCULO DE INCERTIDUMBRES'!D75) -> 0.096 | D27: =IF($C$24=$D$24,C27,CONVERSION!$E$31*C27) -> 0.096 | E27: =IF($D$24=$E$24,D27,C27) -> 0.096 | G27: =IF(C27="","",H44) -> 0.095903616
A28: =IF('CALCULO DE INCERTIDUMBRES'!D106="","",'CALCULO DE INCERTIDUMBRES'!D106) -> 0.1489 | B28: punto 4 | C28: =IF('CALCULO DE INCERTIDUMBRES'!D106="","",'CALCULO DE INCERTIDUMBRES'!D106) -> 0.1489 | D28: =IF($C$24=$D$24,C28,CONVERSION!$E$31*C28) -> 0.1489 | E28: =IF($D$24=$E$24,D28,C28) -> 0.1489 | G28: =IF(C28="","",H45) -> 0.14881064
A29: =IF('CALCULO DE INCERTIDUMBRES'!D137="","",'CALCULO DE INCERTIDUMBRES'!D137) -> 0.1997 | B29: punto 5 | C29: =IF('CALCULO DE INCERTIDUMBRES'!D137="","",'CALCULO DE INCERTIDUMBRES'!D137) -> 0.1997 | D29: =IF($C$24=$D$24,C29,CONVERSION!$E$31*C29) -> 0.1997 | E29: =IF($D$24=$E$24,D29,C29) -> 0.1997 | G29: =IF(C29="","",H46) -> 0.1996166
A30: =IF('CALCULO DE INCERTIDUMBRES'!D168="","",'CALCULO DE INCERTIDUMBRES'!D168) -> 0.2509 | B30: punto 6 | C30: =IF('CALCULO DE INCERTIDUMBRES'!D168="","",'CALCULO DE INCERTIDUMBRES'!D168) -> 0.2509 | D30: =IF($C$24=$D$24,C30,CONVERSION!$E$31*C30) -> 0.2509 | E30: =IF($D$24=$E$24,D30,C30) -> 0.2509 | G30: =IF(C30="","",H47) -> 0.2508215
A31: =IF('CALCULO DE INCERTIDUMBRES'!D199="","",'CALCULO DE INCERTIDUMBRES'!D199) -> 0 | B31: punto 7 | C31: =IF('CALCULO DE INCERTIDUMBRES'!D199="","",'CALCULO DE INCERTIDUMBRES'!D199) -> 0 | D31: =IF($C$24=$D$24,C31,CONVERSION!$E$31*C31) -> 0 | E31: =IF($D$24=$E$24,D31,C31) -> 0 | G31: =IF(C31="","",H48) -> -0.00011002845
A32: =IF('CALCULO DE INCERTIDUMBRES'!D230="","",'CALCULO DE INCERTIDUMBRES'!D230) -> 0 | B32: punto 8 | C32: =IF('CALCULO DE INCERTIDUMBRES'!D230="","",'CALCULO DE INCERTIDUMBRES'!D230) -> 0 | D32: =IF($C$24=$D$24,C32,CONVERSION!$E$31*C32) -> 0 | E32: =IF($D$24=$E$24,D32,C32) -> 0 | G32: =IF(C32="","",H49) -> -0.00011002845
A33: =IF('CALCULO DE INCERTIDUMBRES'!D261="","",'CALCULO DE INCERTIDUMBRES'!D261) -> 0 | B33: punto 9 | C33: =IF('CALCULO DE INCERTIDUMBRES'!D261="","",'CALCULO DE INCERTIDUMBRES'!D261) -> 0 | D33: =IF($C$24=$D$24,C33,CONVERSION!$E$31*C33) -> 0 | E33: =IF($D$24=$E$24,D33,C33) -> 0 | G33: =IF(C33="","",H50) -> -0.00011002845
A34: =IF('CALCULO DE INCERTIDUMBRES'!D292="","",'CALCULO DE INCERTIDUMBRES'!D292) -> 0 | B34: punto 10 | C34: =IF('CALCULO DE INCERTIDUMBRES'!D292="","",'CALCULO DE INCERTIDUMBRES'!D292) -> 0 | D34: =IF($C$24=$D$24,C34,CONVERSION!$E$31*C34) -> 0 | E34: =IF($D$24=$E$24,D34,C34) -> 0 | G34: =IF(C34="","",H51) -> -0.00011002845
A35: =IF('CALCULO DE INCERTIDUMBRES'!D323="","",'CALCULO DE INCERTIDUMBRES'!D323) -> 0 | B35: punto 11 | C35: =IF('CALCULO DE INCERTIDUMBRES'!D323="","",'CALCULO DE INCERTIDUMBRES'!D323) -> 0 | D35: =IF($C$24=$D$24,C35,CONVERSION!$E$31*C35) -> 0 | E35: =IF($D$24=$E$24,D35,C35) -> 0 | G35: =IF(C35="","",H52) -> -0.00011002845
A36: =IF('CALCULO DE INCERTIDUMBRES'!D24="","",'CALCULO DE INCERTIDUMBRES'!D24) | B36: punto 12 | D36: =IF($C$24=$D$24,C36,CONVERSION!$E$31*C36) -> 0 | E36: =IF($D$24=$E$24,D36,C36) -> 0 | G36: =IF(C36="","",H53)
A37: =IF('CALCULO DE INCERTIDUMBRES'!D25="","",'CALCULO DE INCERTIDUMBRES'!D25) | B37: punto 13 | D37: =IF($C$24=$D$24,C37,CONVERSION!$E$31*C37) -> 0 | E37: =IF($D$24=$E$24,D37,C37) -> 0 | G37: =IF(C37="","",H54)
A38: =IF('CALCULO DE INCERTIDUMBRES'!D26="","",'CALCULO DE INCERTIDUMBRES'!D26) | B38: punto 14 | D38: =IF($C$24=$D$24,C38,CONVERSION!$E$31*C38) -> 0 | E38: =IF($D$24=$E$24,D38,C38) -> 0 | G38: =IF(C38="","",H55)
A39: =IF('CALCULO DE INCERTIDUMBRES'!D27="","",'CALCULO DE INCERTIDUMBRES'!D27) | B39: punto 15 | D39: =IF($C$24=$D$24,C39,CONVERSION!$E$31*C39) -> 0 | E39: =IF($D$24=$E$24,D39,C39) -> 0 | G39: =IF(C39="","",H56)
G40: Valor interpolado de la indicacion del patron | J40: Valor interpolado de incertidumbre patron | M40: =G40 -> Valor interpolado de la indicacion del patron | R40: =J40 -> Valor interpolado de incertidumbre patron
B41: Grado del polinomio | C41: coeficientes | D41: p(x) | E41: u (x) | G41: Valor medido | H41: =CONCATENATE(C23," ",D24) -> Toma Datos IBC InH2O | I41: Correccion | J41: Incetidumbre | K41: =H41 -> Toma Datos IBC InH2O | M41: =G41 -> Valor medido | P41: =CONCATENATE(E23," ",E24) -> Unidades IBC InH2O | Q41: =I41 -> Correccion | R41: =P41 -> Unidades IBC InH2O | T41: =H42-I42 -> 0.0045
C42: a0 | D42: =IF(I81="",0,I81) -> -0.00011002845 | E42: =IF(J81="",0,J81) -> 0.00049000012 | G42: Lectura Corregida Medicion patron punto 1 | H42: =$D$42+$D$43*D25+$D$44*D25^2+$D$45*D25^3+$D$46*D25^4+$D$47*D25^5+$D$48*D25^6+$D$49*D25^7+$D$50*D25^8+$D$51*D25^9+$D$52*D25^10+$D$53*D25^11+$D$54*D25^12+$D$55*D25^13+$D$56*D25^14+$D$57*D25^15 -> 0.0043906123 | I42: =H42-D25 -> -0.00010938766 | J42: Incertidumbre Medicion patron punto 1 | K42: =$E$42+$E$43*D25+$E$44*D25^2+$E$45*D25^3+$E$46*D25^4+$E$47*D25^5+$E$48*D25^6+$E$49*D25^7+$E$50*D25^8+$E$51*D25^9+$E$52*D25^10+$E$53*D25^11+$E$54*D25^12+$E$55*D25^13+$E$56*D25^14+$E$57*D25^15 -> 0.00048999735 | M42: =G42 -> Lectura Corregida Medicion patron punto 1 | P42: =IF($D$24=$E$24,H42,CONVERSION!$E$25*H42) -> 0.0043906123 | Q42: =P42-E25 -> -0.00010938766 | R42: =IF($D$24=$E$24,K42,CONVERSION!$E$25*K42) -> 0.00048999735 | T42: =H43-I43 -> 0.0508
C43: a1 | D43: =IF(I82="",0,I82) -> 1.0001422 | E43: =IF(J82="",0,J82) -> -6.1899016e-07 | G43: Lectura Corregida Medicion patron punto 2 | H43: =$D$42+$D$43*D26+$D$44*D26^2+$D$45*D26^3+$D$46*D26^4+$D$47*D26^5+$D$48*D26^6+$D$49*D26^7+$D$50*D26^8+$D$51*D26^9+$D$52*D26^10+$D$53*D26^11+$D$54*D26^12+$D$55*D26^13+$D$56*D26^14+$D$57*D26^15 -> 0.050697241 | I43: =H43-D26 -> -0.00010275856 | J43: Incertidumbre Medicion patron punto 2 | K43: =$E$42+$E$43*D26+$E$44*D26^2+$E$45*D26^3+$E$46*D26^4+$E$47*D26^5+$E$48*D26^6+$E$49*D26^7+$E$50*D26^8+$E$51*D26^9+$E$52*D26^10+$E$53*D26^11+$E$54*D26^12+$E$55*D26^13+$E$56*D26^14+$E$57*D26^15 -> 0.00048997003 | M43: =G43 -> Lectura Corregida Medicion patron punto 2 | P43: =IF($D$24=$E$24,H43,CONVERSION!$E$25*H43) -> 0.050697241 | Q43: =P43-E26 -> -0.00010275856 | R43: =IF($D$24=$E$24,K43,CONVERSION!$E$25*K43) -> 0.00048997003 | T43: =H44-I44 -> 0.096
...

Sheet TOMA DE DATOS
A1: FORMATO CALIBRACION MEDIDORES DE PRESIÓN LC-FR-87 V5 | XFC1: ='[1]Informacion certificados'!$A2 -> Agenquimicos Ltda.
A2: CD412-25 | XFC2: ='[1]Informacion certificados'!$A3 -> Agropecuaria Gomez Cabal S.A.S.
XFC3: ='[1]Informacion certificados'!$A4 -> Agroavicola San Marino S.A.
A4: Revisado Coordinador de Calidad, 2025-02-22 - Aprobado Gerente General, 2025-02-24 | XFC4: ='[1]Informacion certificados'!$A5 -> Alfa Y Omega Instrumentación S.A.S
XFC5: Alimentos Del Valle S. A.
A6: Certificado de calibración No. | F6: TP046-26 | K6: Hora inicio de calibración: | P6: 0.34027778 | XFC6: Ambiocom S.A.S.
A7: Fecha de recepción: | F7: 46136 | K7: Hora final de la calibración: | XFC7: Amed Asesorías A La Medida De Su Empresa S.A.S
A8: Fecha de calibración: | F8: 46136 | XFC8: Ángel Diagnostica S.A
XFC9: Arpack S.A.S
A10: Información del cliente | XFC10: Artilab S.A.
A11: Cliente: | C11: VALLECILLA B Y VALLECILLA M Y CIA S.C.A CARVAL DE COLOMBIA | I11: Dirección: | K11: Calle 15 No 32 - 450 km 2 | P11: Ciudad: | R11: Yumbo, Valle del Cauca | XFC11: Asoclinic Limitada
P12: País | R12: Colombia | XFC12: Automatizamos Ingeniería S.A.S.
A13: Información del instrumento | XFC13: Avantika Colombia S.A.S
A14: Equipo: | C14: Manómetro de presión diferencial | H14: Fabricante: | K14: DWYER | N14: Modelo: | Q14: MAGNEHELIC | XFC14: Avícola Pollo Listo S.A.S
A15: No. serie: | C15: N.I | H15: Código: | K15: CVSAC001-Q642 | N15: Ubicación: | P15: Laboratorio de microbiología / Exclusa de siembra 2 | XFC15: AVIDESA DE OCCIDENTE SA
A16: Sitio de calibración: | E16: Laboratorio de presión de Tecservice s.a.s. | XFC16: B Altman & Compañía S.A.S
XFC17: B ALTMAN & COMPAÑIA SAS
A18: Características metrológicas del instrumento | XFC18: Balanceados SA
A19: Magnitud: | D19: Presión. | XFC19: Basalex S.A.S.
A20: Intervalo de medición: | D20: 0 | F20: InH2O | G20: Hasta | I20: 0.25 | K20: =F20 -> InH2O | L20: Indicación | O20: Analógica | XFC20: Basculas Y Servicios Electrónicos De Pesaje Limitada
A21: Intervalo de calibración: | D21: 0 | F21: =F20 -> InH2O | G21: Hasta | I21: 0.25 | K21: =F20 -> InH2O | L21: Clase de Fabricante | O21: 4 | XFC21: Basculas Y Suministros S.A.S
A22: =IF(O20=E128,"División de escala:",IF(O20=E127,"Resolución:","División de escala/Resolución:")) -> División de escala: | D22: 0.005 | F22: =IF(ISBLANK(F21),"N.A.",F21) -> InH2O | G22: =IF(O20="Digital","N.A.","Apreciacion:") -> Apreciacion: | I22: 0.0025 | K22: =F20 -> InH2O | L22: Clase calculada | O22: =ROUNDUP((('Tabla de resultados'!AM102)/(ABS(D20)+ABS(I20))*100),1) -> 1.8 | XFC22: Belleza Express S.A.
F23: Posición de Montaje | J23: Horizontal | L23: Secuencia | O23: C | XFC23: Bionutrect S.A.S.
A24: Limite Superior | D24: =IF(ISBLANK(O21),((ABS(D20)+ABS(I20))*O22)/100,(O21*((ABS(D20)+ABS(I20)))/100)) -> 0.01 | F24: Limite Inferior | I24: =IF(ISBLANK(O21),((ABS(D20)+ABS(I20))*O22)/-100,(O21*((ABS(D20)+ABS(I20)))/-100)) -> -0.01 | K24: Numero de puntos sin punto cero | P24: =IF(O23="A",9,IF(O23="B",9,5)) -> 5 | XFC24: Biotec Laboratorio S.A.S
XFC25: Bpc Services S.A.S
A26: Evaluación visual de las características de funcionamiento instrumento | XFC26: Byspro S.A.S
A27: Características a evaluar: | J27: Cumple | M27: Observaciones | XFC27: C.I Seasif Pacific S.A.S.
J28: Si | K28: No | L28: N.A | XFC28: Caad Instrumentación Control Y Metrología S.A.S
A29: La escala es legible | J29: X | XFC29: Campofert S.A.S.
A30: Sellos en buen estado | J30: X | XFC30: Campolab S.A.S.
A31: las agujas se encuentran en buen estado | J31: X | XFC31: Carlos Sarmiento L. & Cía.. Ingenio Sancarlos S.A.
A32: Información del instrumento completa | J32: X | XFC32: Cartón De Colombia S.A
A33: El display esta en buenas condiciones | J33: X | XFC33: Cartonera Nacional S.A.
A34: El instrumento presenta contaminación o suciedad | K34: X | XFC34: Carvajal Pulpa Y Papel S.A
A35: El equipo retorna a cero | J35: X | XFC35: Carval De Colombia
A36: Entrada de presión libre | J36: X | XFC36: Carval De Colombia.
A37: Funciones eléctricas en buen estado | L37: X | XFC37: Carval De Colombia
A38: Presenta variación | K38: X | XFC38: Casita De Belén
XFC39: CENEGRALS.A.S.
F40: Trazabilidad | XFC40: Centro De Investigación Científica Caucaseco Limitada
...

Sheet Tabla de resultados
A1: CERTIFICADOS CALIBRACION MEDIDORES DE PRESIÓN LC-FR-87 V5
A2: CD412-25
A4: Revisado Coordinador de Calidad, 2025-02-22 - Aprobado Gerente General, 2025-02-24
A5: CERTIFICADO DE CALIBRACIÓN
A6: Certificate of calibración
R9: CERTIFICADO No: | V9: ='TOMA DE DATOS'!F6 -> TP046-26
R10: Certificate number
A13: Magnitud | E13: Presión | O13: Instrumento:* | R13: ='TOMA DE DATOS'!C14 -> Manómetro de presión diferencial
A15: Solicitante: | E15: ='TOMA DE DATOS'!C11 -> VALLECILLA B Y VALLECILLA M Y CIA S.C.A CARVAL DE COLOMBIA | O15: Fabricante:* | R15: ='TOMA DE DATOS'!K14 -> DWYER
A17: Dirección: | E17: =IF('TOMA DE DATOS'!K11="","",CONCATENATE('TOMA DE DATOS'!K11," ",'TOMA DE DATOS'!R11," - ",'TOMA DE DATOS'!R12)) -> Calle 15 No 32 - 450 km 2 Yumbo, Valle del Cauca - Colombia | O17: Modelo:* | R17: ='TOMA DE DATOS'!Q14 -> MAGNEHELIC
A19: Fecha de recepción: | E19: ='TOMA DE DATOS'!F7 -> 46136 | O19: Identificación:* | R19: ='TOMA DE DATOS'!K15 -> CVSAC001-Q642
A21: Fecha de calibración: | E21: ='TOMA DE DATOS'!F8 -> 46136 | O21: Número de serie:* | S21: ='TOMA DE DATOS'!C15 -> N.I
A23: Número de páginas del certificado : | H23: Dos (2) | O23: Ubicación:* | Q23: ='TOMA DE DATOS'!P15 -> Laboratorio de microbiología / Exclusa de siembra 2
A26: Características Metrológicas del Instrumento de medición
A28: Presión
A29: Intervalo de medición: | E29: =CONCATENATE('TOMA DE DATOS'!D20) -> 0 | G29: ='TOMA DE DATOS'!F20 -> InH2O | H29: Hasta | J29: =CONCATENATE('TOMA DE DATOS'!I20) -> 0,25 | L29: =G29 -> InH2O | Q29: Tipo de indicación: | U29: ='TOMA DE DATOS'!O20 -> Analógica
A30: Intervalo calibrado: | E30: =CONCATENATE('TOMA DE DATOS'!D21) -> 0 | G30: =G29 -> InH2O | H30: Hasta | J30: =CONCATENATE('TOMA DE DATOS'!I21) -> 0,25 | L30: =L29 -> InH2O | Q30: Secuencia Utilizada: | U30: ='TOMA DE DATOS'!O23 -> C
A31: ='TOMA DE DATOS'!A22 -> División de escala: | E31: =CONCATENATE('TOMA DE DATOS'!D22) -> 0,005 | G31: =G30 -> InH2O | Q31: Posición de Montaje: | U31: ='TOMA DE DATOS'!J23 -> Horizontal
A32: Resolución: | E32: ='TOMA DE DATOS'!I22 -> 0.0025 | G32: =G31 -> InH2O
A33: Clase del Fabricante: | E33: =IF('TOMA DE DATOS'!O21="","N.I.",'TOMA DE DATOS'!O21) -> 4 | G33: =IF('TOMA DE DATOS'!O21="","","%") -> % | H33: Clase Calculada: | L33: =IF('TOMA DE DATOS'!O21="",CONCATENATE('TOMA DE DATOS'!O22),"N.A.") -> N.A. | N33: =IF('TOMA DE DATOS'!O21="","%","")
A34: Limite Superior: | D34: =CONCATENATE('TOMA DE DATOS'!D24) -> 0,01 | F34: =IF(D34="","",G29) -> InH2O | H34: Limite Inferior: | L34: =CONCATENATE('TOMA DE DATOS'!I24) -> -0,01 | N34: =IF(L34="","",G29) -> InH2O
A37: Este certificado expresa fielmente el resultado de las mediciones realizadas. No podrá ser reproducido parcialmente.
A38: Este certificado es emitido de acuerdo con los requerimientos de la norma NTC- ISO/IEC 17025:2017 (Requisitos generales para la competencia de los laboratorios de ensayo y calibración). El usuario es responsable de la calibración de sus instrumentos a intervalos apropiados.
A40: Resultado evaluación física:
A41: El instrumento a calibrar fue inspeccionado detalladamente para determinar su estado y condición física determinando que puede ser calibrado
A43: Método de calibración utilizado:
A44: Método de comparación directa, el cual consiste en comparar la indicación del instrumento versus las sustancias y/o equipos de referencia.
A47: Procedimiento de calibración:
A48: Procedimiento LC-PR-36 para calibración de equipos medidores de presión, vacío, presión diferencial.
A52: Lugar de calibración:
A53: La calibración se realizó en las instalaciones de | J53: ='TOMA DE DATOS'!E16 -> Laboratorio de presión de Tecservice s.a.s.
A55: Descripción de la trazabilidad
A56: Esta calibración es trazable al Sistema Internacional de Unidades (SI), a través de una cadena ininterrumpida de comparaciones, cada eslabón de la cadena está documentado y la incertidumbre de medición ha sido estimada en cada paso.
C58: Código | G58: Descripción | M58: Marca | Q58: Certificado No. | U58: Fecha Prox Calibración
C59: ='TOMA DE DATOS'!F42 -> TEC-LAB-PDI-01 | G59: =VLOOKUP(C59,TRAZABILIDAD!$A$3:$E$12,2,0) -> Manometro de presión Diferencial | M59: =VLOOKUP(C59,TRAZABILIDAD!$A$3:$E$9,3,0) -> Additel | Q59: =VLOOKUP(C59,TRAZABILIDAD!$A$3:$E$9,4,0) -> N25121723 | U59: =VLOOKUP(C59,TRAZABILIDAD!$A$3:$F$9,6,0) -> 46373
C60: =IF(ISBLANK('TOMA DE DATOS'!F43),"",'TOMA DE DATOS'!F43) | G60: =IF(ISBLANK('TOMA DE DATOS'!F43),"",VLOOKUP(C60,TRAZABILIDAD!$A$3:$E$12,2,0)) | M60: =IF(ISBLANK('TOMA DE DATOS'!F43),"",VLOOKUP(C60,TRAZABILIDAD!$A$3:$E$12,3,0)) | Q60: =IF(ISBLANK('TOMA DE DATOS'!F43),"",VLOOKUP(C60,TRAZABILIDAD!$A$3:$E$12,4,0)) | U60: =IF(ISBLANK('TOMA DE DATOS'!F43),"",VLOOKUP(C60,TRAZABILIDAD!$A$3:$F$12,6,0))
C61: =IF(ISBLANK('TOMA DE DATOS'!F44),"",'TOMA DE DATOS'!F44) | G61: =IF(ISBLANK('TOMA DE DATOS'!F44),"",VLOOKUP(C61,TRAZABILIDAD!$A$3:$E$12,2,0)) | M61: =IF(ISBLANK('TOMA DE DATOS'!F44),"",VLOOKUP(C61,TRAZABILIDAD!$A$3:$E$12,3,0)) | Q61: =IF(ISBLANK('TOMA DE DATOS'!F44),"",VLOOKUP(C61,TRAZABILIDAD!$A$3:$E$12,4,0)) | U61: =IF(ISBLANK('TOMA DE DATOS'!F44),"",VLOOKUP(C61,TRAZABILIDAD!$A$3:$F$12,6,0))
A65: FIRMAS AUTORIZADAS
E67: =IF(U59<TODAY(),"No Se Puede Emitir Certificado, Revisar Equipo Patron") -> FALSE
A70: ='TOMA DE DATOS'!K116 -> Diego Vera
...

Sheet CALCULO DE INCERTIDUMBRES
A1: Aportantes de incertidumbre
C2: 1
E4: TIPO B | F4: TIPO B | G4: TIPO B | H4: TIPO A | I4: TIPO B | J4: TIPO B | K4: TIPO B
A5: Punto 1 | J5: Valor mas pequeño estimado por residuos | O5: *
A6: 0
C8: ='Tabla de resultados'!$A$90 -> Valor indicación [InH2O] | D8: ='Tabla de resultados'!$E$90 -> Patrón Estándar [InH2O] | E8: Por certificado del patron | F8: Incertidumbre estandar por resolucion del instrumento | J8: Aportante por interpolacion | K8: Aportante por deriva
A9: 17 | C9: =IF('TOMA DE DATOS'!$A$68='TOMA DE DATOS'!$Q$138,'TOMA DE DATOS'!$C$78,'TOMA DE DATOS'!C78+'Base Patrones Presion'!Q42) -> 0 | D9: ='TOMA DE DATOS'!E78&"" -> 0,0067 | E9: ='Base Patrones Presion'!R42 -> 0.00048999735 | F9: =IF('TOMA DE DATOS'!$O$20="Analógica",SQRT((1/3)*(POWER((2*'TOMA DE DATOS'!$I$22)/2,2))),SQRT((1/3)*(POWER((2*'TOMA DE DATOS'!$D$22)/2,2)))) -> 0.0014433757 | G9: =SQRT((1/3)*(POWER(($Q$11)/2,2))) -> 0.0006350853 | H9: =SQRT((1/3)*(POWER(S21/2,2))) -> 0 | I9: =SQRT(1/3*POWER((S29)/2,2)) -> 0.0006350853 | J9: ='Base Patrones Presion'!$M$63 -> 4.4772765e-15 | K9: ='Base Patrones Presion'!$N$93 -> 0 | Q9: =ABS(D10-D9) -> 0.0022
D10: ='TOMA DE DATOS'!G78 -> 0.0045 | Q10: =ABS(D12-D11) -> 0
D11: ='TOMA DE DATOS'!K78 -> 0 | P11: 𝑓 | Q11: =IF(OR('TOMA DE DATOS'!O23="C",'TOMA DE DATOS'!O23="B"), MAX(Q9),MAX(Q9:Q10)) -> 0.0022
D12: ='TOMA DE DATOS'!M78 -> 0
B13: Promedio | D13: =IF('TOMA DE DATOS'!$O$23="C",AVERAGE(D9:D10),IF('TOMA DE DATOS'!O23="B",AVERAGE(((D9+D10)/2),D11),AVERAGE(D9:D12))) -> 0.0045 | E13: promedio con ajuste | F13: =IF('TOMA DE DATOS'!$A$68='TOMA DE DATOS'!$Q$137,D13,D13+'Base Patrones Presion'!Q42) -> 0.0043906123
B14: Desviacion | D14: =IF('TOMA DE DATOS'!$A$68='TOMA DE DATOS'!$Q$138,(C9-F13),F13-C9) -> -0.0043906123
B15: Grados de libertad | E15: 200 | F15: 200 | G15: 200 | H15: =COUNT('TOMA DE DATOS'!$E$78:$N$87)-1 -> 11 | I15: 200 | J15: 200 | K15: 200 | O15: **
B16: Coeficientes de sensibilidad | E16: -1 | F16: 1 | G16: 1 | H16: 1 | I16: 1 | J16: 1 | K16: 1 | O16: Repetibilidad solo aplica para secuencias B y A.
B17: Cuadrado de los aportantes por coeficientes | E17: =POWER(E9*E16,2) -> 2.400974e-07 | F17: =POWER(F9*F16,2) -> 2.0833333e-06 | G17: =POWER(G9*G16,2) -> 4.0333333e-07 | H17: =POWER(H9*H16,2) -> 0 | I17: =POWER(I9*I16,2) -> 4.0333333e-07 | J17: =POWER(J9*J16,2) -> 2.0046005e-29 | K17: =POWER(K9*K16,2) -> 0 | O17: Para secuencia C es 0
B18: incertidumbre estandar combinada | E18: =SQRT(SUM(E17:K17)) -> 0.0017692081
S20: Repetibilidad
S21: =IF('TOMA DE DATOS'!$O$23="A",MAX(ABS(D11-D9),ABS(D12-D10)),IF('TOMA DE DATOS'!$O$23="B",ABS(D11-D9),0)) -> 0
B22: Grados efectivos de libertad | E22: =POWER(E18,2)/((POWER(E17,2)/E15)+(POWER(F17,2)/F15)+(POWER(G17,2)/G15)+(POWER(H17,2)/H15)+(POWER(I17,2)/I15)+(POWER(J17,2)/J15)+(POWER(K17,2)/K15)) -> 1.3253914e+08
O24: ***
B26: k | E26: =TINV(0.05,E22) -> 1.959964
B27: Incertidumbre expandida | E27: =E18*E26 -> 0.0034675842 | O27: donde j es la posicion del escalon.
O29: n segun secuencia | R29: histeresis | S29: =IF('TOMA DE DATOS'!O23="A",(ABS((D10-D9))+ABS((D12-D11)))/2,D10-D9) -> -0.0022
O30: A | P30: 2
O31: B | P31: 1
O32: C | P32: 1
C33: 2
E35: TIPO B | F35: TIPO B | G35: TIPO B | H35: TIPO A | I35: TIPO B | J35: TIPO B | K35: TIPO B
A36: Punto 2 | J36: Valor mas pequeño estimado por residuos | O36: *
A37: ='TOMA DE DATOS'!C79 -> 0.05
C39: ='Tabla de resultados'!$A$90 -> Valor indicación [InH2O] | D39: ='Tabla de resultados'!$E$90 -> Patrón Estándar [InH2O] | E39: Por certificado del patron | F39: Incertidumbre estandar por resolucion del instrumento | J39: Aportante por interpolacion | K39: Aportante por deriva
A40: 18 | C40: =IF('TOMA DE DATOS'!$A$68='TOMA DE DATOS'!$Q$138,'TOMA DE DATOS'!$C$79,'TOMA DE DATOS'!C79+'Base Patrones Presion'!Q43) -> 0.05 | D40: ='TOMA DE DATOS'!E79 -> 0.0518 | E40: ='Base Patrones Presion'!R43 -> 0.00048997003 | F40: =IF('TOMA DE DATOS'!$O$20="Analógica",SQRT((1/3)*(POWER((2*'TOMA DE DATOS'!$I$22)/2,2))),SQRT((1/3)*(POWER((2*'TOMA DE DATOS'!$D$22)/2,2)))) -> 0.0014433757 | G40: =G9 -> 0.0006350853 | H40: =SQRT((1/3)*(POWER(S52/2,2))) -> 0 | I40: =SQRT(1/3*POWER((S60)/2,2)) -> 0.00057735027 | J40: ='Base Patrones Presion'!$M$63 -> 4.4772765e-15 | K40: ='Base Patrones Presion'!$N$93 -> 0 | Q40: =ABS(D41-D40) -> 0.002
D41: ='TOMA DE DATOS'!G79 -> 0.0498 | Q41: =ABS(D43-D42) -> 0
D42: ='TOMA DE DATOS'!K79 -> 0 | P42: 𝑓 | Q42: =IF(OR('TOMA DE DATOS'!$O$23="C",'TOMA DE DATOS'!$O$23="B"), MAX(Q40),MAX(Q40:Q41)) -> 0.002
D43: ='TOMA DE DATOS'!M79 -> 0
B44: Promedio | D44: =IF('TOMA DE DATOS'!$O$23="C",AVERAGE(D40:D41),IF('TOMA DE DATOS'!$O$23="B",AVERAGE(D40:D42),AVERAGE(D40:D43))) -> 0.0508 | E44: promedio con ajuste | F44: =IF('TOMA DE DATOS'!$A$68='TOMA DE DATOS'!$Q$137,D44,D44+'Base Patrones Presion'!Q43) -> 0.050697241
B45: Desviacion | D45: =IF('TOMA DE DATOS'!$A$68='TOMA DE DATOS'!$Q$138,(C40-F44),F44-C40) -> -0.00069724144
B46: Grados de libertad | E46: 200 | F46: 200 | G46: 200 | H46: =COUNT('TOMA DE DATOS'!$E$78:$N$87)-1 -> 11 | I46: 200 | J46: 200 | K46: 200 | O46: **
B47: Coeficientes de sensibilidad | E47: -1 | F47: 1 | G47: 1 | H47: 1 | I47: 1 | J47: 1 | K47: 1 | O47: Repetibilidad solo aplica para secuencias B y A.
B48: Cuadrado de los aportantes por coeficientes | E48: =POWER(E40*E47,2) -> 2.4007063e-07 | F48: =POWER(F40*F47,2) -> 2.0833333e-06 | G48: =POWER(G40*G47,2) -> 4.0333333e-07 | H48: =POWER(H40*H47,2) -> 0 | I48: =POWER(I40*I47,2) -> 3.3333333e-07 | J48: =POWER(J40*J47,2) -> 2.0046005e-29 | K48: =POWER(K40*K47,2) -> 0 | O48: Para secuencia C es 0
...

Sheet CONVERSION
E2: cuanto equivale la unidad de la columna respecto a la fila, ejemplo 1 Pa equivale a 1,0 E+03kPa,
A4: Unidades | B4: Pa | C4: kPa | D4: MPa | E4: bar | F4: mbar | G4: psi | H4: InH2O | I4: mmH2O | J4: InHg | K4: mmHg | L4: kg/cm2 | M4: cmHg
A5: Pa | B5: 1 | C5: 1000 | D5: 1000000 | E5: 100000 | F5: 100 | G5: =1/B10 -> 6894.7448 | H5: 249.1 | I5: 9.807 | J5: 3386 | K5: 133.3 | L5: 98066.5 | M5: =K5*10 -> 1333
A6: kPa | B6: 0.001 | C6: 1 | D6: 1000 | E6: 100 | F6: 0.1 | G6: =1/C10 -> 6.8947448 | H6: 0.2491 | I6: 0.009807 | J6: 3.386 | K6: 0.1333 | L6: 98.0665 | M6: =K6*10 -> 1.333
A7: MPa | B7: 1e-06 | C7: 0.001 | D7: 1 | E7: 0.1 | F7: 0.0001 | G7: =G6/1000 -> 0.0068947448 | H7: 0.0002491 | I7: 9.807e-06 | J7: 0.003386 | K7: 0.0001333 | L7: 0.0980665 | M7: =K7*10 -> 0.001333
A8: bar | B8: 1e-05 | C8: 0.01 | D8: 10 | E8: 1 | F8: 0.001 | G8: 0.0689476 | H8: 0.002491 | I8: 9.807e-05 | J8: 0.03386 | K8: 0.001333 | L8: 0.980665 | M8: =K8*10 -> 0.01333 | N8: 0.06894745 | O8: =+G8-N8 -> 1.5e-07
A9: mbar | B9: 0.01 | C9: 10 | D9: 10000 | E9: 1000 | F9: 1 | G9: 68.9476 | H9: 2.491 | I9: 0.09807 | J9: 33.86 | K9: 1.333 | L9: 980.665 | M9: =K9*10 -> 13.33
A10: psi | B10: 0.000145038 | C10: 0.145038 | D10: 145 | E10: 14.5038 | F10: 0.0145 | G10: 1 | H10: 0.03613 | I10: 0.001422 | J10: 0.4912 | K10: 0.01934 | L10: 14.2233 | M10: =K10*10 -> 0.1934
A11: InH2O | B11: 0.00401463 | C11: 4.01463 | D11: 4.015 | E11: 401.463 | F11: 0.4015 | G11: 27.6799 | H11: 1 | I11: 0.03937 | J11: 13.6 | K11: 0.5352 | L11: 393.701 | M11: =K11*10 -> 5.352
A12: mmH2O | B12: 0.101972 | C12: 101.972 | D12: 101972 | E12: 10197.2 | F12: 10.2 | G12: 703.07 | H12: 25.4 | I12: 1 | J12: 345.3 | K12: 13.6 | L12: 10000 | M12: =K12*10 -> 136
A13: InHg | B13: 0.0002953 | C13: 0.2953 | D13: 295.3 | E13: 29.53 | F13: 0.02953 | G13: 2.03602 | H13: 0.07356 | I13: 0.002896 | J13: 1 | K13: 0.03937 | L13: 28.959 | M13: =K13*10 -> 0.3937
A14: mmHg | B14: 0.00750062 | C14: 7.50062 | D14: 7501 | E14: 750.062 | F14: 0.7501 | G14: 51.7149 | H14: 1.868 | I14: 0.07356 | J14: 25.4 | K14: 1 | L14: 735.559 | M14: =K14*10 -> 10 | O14: =M14 -> 10
A15: kg/cm2 | B15: 1.01972e-05 | C15: 0.0101972 | D15: 10.2 | E15: 1.01972 | F15: 0.00102 | G15: 0.070307 | H15: 0.00254 | I15: 0.0001 | J15: 0.03453 | K15: 0.00136 | L15: 1 | M15: =K15*10 -> 0.0136
A16: cmHg | B16: =B14/10 -> 0.000750062 | C16: =C14/10 -> 0.750062 | D16: =D14/10 -> 750.1 | E16: =E14/10 -> 75.0062 | F16: =F14/10 -> 0.07501 | G16: =G14/10 -> 5.17149 | H16: =H14/10 -> 0.1868 | I16: =I14/10 -> 0.007356 | ... M16: =M14/10 -> 1
A17: cuanto equivale la unidad de la fila respecto a la columna, ejemplo 1 Pa equivale 1,03 E-03 kPa
B20: Los referenciados en este color son la conversion que aparece directamente NIST Special Publication 811 2008 Edition Ambler Thompson and Barry N. Taylor
C23: solo cambia la variable original del patron para la conversion
C24: Unidad original P | E24: ='Base Patrones Presion'!$D$24 -> InH2O | F24: Unidad a convertir | H24: ='TOMA DE DATOS'!F20 -> InH2O
C25: Valor | E25: =INDEX(B5:M16,E28,E27) -> 1 | J25: =INDEX(B5:M16,E28,E27) -> 1 | K25: 0.01 | L25: =J25*K25 -> 0.01
D27: Columna | E27: =MATCH(E24,A5:A16,0) -> 7 | G27: =INDEX(B5:M16,E27,E28) -> 1
D28: Fila | E28: =MATCH(H24,B4:M4,0) -> 7
C30: Unidad original Dato IBC | E30: ='TOMA DE DATOS'!F20 -> InH2O | F30: Unidad a convertir | H30: ='Base Patrones Presion'!F78 -> InH2O
C31: Valor | E31: =INDEX(B5:M16,E27,E28) -> 1

Sheet TRAZABILIDAD
A1: TRAZABILIDAD
A2: Código | B2: Descripción | C2: Marca | D2: N° de certificado | E2: Fecha de Calibracion | F2: Fecha de vencimiento | G2: intervalo | H2: resolución | I2: CI % | J2: Unidades de trabajo en el instrumento patrón | R2: Frecuencia | S2: Viegencia anterior
A3: TEC-LAB-PS-10 | B3: Manometro | C3: Additel | D3: 13027 | E3: 45890 | F3: 46620 | G3: 0 psi a 5000 psi | H3: 0,1 psi | I3: 0.05 | J3: psi | K3: mbar | L3: mmH2O | M3: inH2O | N3: Pa | O3: kPa | P3: Mpa | Q3: bar | R3: =DAYS360(E3,F3) -> 720 | S3: =EDATE(E3,-R3/30) -> 45159
A4: TEC-LAB-PI-01 | B4: Manometro | C4: Additel | D4: 12629 | E4: 45771 | F4: 46501 | G4: 0 psi a 300 psi | H4: 0,01 psi | I4: 0.05 | J4: psi | K4: mbar | L4: mmH2O | M4: inH2O | N4: Pa | O4: kPa | P4: Mpa | Q4: bar | R4: =DAYS360(E4,F4) -> 720 | S4: =EDATE(E4,-R4/30) -> 45040
A5: TEC-LAB-PS-03- | B5: Manovacuometro | C5: Reed Instruments | D5: 12352 | E5: 45700 | F5: 46430 | G5: 0 psi a +/- 10 psi | H5: 0,01 psi | I5: 0.3 | J5: bar | K5: mmHg | L5: inH2O | M5: inHg | N5: mbar | O5: psi | P5: --- | Q5: --- | R5: =DAYS360(E5,F5) -> 720 | S5: =EDATE(E5,-R5/30) -> 44969
A6: TEC-LAB-PS-03+ | B6: Manovacuometro | C6: Reed Instruments | D6: 12349 | E6: 45700 | F6: 46430 | G6: 0 psi a +/- 30 psi | H6: 0,01 psi | I6: 0.3 | J6: bar | K6: mmHg | L6: inH2O | M6: inHg | N6: mbar | O6: psi | P6: --- | Q6: --- | R6: =DAYS360(E6,F6) -> 720 | S6: =EDATE(E6,-R6/30) -> 44969
A7: TEC-LAB-PDI-03 | B7: Manometro de presión Diferencial | C7: Additel | D7: C2803-25 | E7: 45733 | F7: 46098 | G7: -2 In H2O a 2 In H2O | H7: 0,1 psi | I7: 0.05 | J7: psi | K7: mbar | L7: mmH2O | M7: inH2O | N7: Pa | O7: kPa | P7: Mpa | Q7: bar | R7: =DAYS360(E7,F7) -> 360 | S7: =EDATE(E7,-R7/30) -> 45368
A8: TEC-LAB-PDI-02 | B8: Manometro de presión Diferencial | C8: Dwyer | D8: TLM-P-6702 | E8: 45762 | F8: 46127 | G8: -4 In H2O A 4 In H2O | H8: 0,001 H2O | I8: 0.05 | M8: inH2O | R8: =DAYS360(E8,F8) -> 360 | S8: =EDATE(E8,-R8/30) -> 45397
A9: TEC-LAB-PDI-01 | B9: Manometro de presión Diferencial | C9: Additel | D9: N25121723 | E9: 46008 | F9: 46373 | G9: -2 In H2O a 2 In H2O | H9: 0,1 psi | I9: 0.05 | J9: psi | K9: mbar | L9: mmH2O | M9: inH2O | N9: Pa | O9: kPa | P9: Mpa | Q9: bar | R9: =DAYS360(E9,F9) -> 360 | S9: =EDATE(E9,-R9/30) -> 45643
R14: =730/12 -> 60.833333

Sheet Hoja1
F19: Posicion | G19: Presion indicacion | H19: Presion Standar | I19: Desviacion | J19: Incertidumbre
A20: CODIGO | B20: TEC-LAB-PI-01 | C20: 9749 | F20: 1 | G20: 0 | H20: 0 | I20: 0 | J20: 0.019
F21: 2 | G21: 37.508 | H21: 37.5 | I21: 0.008 | J21: 0.025
F22: 3 | G22: 75.005 | H22: 75 | I22: 0.005 | J22: 0.024
F23: 4 | G23: 112.5 | H23: 112.5 | I23: 0 | J23: 0.024
F24: 5 | G24: 149.99 | H24: 150 | I24: -0.01 | J24: 0.026
F25: 6 | G25: 187.488 | H25: 187.5 | I25: -0.012 | J25: 0.027
F26: 7 | G26: 224.985 | H26: 225 | I26: -0.015 | J26: 0.029
F27: 8 | G27: 262.48 | H27: 262.5 | I27: -0.02 | J27: 0.03
F28: 9 | G28: 299.963 | H28: 300 | I28: -0.037 | J28: 0.033
F30: Posicion | G30: Presion indicacion | H30: Presion Standar | I30: Desviacion | J30: Incertidumbre
A31: CODIGO | B31: TEC-LAB-PDI-01 | C31: DE6301-23 | F31: 1 | G31: -1.9992 | H31: -1.99915 | I31: -0.0001 | J31: 0.00039
F32: 2 | G32: -1.4994 | H32: -1.49935 | I32: 0 | J32: 0.00039
F33: 3 | G33: -0.9995 | H33: -0.99944 | I33: 0 | J33: 0.00039
F34: 4 | G34: -0.4996 | H34: -0.49962 | I34: 0 | J34: 0.00039
F35: 5 | G35: 0.0001 | H35: 0.00011 | I35: 0 | J35: 0.00039
F36: 6 | G36: 0.5 | H36: 0.50012 | I36: -0.0001 | J36: 0.00039
F37: 7 | G37: 0.9999 | H37: 0.99998 | I37: -0.0001 | J37: 0.00039
F38: 8 | G38: 1.4998 | H38: 1.49985 | I38: -0.0001 | J38: 0.00039
F39: 9 | G39: 1.9997 | H39: 1.99976 | I39: -0.0001 | J39: 0.00039
F41: Posicion | G41: Presion indicacion | H41: Presion Standar | I41: Desviacion | J41: Incertidumbre
A42: CODIGO | B42: TEC-LAB-PS-10 | C42: 10142 | F42: 1 | G42: 0 | H42: 0 | I42: =G42-H42 -> 0 | J42: 0.058
F43: 2 | G43: 399.922 | H43: 400 | I43: =G43-H43 -> -0.078 | J43: 0.0666
F44: 3 | G44: 699.97 | H44: 700 | I44: =G44-H44 -> -0.03 | J44: 0.1
F45: 4 | G45: 999.95 | H45: 1000 | I45: =G45-H45 -> -0.05 | J45: 0.15
F46: 5 | G46: 1499.95 | H46: 1500 | I46: =G46-H46 -> -0.05 | J46: 0.17
F47: 6 | G47: 1999.9 | H47: 2000 | I47: =G47-H47 -> -0.1 | J47: 0.18
F48: 7 | G48: 2499.85 | H48: 2500 | I48: =G48-H48 -> -0.15 | J48: 0.24
F49: 8 | G49: 2999.75 | H49: 3000 | I49: =G49-H49 -> -0.25 | J49: 0.27
F50: 9 | G50: 3499.7 | H50: 3500 | I50: =G50-H50 -> -0.3 | J50: 0.29
F51: 10 | G51: 3999.7 | H51: 4000 | I51: =G51-H51 -> -0.3 | J51: 0.33
F52: 11 | G52: 4999.62 | H52: 5000 | I52: =G52-H52 -> -0.38 | J52: 0.41
F54: Posicion | G54: Presion Estándar | H54: Presion Indicacion | I54: Desviacion | J54: Incertidumbre
A55: CODIGO | B55: TC-LAB-PS-03 | C55: 9347/9348 | F55: 1 | G55: 0 | H55: 0.01 | I55: 0.005 | J55: 0.027
F56: 2 | G56: 3.001 | H56: 2.99 | I56: -0.011 | J56: 0.027
F57: 3 | G57: 5.002 | H57: 4.98 | I57: -0.022 | J57: 0.027
F58: 4 | G58: 10.002 | H58: 9.94 | I58: -0.062 | J58: 0.027
F59: 5 | G59: 15.003 | H59: 14.95 | I59: -0.053 | J59: 0.027
F60: 6 | G60: 20.003 | H60: 19.96 | I60: -0.43 | J60: 0.027
F61: 7 | G61: 25.003 | H61: 25 | I61: -0.008 | J61: 0.027
...
