Workbook
Name Cargo: #REF!
Name Cargo: #REF!
Name Cargo: #REF!
Name CARRO: #REF!
Name CESAR: #REF!
Name Clase: #REF!
Name Codigo: #REF!
Name Codigo: #REF!
Name Codigo: #REF!
Name División_de_verificación: #REF!
Name Excentricidad: #REF!
Name Max: #REF!
Name Min: #REF!
Name MOTO: #REF!
Name Nombres: #REF!
Name Nombres: #REF!
Name Nombres: #REF!
Name Patrón: #REF!
Name Repetibilidad: #REF!
Name Resolucion: #REF!
Name Resolución: #REF!
Name Temperatura: #REF!
Name U0: #REF!
Name Umax: #REF!
Name Unidades: #REF!
Name Unidades: #REF!
Name Unidades: #REF!

Sheet Alcance
A1: 0 | B1: 8 | C1: DG1 | D1: Masa | E1: En sitio | F1: 0 g < m ≤ 8 g | G1: Intrumento de pesaje de funcionamiento no automático con d ≥ 0,001 mg | H1: 7,6 x 10-6 | I1: 7.6e-06 | J1: =I1 -> 7.6e-06 | K1: =0.001/1000 -> 1e-06 | L1: g
A2: =A1*1000 -> 0 | B2: =B1*1000 -> 8000 | F2: 0 g < m ≤ 8000 mg | I2: =I1 -> 7.6e-06 | J2: =I2 -> 7.6e-06 | K2: 0.001 | L2: mg
A3: 8 | B3: 120 | C3: DG1 | D3: Masa | E3: En sitio | F3: 8 g < m ≤ 120 g | G3: Intrumento de pesaje de funcionamiento no automático con d ≥ 0,01 mg | H3: 1,3 x 10-6 | I3: 1.3e-06 | J3: =I3 -> 1.3e-06 | K3: =0.01/1000 -> 1e-05 | L3: g
A4: =A3*1000 -> 8000 | B4: =B3*1000 -> 120000 | F4: 8000 mg < m ≤ 120000 mg | I4: =I3 -> 1.3e-06 | J4: =I4 -> 1.3e-06 | K4: 0.01 | L4: mg
A5: 120 | B5: 510 | C5: DG1 | D5: Masa | E5: En sitio | F5: 120 g < m ≤ 510 g | G5: Intrumento de pesaje de funcionamiento no automático con d ≥ 0,1 mg | H5: 9,2 x 10-7 | I5: 9.2e-07 | J5: =I5 -> 9.2e-07 | K5: =0.1/1000 -> 0.0001 | L5: mg
A6: =A5*1000 -> 120000 | B6: =B5*1000 -> 510000 | F6: 120000 mg < m ≤ 510000 mg | I6: =I5 -> 9.2e-07 | J6: =I6 -> 9.2e-07 | K6: 0.1 | L6: mg
A7: 510 | B7: 1200 | C7: DG1 | D7: Masa | E7: En sitio | F7: 510 g < m ≤ 1200 g | G7: Intrumento de pesaje de funcionamiento no automático con d ≥ 1 mg | H7: 3,0 x 10-6 | I7: 3e-06 | J7: =I7 -> 3e-06 | K7: =1/1000 -> 0.001 | L7: g
A8: =A7*1000 -> 510000 | B8: =B7*1000 -> 1200000 | F8: 510000 mg < m ≤ 1200000 mg | I8: =I7 -> 3e-06 | J8: =I8 -> 3e-06 | K8: 1 | L8: mg
A9: 1200 | B9: 8100 | C9: DG1 | D9: Masa | E9: En sitio | F9: 1200 g < m ≤ 81000 g | G9: Intrumento de pesaje de funcionamiento no automático con d ≥ 0,01 g | H9: 3,1 x 10-6 | I9: 3.1e-06 | J9: =I9 -> 3.1e-06 | K9: 0.01 | L9: g
A10: 1.2 | B10: 8.1 | F10: 1,2 kg < m ≤ 8,1 kg | I10: =I9 -> 3.1e-06 | J10: =I10 -> 3.1e-06 | K10: =0.01/1000 -> 1e-05 | L10: kg
A11: 8100 | B11: 60000 | C11: DG1 | D11: Masa | E11: En sitio | F11: 8100 g < m ≤ 60000 g | G11: Intrumento de pesaje de funcionamiento no automático con d ≥ 0,1 g | H11: 4,5 x 10-6 | I11: 4.5e-06 | J11: =I11 -> 4.5e-06 | K11: 0.1 | L11: g
A12: 8.1 | B12: 60 | F12: 8,1 kg < m ≤ 60 kg | I12: =I11 -> 4.5e-06 | J12: =I12 -> 4.5e-06 | K12: =0.1/1000 -> 0.0001 | L12: kg
A13: 60 | B13: 100 | C13: DG1 | D13: Masa | E13: En sitio | F13: 60 kg < m ≤ 100 kg | G13: Intrumento de pesaje de funcionamiento no automático con d ≥ 0,01 kg | H13: 8,4 x 10-5 | I13: 8.4e-05 | J13: =I13 -> 8.4e-05 | K13: 0.01 | L13: kg
A14: 60000 | B14: 100000 | F14: 60000 g < m ≤ 100000 g | I14: =I13 -> 8.4e-05 | J14: =I14 -> 8.4e-05 | K14: =0.01*1000 -> 10 | L14: g
A15: 100 | B15: 300 | C15: DG1 | D15: Masa | E15: En sitio | F15: 100 kg < m ≤ 300 kg | G15: Intrumento de pesaje de funcionamiento no automático con d ≥ 0,02 kg | H15: 5,7 x 10-5 | I15: 5.7e-05 | J15: =I15 -> 5.7e-05 | K15: 0.02 | L15: kg
A16: 300 | B16: 1000 | C16: DG1 | D16: Masa | E16: En sitio | F16: 300 kg < m ≤ 1000 kg | G16: Intrumento de pesaje de funcionamiento no automático con d ≥ 0,1 kg | H16: 1,6 x 10-4 | I16: 0.00016 | J16: =I16 -> 0.00016 | K16: 0.1 | L16: kg
A17: 1000 | B17: 1500 | C17: DG1 | D17: Masa | E17: En sitio | F17: 1000 kg < m ≤ 1500 kg | G17: Intrumento de pesaje de funcionamiento no automático con d ≥ 0,2 kg | H17: 2,6 x 10-4 | I17: 0.00026 | J17: =I17 -> 0.00026 | K17: 0.2 | L17: kg

Sheet Calculo P Conformidad
K2: Límite de tolerancia superior único | X2: Otro Info
X3: https://youtu.be/WtRRT4YwAyM?si=vyZ179gciL1UpRil
X4: Minuto | Y4: 2:01:45
M6: = | N6: Pc
K7: Intervalos de tolerancia bilaterales con FDP normales
AF42: PC | AH42: PC
K43: Valor de referencia | L43: EMP | M43: Tu | N43: TL | O43: y | P43: u | Q43: U | R43: k | S43: Pcu | U43: PcL | W43: PC | Y43: PC | AB43: Ztu | AC43: =CONCATENATE("ɸ(",ROUND(AB44,2)," ) ") -> ɸ(1,67 ) | AD43: ZTL | AE43: =CONCATENATE("ɸ(",ROUND(AD44,2)," ) ") -> ɸ(-1,67 ) | AF43: =CONCATENATE("ɸ(",ROUND(AB44,2)," ) - ","ɸ(",ROUND(AD44,2)," ) ") -> ɸ(1,67 ) - ɸ(-1,67 )
K44: 1500 | L44: 0.2 | M44: 1500.2 | N44: 1499.8 | O44: 1500 | P44: 0.12 | Q44: =P44/R44 -> 0.058536585 | R44: 2.05 | S44: =_xlfn.NORM.DIST(M44,O44,P44,1) -> 0.95220965 | U44: =_xlfn.NORM.DIST(N44,O44,P44,1) -> 0.047790352 | W44: =S44-U44 -> 0.9044193 | X44: =W44 -> 0.9044193 | Y44: =1-W44 -> 0.095580705 | Z44: =Y44 -> 0.095580705 | AB44: =(M44-O44)/P44 -> 1.6666667 | AC44: =_xlfn.NORM.S.DIST(AB44,1) -> 0.95220965 | AD44: =(N44-O44)/P44 -> -1.6666667 | AE44: =_xlfn.NORM.S.DIST(AD44,1) -> 0.047790352 | AF44: =AC44-AE44 -> 0.9044193 | AG44: =AF44 -> 0.9044193 | AH44: =1-AF44 -> 0.095580705 | AI44: =AH44 -> 0.095580705
K46: Valor de referencia | L46: EMP | M46: Tu | N46: TL | O46: y | P46: s | S46: Pcu | U46: PcL | W46: PC | Y46: PC
K47: 1500 | L47: 0.2 | M47: 1500.2 | N47: 1499.8 | O47: 1500 | P47: 0.12 | S47: =_xlfn.NORM.DIST(M47,O47,P47,1) -> 0.95220965 | U47: =_xlfn.NORM.DIST(N47,O47,P47,1) -> 0.047790352 | W47: =S47-U47 -> 0.9044193 | X47: =W47 -> 0.9044193 | Y47: =1-W47 -> 0.095580705 | Z47: =Y47 -> 0.095580705
J52: Prueba con datos de calibraciones
O54: TEC-LAB-BA-07
N55: Indicación | O55: Corrección | P55: U | Q55: EMP | AM55: PC | AO55: PC
N56: g | O56: g | P56: g | Q56: g | R56: Valor de referencia | S56: EMP | U56: Tu | W56: TL | X56: y | Y56: U | Z56: uc | AA56: k | AB56: Pcu | AC56: PcL | AD56: PC | AF56: PC | AI56: Ztu | AJ56: =CONCATENATE("ɸ(",ROUND(AI57,2)," ) ") -> ɸ(9,62 ) | AK56: ZTL | AL56: =CONCATENATE("ɸ(",ROUND(AK57,2)," ) ") -> ɸ(-9,62 ) | AM56: =CONCATENATE("ɸ(",ROUND(AI57,2)," ) - ","ɸ(",ROUND(AK57,2)," ) ") -> ɸ(9,62 ) - ɸ(-9,62 )
N57: 50 | O57: 9e-05 | P57: 0.00021 | Q57: 0.001 | R57: =N57+O57 -> 50.00009 | S57: =Q57 -> 0.001 | U57: =R57+S57 -> 50.00109 | W57: =R57-S57 -> 49.99909 | X57: =R57 -> 50.00009 | Y57: =P57 -> 0.00021 | Z57: =Y57/AA57 -> 0.0001039604 | AA57: 2.02 | AB57: =_xlfn.NORM.DIST(U57,X57,Z57,1) -> 1 | AC57: =_xlfn.NORM.DIST(W57,X57,Z57,1) -> 3.3221743e-22 | AD57: =AB57-AC57 -> 1 | AE57: =AD57 -> 1 | AF57: =1-AD57 -> 0 | AG57: =AF57 -> 0 | AI57: =(U57-X57)/Z57 -> 9.6190476 | AJ57: =_xlfn.NORM.S.DIST(AI57,1) -> 1 | AK57: =(W57-X57)/Z57 -> -9.6190476 | AL57: =_xlfn.NORM.S.DIST(AK57,1) -> 3.3221743e-22 | AM57: =AJ57-AL57 -> 1 | AN57: =AM57 -> 1 | AO57: =1-AM57 -> 0 | AP57: =AO57 -> 0
N58: 65 | O58: 0.00013 | P58: 0.00022 | Q58: 0.001 | R58: =N58+O58 -> 65.00013 | S58: =Q58 -> 0.001 | U58: =R58+S58 -> 65.00113 | W58: =R58-S58 -> 64.99913 | X58: =R58 -> 65.00013 | Y58: =P58 -> 0.00022 | Z58: =Y58/AA58 -> 0.00010891089 | AA58: 2.02 | AB58: =_xlfn.NORM.DIST(U58,X58,Z58,1) -> 1 | AC58: =_xlfn.NORM.DIST(W58,X58,Z58,1) -> 2.1193653e-20 | AD58: =AB58-AC58 -> 1 | AE58: =AD58 -> 1 | AF58: =1-AD58 -> 0 | AG58: =AF58 -> 0 | AI58: =(U58-X58)/Z58 -> 9.1818182 | AJ58: =_xlfn.NORM.S.DIST(AI58,1) -> 1 | AK58: =(W58-X58)/Z58 -> -9.1818182 | AL58: =_xlfn.NORM.S.DIST(AK58,1) -> 2.1193653e-20 | AM58: =AJ58-AL58 -> 1 | AN58: =AM58 -> 1 | AO58: =1-AM58 -> 0 | AP58: =AO58 -> 0
N59: 80 | O59: 0.00018 | P59: 0.00023 | Q59: 0.001 | R59: =N59+O59 -> 80.00018 | S59: =Q59 -> 0.001 | U59: =R59+S59 -> 80.00118 | W59: =R59-S59 -> 79.99918 | X59: =R59 -> 80.00018 | Y59: =P59 -> 0.00023 | Z59: =Y59/AA59 -> 0.00011386139 | AA59: 2.02 | AB59: =_xlfn.NORM.DIST(U59,X59,Z59,1) -> 1 | AC59: =_xlfn.NORM.DIST(W59,X59,Z59,1) -> 7.9863045e-19 | AD59: =AB59-AC59 -> 1 | AE59: =AD59 -> 1 | AF59: =1-AD59 -> 0 | AG59: =AF59 -> 0 | AI59: =(U59-X59)/Z59 -> 8.7826087 | AJ59: =_xlfn.NORM.S.DIST(AI59,1) -> 1 | AK59: =(W59-X59)/Z59 -> -8.7826087 | AL59: =_xlfn.NORM.S.DIST(AK59,1) -> 7.9863045e-19 | AM59: =AJ59-AL59 -> 1 | AN59: =AM59 -> 1 | AO59: =1-AM59 -> 0 | AP59: =AO59 -> 0
N60: 95 | O60: 0.00024 | P60: 0.00025 | Q60: 0.001 | R60: =N60+O60 -> 95.00024 | S60: =Q60 -> 0.001 | U60: =R60+S60 -> 95.00124 | W60: =R60-S60 -> 94.99924 | X60: =R60 -> 95.00024 | Y60: =P60 -> 0.00025 | Z60: =Y60/AA60 -> 0.00012376238 | AA60: 2.02 | AB60: =_xlfn.NORM.DIST(U60,X60,Z60,1) -> 1 | AC60: =_xlfn.NORM.DIST(W60,X60,Z60,1) -> 3.2383387e-16 | AD60: =AB60-AC60 -> 1 | AE60: =AD60 -> 1 | AF60: =1-AD60 -> 0 | AG60: =AF60 -> 0 | AI60: =(U60-X60)/Z60 -> 8.08 | AJ60: =_xlfn.NORM.S.DIST(AI60,1) -> 1 | AK60: =(W60-X60)/Z60 -> -8.08 | AL60: =_xlfn.NORM.S.DIST(AK60,1) -> 3.2383387e-16 | AM60: =AJ60-AL60 -> 1 | AN60: =AM60 -> 1 | AO60: =1-AM60 -> 0 | AP60: =AO60 -> 0
N61: 110 | O61: 0.00013 | P61: 0.00023 | Q61: 0.001 | R61: =N61+O61 -> 110.00013 | S61: =Q61 -> 0.001 | U61: =R61+S61 -> 110.00113 | W61: =R61-S61 -> 109.99913 | X61: =R61 -> 110.00013 | Y61: =P61 -> 0.00023 | Z61: =Y61/AA61 -> 0.00011386139 | AA61: 2.02 | AB61: =_xlfn.NORM.DIST(U61,X61,Z61,1) -> 1 | AC61: =_xlfn.NORM.DIST(W61,X61,Z61,1) -> 7.9863045e-19 | AD61: =AB61-AC61 -> 1 | AE61: =AD61 -> 1 | AF61: =1-AD61 -> 0 | AG61: =AF61 -> 0 | AI61: =(U61-X61)/Z61 -> 8.7826087 | AJ61: =_xlfn.NORM.S.DIST(AI61,1) -> 1 | AK61: =(W61-X61)/Z61 -> -8.7826087 | AL61: =_xlfn.NORM.S.DIST(AK61,1) -> 7.9863045e-19 | AM61: =AJ61-AL61 -> 1 | AN61: =AM61 -> 1 | AO61: =1-AM61 -> 0 | AP61: =AO61 -> 0
N62: 130 | O62: 0.0002 | P62: 0.00026 | Q62: 0.001 | R62: =N62+O62 -> 130.0002 | S62: =Q62 -> 0.001 | U62: =R62+S62 -> 130.0012 | W62: =R62-S62 -> 129.9992 | X62: =R62 -> 130.0002 | Y62: =P62 -> 0.00026 | Z62: =Y62/AA62 -> 0.00012871287 | AA62: 2.02 | AB62: =_xlfn.NORM.DIST(U62,X62,Z62,1) -> 1 | AC62: =_xlfn.NORM.DIST(W62,X62,Z62,1) -> 3.9482095e-15 | AD62: =AB62-AC62 -> 1 | AE62: =AD62 -> 1 | AF62: =1-AD62 -> 7.9936058e-15 | AG62: =AF62 -> 7.9936058e-15 | AI62: =(U62-X62)/Z62 -> 7.7692308 | AJ62: =_xlfn.NORM.S.DIST(AI62,1) -> 1 | AK62: =(W62-X62)/Z62 -> -7.7692308 | AL62: =_xlfn.NORM.S.DIST(AK62,1) -> 3.9482095e-15 | AM62: =AJ62-AL62 -> 1 | AN62: =AM62 -> 1 | AO62: =1-AM62 -> 7.9936058e-15 | AP62: =AO62 -> 7.9936058e-15
N63: 149.9999 | O63: 0.00029 | P63: 0.00026 | Q63: 0.001 | R63: =N63+O63 -> 150.00019 | S63: =Q63 -> 0.001 | U63: =R63+S63 -> 150.00119 | W63: =R63-S63 -> 149.99919 | X63: =R63 -> 150.00019 | Y63: =P63 -> 0.00026 | Z63: =Y63/AA63 -> 0.00012871287 | AA63: 2.02 | AB63: =_xlfn.NORM.DIST(U63,X63,Z63,1) -> 1 | AC63: =_xlfn.NORM.DIST(W63,X63,Z63,1) -> 3.9482095e-15 | AD63: =AB63-AC63 -> 1 | AE63: =AD63 -> 1 | AF63: =1-AD63 -> 7.9936058e-15 | AG63: =AF63 -> 7.9936058e-15 | AI63: =(U63-X63)/Z63 -> 7.7692308 | AJ63: =_xlfn.NORM.S.DIST(AI63,1) -> 1 | AK63: =(W63-X63)/Z63 -> -7.7692308 | AL63: =_xlfn.NORM.S.DIST(AK63,1) -> 3.9482095e-15 | AM63: =AJ63-AL63 -> 1 | AN63: =AM63 -> 1 | AO63: =1-AM63 -> 7.9936058e-15 | AP63: =AO63 -> 7.9936058e-15
N64: 164.9999 | O64: 0.00034 | P64: 0.0003 | Q64: 0.001 | R64: =N64+O64 -> 165.00024 | S64: =Q64 -> 0.001 | U64: =R64+S64 -> 165.00124 | W64: =R64-S64 -> 164.99924 | X64: =R64 -> 165.00024 | Y64: =P64 -> 0.0003 | Z64: =Y64/AA64 -> 0.00014851485 | AA64: 2.02 | AB64: =_xlfn.NORM.DIST(U64,X64,Z64,1) -> 1 | AC64: =_xlfn.NORM.DIST(W64,X64,Z64,1) -> 8.2909791e-12 | AD64: =AB64-AC64 -> 1 | AE64: =AD64 -> 1 | AF64: =1-AD64 -> 1.6582069e-11 | AG64: =AF64 -> 1.6582069e-11 | AI64: =(U64-X64)/Z64 -> 6.7333333 | AJ64: =_xlfn.NORM.S.DIST(AI64,1) -> 1 | AK64: =(W64-X64)/Z64 -> -6.7333333 | AL64: =_xlfn.NORM.S.DIST(AK64,1) -> 8.2909791e-12 | AM64: =AJ64-AL64 -> 1 | AN64: =AM64 -> 1 | AO64: =1-AM64 -> 1.6582069e-11 | AP64: =AO64 -> 1.6582069e-11
N65: 179.9999 | O65: 0.00038 | P65: 0.00031 | Q65: 0.001 | R65: =N65+O65 -> 180.00028 | S65: =Q65 -> 0.001 | U65: =R65+S65 -> 180.00128 | W65: =R65-S65 -> 179.99928 | X65: =R65 -> 180.00028 | Y65: =P65 -> 0.00031 | Z65: =Y65/AA65 -> 0.00015346535 | AA65: 2.02 | AB65: =_xlfn.NORM.DIST(U65,X65,Z65,1) -> 1 | AC65: =_xlfn.NORM.DIST(W65,X65,Z65,1) -> 3.6072461e-11 | AD65: =AB65-AC65 -> 1 | AE65: =AD65 -> 1 | AF65: =1-AD65 -> 7.2144957e-11 | AG65: =AF65 -> 7.2144957e-11 | AI65: =(U65-X65)/Z65 -> 6.516129 | AJ65: =_xlfn.NORM.S.DIST(AI65,1) -> 1 | AK65: =(W65-X65)/Z65 -> -6.516129 | AL65: =_xlfn.NORM.S.DIST(AK65,1) -> 3.6072461e-11 | AM65: =AJ65-AL65 -> 1 | AN65: =AM65 -> 1 | AO65: =1-AM65 -> 7.2144957e-11 | AP65: =AO65 -> 7.2144957e-11
N66: 195 | O66: 0.00034 | P66: 0.00034 | Q66: 0.001 | R66: =N66+O66 -> 195.00034 | S66: =Q66 -> 0.001 | U66: =R66+S66 -> 195.00134 | W66: =R66-S66 -> 194.99934 | X66: =R66 -> 195.00034 | Y66: =P66 -> 0.00034 | Z66: =Y66/AA66 -> 0.00016831683 | AA66: 2.02 | AB66: =_xlfn.NORM.DIST(U66,X66,Z66,1) -> 1 | AC66: =_xlfn.NORM.DIST(W66,X66,Z66,1) -> 1.4149189e-09 | AD66: =AB66-AC66 -> 1 | AE66: =AD66 -> 1 | AF66: =1-AD66 -> 2.8298377e-09 | AG66: =AF66 -> 2.8298377e-09 | AI66: =(U66-X66)/Z66 -> 5.9411765 | AJ66: =_xlfn.NORM.S.DIST(AI66,1) -> 1 | AK66: =(W66-X66)/Z66 -> -5.9411765 | AL66: =_xlfn.NORM.S.DIST(AK66,1) -> 1.4149189e-09 | AM66: =AJ66-AL66 -> 1 | AN66: =AM66 -> 1 | AO66: =1-AM66 -> 2.8298377e-09 | AP66: =AO66 -> 2.8298377e-09
N67: 210 | O67: 0.00019 | P67: 0.0003 | Q67: 0.001 | R67: =N67+O67 -> 210.00019 | S67: =Q67 -> 0.001 | U67: =R67+S67 -> 210.00119 | W67: =R67-S67 -> 209.99919 | X67: =R67 -> 210.00019 | Y67: =P67 -> 0.0003 | Z67: =Y67/AA67 -> 0.00014851485 | AA67: 2.02 | AB67: =_xlfn.NORM.DIST(U67,X67,Z67,1) -> 1 | AC67: =_xlfn.NORM.DIST(W67,X67,Z67,1) -> 8.2909791e-12 | AD67: =AB67-AC67 -> 1 | AE67: =AD67 -> 1 | AF67: =1-AD67 -> 1.6582069e-11 | AG67: =AF67 -> 1.6582069e-11 | AI67: =(U67-X67)/Z67 -> 6.7333333 | AJ67: =_xlfn.NORM.S.DIST(AI67,1) -> 1 | AK67: =(W67-X67)/Z67 -> -6.7333333 | AL67: =_xlfn.NORM.S.DIST(AK67,1) -> 8.2909791e-12 | AM67: =AJ67-AL67 -> 1 | AN67: =AM67 -> 1 | AO67: =1-AM67 -> 1.6582069e-11 | AP67: =AO67 -> 1.6582069e-11
C69: Simple
C70: Conservadora | M70: =Formato!Q79 -> 3. Prueba para los errores de las indicaciones | O70: =Formato!D15 -> Equipo de Pesaje | P70: =CONCATENATE(Formato!S20," a ",Formato!Y20," ",Formato!I20) -> 0,01 a 40 g | Q70: =Formato!I7 -> TM028-25A | R70: con w=0
G71: =IF(Formato!AL76="","",Formato!AL76) | N71: Indicación | O71: Error | P71: U | Q71: EMP | R71: Regla Decisión Simple | T71: [EMP] | U71: TU | V71: [-EMP] | W71: TL | AM71: PC | AO71: PC | AV71: PC | AX71: PC
B72: =S72 -> TL | C72: =IF(OR($G$71="",$G$71="N.A."),"",IF(AND(B74=C74,B75=C75,B76=C76),"AL=TL",T72)) | D72: =IF(OR($G$71="",$G$71="N.A."),"",IF(AND(D74=E74,E75=D75,E76=D76),"AL-=TL-",V72)) | E72: =CONCATENATE("-",S72) -> -TL | F72: Pc | G72: Conformidad | H72: Pc | I72: Lim inf | J72: Lim Sup | N72: =Formato!I20 -> g | O72: =N72 -> g | P72: =O72 -> g | Q72: =P72 -> g | R72: Carga | S72: TL | T72: AL | U72: TL | V72: AL- | W72: TL- | X72: y | Y72: U | Z72: uc | AA72: k | AB72: Pcu | AC72: PcL | AD72: PC | AF72: PC | AI72: Ztu | AJ72: =CONCATENATE("ɸ(",ROUND(AI74,2)," ) ") -> ɸ(-0,03 ) | AK72: ZTL | AL72: =CONCATENATE("ɸ(",ROUND(AK74,2)," ) ") -> ɸ(-0,03 ) | AM72: =CONCATENATE("ɸ(",ROUND(AI74,2)," ) - ","ɸ(",ROUND(AK74,2)," ) ") -> ɸ(-0,03 ) - ɸ(-0,03 ) | AR72: Ztu | AS72: =CONCATENATE("ɸ(",ROUND(AR74,2)," ) ") -> ɸ(-0,03 ) | AT72: ZTL | AU72: =CONCATENATE("ɸ(",ROUND(AT74,2)," ) ") -> ɸ(-0,03 ) | AV72: =CONCATENATE("ɸ(",ROUND(AR74,2)," ) - ","ɸ(",ROUND(AT74,2)," ) ") -> ɸ(-0,03 ) - ɸ(-0,03 )
B73: =IF(Formato!$AL$76=$C$70,S90,S73) -> 0 | C73: =IF(OR($G$71="",$G$71="N.A."),"",IF(Formato!$AL$76=$C$70,T90,T73)) | D73: =IF(OR($G$71="",$G$71="N.A."),"",IF(Formato!$AL$76=$C$70,V90,V73)) | E73: =IF(Formato!$AL$76=$C$70,-S90,-S73) -> 0 | F73: =IF(Formato!$AL$76=$C$70,AG90,AG73) -> 1 | G73: ='Certificado de calibración'!S127 -> N.A. | H73: =IF(G73="Cumple",F73,"") | I73: =-Q73+P73 -> 2.3459923e-05 | J73: =Q73-P73 -> -2.3459923e-05 | K73: =O73>I73 -> FALSE | L73: =O73<J73 -> FALSE | N73: =Formato!X82 -> 0 | O73: =Formato!AL82 -> 0 | P73: =Formato!AK82 -> 2.3459923e-05 | Q73: =Formato!$G$21 -> 0 | R73: =N73+O73 -> 0 | S73: =Q73 -> 0 | T73: =S73 -> 0 | U73: =N73+S73 -> 0 | V73: =-S73 -> 0 | W73: =N73-S73 -> 0 | X73: =R73 -> 0 | Y73: =P73 -> 2.3459923e-05 | Z73: =Y73/AA73 -> 3.480779e-06 | AA73: ='Estimación de la Incertidumbre'!H38 -> 6.7398486 | AB73: =_xlfn.NORM.DIST(U73,X73,Z73,1) -> 0.5 | AC73: =_xlfn.NORM.DIST(W73,X73,Z73,1) -> 0.5 | AD73: =AB73-AC73 -> 0 | AE73: =AD73 -> 0 | AF73: =1-AD73 -> 1 | AG73: =AF73 -> 1 | AI73: =(U73-X73)/Z73 -> 0 | AJ73: =_xlfn.NORM.S.DIST(AI73,1) -> 0.5 | AK73: =(W73-X73)/Z73 -> 0 | AL73: =_xlfn.NORM.S.DIST(AK73,1) -> 0.5 | AM73: =AJ73-AL73 -> 0 | AN73: =AM73 -> 0 | AO73: =1-AM73 -> 1 | AP73: =AO73 -> 1 | AR73: =(U73-X73)/Z73 -> 0 | AS73: =NORMSDIST(AR73) -> 0.5 | AT73: =(W73-X73)/Z73 -> 0 | AU73: =NORMSDIST(AT73) -> 0.5 | AV73: =AS73-AU73 -> 0 | AW73: =AV73 -> 0 | AX73: =1-AV73 -> 1 | AY73: =AX73 -> 1
A74: 1 | B74: =IF(Formato!$AL$76=$C$70,S91,S74) -> 0 | C74: =IF(OR($G$71="",$G$71="N.A."),"",IF(Formato!$AL$76=$C$70,T91,T74)) | D74: =IF(OR($G$71="",$G$71="N.A."),"",IF(Formato!$AL$76=$C$70,V91,V74)) | E74: =IF(Formato!$AL$76=$C$70,-S91,-S74) -> 0 | F74: =IF(Formato!$AL$76=$C$70,AG91,AG74) -> 1 | G74: ='Certificado de calibración'!S128 -> N.A. | H74: =IF(G74="Cumple",F74,"") | I74: =-Q74+P74 -> 2.402859e-05 | J74: =Q74-P74 -> -2.402859e-05 | K74: =O74>I74 -> FALSE | L74: =O74<J74 -> FALSE | N74: =Formato!X87 -> 0.01 | O74: =Formato!AL87 -> 2.9894352e-07 | P74: =Formato!AK87 -> 2.402859e-05 | Q74: =Formato!$G$21 -> 0 | R74: =N74+O74 -> 0.010000299 | S74: =Q74 -> 0 | T74: =S74 -> 0 | U74: =N74+S74 -> 0.01 | V74: =-S74 -> 0 | W74: =N74-S74 -> 0.01 | X74: =R74 -> 0.010000299 | Y74: =P74 -> 2.402859e-05 | Z74: =Y74/AA74 -> 9.5351549e-06 | AA74: ='Estimación de la Incertidumbre'!H39 -> 2.52 | AB74: =_xlfn.NORM.DIST(U74,X74,Z74,1) -> 0.48749452 | AC74: =_xlfn.NORM.DIST(W74,X74,Z74,1) -> 0.48749452 | AD74: =AB74-AC74 -> 0 | AE74: =AD74 -> 0 | AF74: =1-AD74 -> 1 | AG74: =AF74 -> 1 | AI74: =(U74-X74)/Z74 -> -0.031351721 | AJ74: =_xlfn.NORM.S.DIST(AI74,1) -> 0.48749452 | AK74: =(W74-X74)/Z74 -> -0.031351721 | AL74: =_xlfn.NORM.S.DIST(AK74,1) -> 0.48749452 | AM74: =AJ74-AL74 -> 0 | AN74: =AM74 -> 0 | AO74: =1-AM74 -> 1 | AP74: =AO74 -> 1 | AR74: =(U74-X74)/Z74 -> -0.031351721 | AS74: =NORMSDIST(AR74) -> 0.48749452 | AT74: =(W74-X74)/Z74 -> -0.031351721 | AU74: =NORMSDIST(AT74) -> 0.48749452 | AV74: =AS74-AU74 -> 0 | AW74: =AV74 -> 0 | AX74: =1-AV74 -> 1 | AY74: =AX74 -> 1
A75: 2 | B75: =IF(Formato!$AL$76=$C$70,S92,S75) -> 0 | C75: =IF(OR($G$71="",$G$71="N.A."),"",IF(Formato!$AL$76=$C$70,T92,T75)) | D75: =IF(OR($G$71="",$G$71="N.A."),"",IF(Formato!$AL$76=$C$70,V92,V75)) | E75: =IF(Formato!$AL$76=$C$70,-S92,-S75) -> 0 | F75: =IF(Formato!$AL$76=$C$70,AG92,AG75) -> 1 | G75: ='Certificado de calibración'!S129 -> N.A. | H75: =IF(G75="Cumple",F75,"") | I75: =-Q75+P75 -> 4.4398152e-05 | J75: =Q75-P75 -> -4.4398152e-05 | K75: =O75>I75 -> FALSE | L75: =O75<J75 -> FALSE | N75: =Formato!X92 -> 4 | O75: =Formato!AL92 -> 5.5773944e-06 | P75: =Formato!AK92 -> 4.4398152e-05 | Q75: =Formato!$G$21 -> 0 | R75: =N75+O75 -> 4.0000056 | S75: =Q75 -> 0 | T75: =S75 -> 0 | U75: =N75+S75 -> 4 | V75: =-S75 -> 0 | W75: =N75-S75 -> 4 | X75: =R75 -> 4.0000056 | Y75: =P75 -> 4.4398152e-05 | Z75: =Y75/AA75 -> 2.1979283e-05 | AA75: ='Estimación de la Incertidumbre'!I39 -> 2.02 | AB75: =_xlfn.NORM.DIST(U75,X75,Z75,1) -> 0.39984169 | AC75: =_xlfn.NORM.DIST(W75,X75,Z75,1) -> 0.39984169 | AD75: =AB75-AC75 -> 0 | AE75: =AD75 -> 0 | AF75: =1-AD75 -> 1 | AG75: =AF75 -> 1 | AI75: =(U75-X75)/Z75 -> -0.25375688 | AJ75: =_xlfn.NORM.S.DIST(AI75,1) -> 0.39984169 | AK75: =(W75-X75)/Z75 -> -0.25375688 | AL75: =_xlfn.NORM.S.DIST(AK75,1) -> 0.39984169 | AM75: =AJ75-AL75 -> 0 | AN75: =AM75 -> 0 | AO75: =1-AM75 -> 1 | AP75: =AO75 -> 1 | AR75: =(U75-X75)/Z75 -> -0.25375688 | AS75: =NORMSDIST(AR75) -> 0.39984169 | AT75: =(W75-X75)/Z75 -> -0.25375688 | AU75: =NORMSDIST(AT75) -> 0.39984169 | AV75: =AS75-AU75 -> 0 | AW75: =AV75 -> 0 | AX75: =1-AV75 -> 1 | AY75: =AX75 -> 1
A76: 3 | B76: =IF(Formato!$AL$76=$C$70,S93,S76) -> 0 | C76: =IF(OR($G$71="",$G$71="N.A."),"",IF(Formato!$AL$76=$C$70,T93,T76)) | D76: =IF(OR($G$71="",$G$71="N.A."),"",IF(Formato!$AL$76=$C$70,V93,V76)) | E76: =IF(Formato!$AL$76=$C$70,-S93,-S76) -> 0 | F76: =IF(Formato!$AL$76=$C$70,AG93,AG76) -> 1 | G76: ='Certificado de calibración'!S130 -> N.A. | H76: =IF(G76="Cumple",F76,"") | I76: =-Q76+P76 -> 6.4456648e-05 | J76: =Q76-P76 -> -6.4456648e-05 | K76: =O76>I76 -> FALSE | L76: =O76<J76 -> FALSE | N76: =Formato!X97 -> 8 | O76: =Formato!AL97 -> 1.2154789e-05 | P76: =Formato!AK97 -> 6.4456648e-05 | Q76: =Formato!$G$21 -> 0 | R76: =N76+O76 -> 8.0000122 | S76: =Q76 -> 0 | T76: =S76 -> 0 | U76: =N76+S76 -> 8 | V76: =-S76 -> 0 | W76: =N76-S76 -> 8 | X76: =R76 -> 8.0000122 | Y76: =P76 -> 6.4456648e-05 | Z76: =Y76/AA76 -> 3.2067984e-05 | AA76: ='Estimación de la Incertidumbre'!J39 -> 2.01 | AB76: =_xlfn.NORM.DIST(U76,X76,Z76,1) -> 0.35233209 | AC76: =_xlfn.NORM.DIST(W76,X76,Z76,1) -> 0.35233209 | AD76: =AB76-AC76 -> 0 | AE76: =AD76 -> 0 | AF76: =1-AD76 -> 1 | AG76: =AF76 -> 1 | AI76: =(U76-X76)/Z76 -> -0.3790319 | AJ76: =_xlfn.NORM.S.DIST(AI76,1) -> 0.35233209 | AK76: =(W76-X76)/Z76 -> -0.3790319 | AL76: =_xlfn.NORM.S.DIST(AK76,1) -> 0.35233209 | AM76: =AJ76-AL76 -> 0 | AN76: =AM76 -> 0 | AO76: =1-AM76 -> 1 | AP76: =AO76 -> 1 | AR76: =(U76-X76)/Z76 -> -0.3790319 | AS76: =NORMSDIST(AR76) -> 0.35233209 | AT76: =(W76-X76)/Z76 -> -0.3790319 | AU76: =NORMSDIST(AT76) -> 0.35233209 | AV76: =AS76-AU76 -> 0 | AW76: =AV76 -> 0 | AX76: =1-AV76 -> 1 | AY76: =AX76 -> 1
A77: 4 | B77: =IF(Formato!$AL$76=$C$70,S94,S77) -> 0 | C77: =IF(OR($G$71="",$G$71="N.A."),"",IF(Formato!$AL$76=$C$70,T94,T77)) | D77: =IF(OR($G$71="",$G$71="N.A."),"",IF(Formato!$AL$76=$C$70,V94,V77)) | E77: =IF(Formato!$AL$76=$C$70,-S94,-S77) -> 0 | F77: =IF(Formato!$AL$76=$C$70,AG94,AG77) -> 1 | G77: ='Certificado de calibración'!S131 -> N.A. | H77: =IF(G77="Cumple",F77,"") | I77: =-Q77+P77 -> 5.5921729e-05 | J77: =Q77-P77 -> -5.5921729e-05 | K77: =O77>I77 -> FALSE | L77: =O77<J77 -> FALSE | N77: =Formato!X102 -> 12 | O77: =Formato!AL102 -> -1.2678196e-06 | P77: =Formato!AK102 -> 5.5921729e-05 | Q77: =Formato!$G$21 -> 0 | R77: =N77+O77 -> 11.999999 | S77: =Q77 -> 0 | T77: =S77 -> 0 | U77: =N77+S77 -> 12 | V77: =-S77 -> 0 | W77: =N77-S77 -> 12 | X77: =R77 -> 11.999999 | Y77: =P77 -> 5.5921729e-05 | Z77: =Y77/AA77 -> 2.7821756e-05 | AA77: ='Estimación de la Incertidumbre'!K39 -> 2.01 | AB77: =_xlfn.NORM.DIST(U77,X77,Z77,1) -> 0.51817325 | AC77: =_xlfn.NORM.DIST(W77,X77,Z77,1) -> 0.51817325 | AD77: =AB77-AC77 -> 0 | AE77: =AD77 -> 0 | AF77: =1-AD77 -> 1 | AG77: =AF77 -> 1 | AI77: =(U77-X77)/Z77 -> 0.045569361 | AJ77: =_xlfn.NORM.S.DIST(AI77,1) -> 0.51817325 | AK77: =(W77-X77)/Z77 -> 0.045569361 | AL77: =_xlfn.NORM.S.DIST(AK77,1) -> 0.51817325 | AM77: =AJ77-AL77 -> 0 | AN77: =AM77 -> 0 | AO77: =1-AM77 -> 1 | AP77: =AO77 -> 1 | AR77: =(U77-X77)/Z77 -> 0.045569361 | AS77: =NORMSDIST(AR77) -> 0.51817325 | AT77: =(W77-X77)/Z77 -> 0.045569361 | AU77: =NORMSDIST(AT77) -> 0.51817325 | AV77: =AS77-AU77 -> 0 | AW77: =AV77 -> 0 | AX77: =1-AV77 -> 1 | AY77: =AX77 -> 1
A78: 5 | B78: =IF(Formato!$AL$76=$C$70,S95,S78) -> 0 | C78: =IF(OR($G$71="",$G$71="N.A."),"",IF(Formato!$AL$76=$C$70,T95,T78)) | D78: =IF(OR($G$71="",$G$71="N.A."),"",IF(Formato!$AL$76=$C$70,V95,V78)) | E78: =IF(Formato!$AL$76=$C$70,-S95,-S78) -> 0 | F78: =IF(Formato!$AL$76=$C$70,AG95,AG78) -> 1 | G78: ='Certificado de calibración'!S132 -> N.A. | H78: =IF(G78="Cumple",F78,"") | I78: =-Q78+P78 -> 6.1885758e-05 | J78: =Q78-P78 -> -6.1885758e-05 | K78: =O78>I78 -> FALSE | L78: =O78<J78 -> FALSE | N78: =Formato!X107 -> 15.00001 | O78: =Formato!AL107 -> 1.0415226e-05 | P78: =Formato!AK107 -> 6.1885758e-05 | Q78: =Formato!$G$21 -> 0 | R78: =N78+O78 -> 15.00002 | S78: =Q78 -> 0 | T78: =S78 -> 0 | U78: =N78+S78 -> 15.00001 | V78: =-S78 -> 0 | W78: =N78-S78 -> 15.00001 | X78: =R78 -> 15.00002 | Y78: =P78 -> 6.1885758e-05 | Z78: =Y78/AA78 -> 3.0788934e-05 | AA78: ='Estimación de la Incertidumbre'!L39 -> 2.01 | AB78: =_xlfn.NORM.DIST(U78,X78,Z78,1) -> 0.36757677 | AC78: =_xlfn.NORM.DIST(W78,X78,Z78,1) -> 0.36757677 | AD78: =AB78-AC78 -> 0 | AE78: =AD78 -> 0 | AF78: =1-AD78 -> 1 | AG78: =AF78 -> 1 | AI78: =(U78-X78)/Z78 -> -0.33827822 | AJ78: =_xlfn.NORM.S.DIST(AI78,1) -> 0.36757677 | AK78: =(W78-X78)/Z78 -> -0.33827822 | AL78: =_xlfn.NORM.S.DIST(AK78,1) -> 0.36757677 | AM78: =AJ78-AL78 -> 0 | AN78: =AM78 -> 0 | AO78: =1-AM78 -> 1 | AP78: =AO78 -> 1 | AR78: =(U78-X78)/Z78 -> -0.33827822 | AS78: =NORMSDIST(AR78) -> 0.36757677 | AT78: =(W78-X78)/Z78 -> -0.33827822 | AU78: =NORMSDIST(AT78) -> 0.36757677 | AV78: =AS78-AU78 -> 0 | AW78: =AV78 -> 0 | AX78: =1-AV78 -> 1 | AY78: =AX78 -> 1
A79: 6 | B79: =IF(Formato!$AL$76=$C$70,S96,S79) -> 0 | C79: =IF(OR($G$71="",$G$71="N.A."),"",IF(Formato!$AL$76=$C$70,T96,T79)) | D79: =IF(OR($G$71="",$G$71="N.A."),"",IF(Formato!$AL$76=$C$70,V96,V79)) | E79: =IF(Formato!$AL$76=$C$70,-S96,-S79) -> 0 | F79: =IF(Formato!$AL$76=$C$70,AG96,AG79) -> 1 | G79: ='Certificado de calibración'!S133 -> N.A. | H79: =IF(G79="Cumple",F79,"") | I79: =-Q79+P79 -> 4.9375364e-05 | J79: =Q79-P79 -> -4.9375364e-05 | K79: =O79>I79 -> FALSE | L79: =O79<J79 -> FALSE | N79: =Formato!X112 -> 20 | O79: =Formato!AL112 -> 3.8869686e-06 | P79: =Formato!AK112 -> 4.9375364e-05 | Q79: =Formato!$G$21 -> 0 | R79: =N79+O79 -> 20.000004 | S79: =Q79 -> 0 | T79: =S79 -> 0 | U79: =N79+S79 -> 20 | V79: =-S79 -> 0 | W79: =N79-S79 -> 20 | X79: =R79 -> 20.000004 | Y79: =P79 -> 4.9375364e-05 | Z79: =Y79/AA79 -> 2.444325e-05 | AA79: ='Estimación de la Incertidumbre'!M39 -> 2.02 | AB79: =_xlfn.NORM.DIST(U79,X79,Z79,1) -> 0.43682651 | AC79: =_xlfn.NORM.DIST(W79,X79,Z79,1) -> 0.43682651 | AD79: =AB79-AC79 -> 0 | AE79: =AD79 -> 0 | AF79: =1-AD79 -> 1 | AG79: =AF79 -> 1 | AI79: =(U79-X79)/Z79 -> -0.15902013 | AJ79: =_xlfn.NORM.S.DIST(AI79,1) -> 0.43682651 | AK79: =(W79-X79)/Z79 -> -0.15902013 | AL79: =_xlfn.NORM.S.DIST(AK79,1) -> 0.43682651 | AM79: =AJ79-AL79 -> 0 | AN79: =AM79 -> 0 | AO79: =1-AM79 -> 1 | AP79: =AO79 -> 1 | AR79: =(U79-X79)/Z79 -> -0.15902013 | AS79: =NORMSDIST(AR79) -> 0.43682651 | AT79: =(W79-X79)/Z79 -> -0.15902013 | AU79: =NORMSDIST(AT79) -> 0.43682651 | AV79: =AS79-AU79 -> 0 | AW79: =AV79 -> 0 | AX79: =1-AV79 -> 1 | AY79: =AX79 -> 1
A80: 7 | B80: =IF(Formato!$AL$76=$C$70,S97,S80) -> 0 | C80: =IF(OR($G$71="",$G$71="N.A."),"",IF(Formato!$AL$76=$C$70,T97,T80)) | D80: =IF(OR($G$71="",$G$71="N.A."),"",IF(Formato!$AL$76=$C$70,V97,V80)) | E80: =IF(Formato!$AL$76=$C$70,-S97,-S80) -> 0 | F80: =IF(Formato!$AL$76=$C$70,AG97,AG80) -> 1 | G80: ='Certificado de calibración'!S134 -> N.A. | H80: =IF(G80="Cumple",F80,"") | I80: =-Q80+P80 -> 7.3328671e-05 | J80: =Q80-P80 -> -7.3328671e-05 | K80: =O80>I80 -> FALSE | L80: =O80<J80 -> FALSE | N80: =Formato!X117 -> 25.00001 | O80: =Formato!AL117 -> 2.5358712e-05 | P80: =Formato!AK117 -> 7.3328671e-05 | Q80: =Formato!$G$21 -> 0 | R80: =N80+O80 -> 25.000035 | S80: =Q80 -> 0 | T80: =S80 -> 0 | U80: =N80+S80 -> 25.00001 | V80: =-S80 -> 0 | W80: =N80-S80 -> 25.00001 | X80: =R80 -> 25.000035 | Y80: =P80 -> 7.3328671e-05 | Z80: =Y80/AA80 -> 3.6481926e-05 | AA80: ='Estimación de la Incertidumbre'!N39 -> 2.01 | AB80: =_xlfn.NORM.DIST(U80,X80,Z80,1) -> 0.24349524 | AC80: =_xlfn.NORM.DIST(W80,X80,Z80,1) -> 0.24349524 | AD80: =AB80-AC80 -> 0 | AE80: =AD80 -> 0 | AF80: =1-AD80 -> 1 | AG80: =AF80 -> 1 | AI80: =(U80-X80)/Z80 -> -0.69510344 | AJ80: =_xlfn.NORM.S.DIST(AI80,1) -> 0.24349524 | AK80: =(W80-X80)/Z80 -> -0.69510344 | AL80: =_xlfn.NORM.S.DIST(AK80,1) -> 0.24349524 | AM80: =AJ80-AL80 -> 0 | AN80: =AM80 -> 0 | AO80: =1-AM80 -> 1 | AP80: =AO80 -> 1 | AR80: =(U80-X80)/Z80 -> -0.69510344 | AS80: =NORMSDIST(AR80) -> 0.24349524 | AT80: =(W80-X80)/Z80 -> -0.69510344 | AU80: =NORMSDIST(AT80) -> 0.24349524 | AV80: =AS80-AU80 -> 0 | AW80: =AV80 -> 0 | AX80: =1-AV80 -> 1 | AY80: =AX80 -> 1
A81: 8 | B81: =IF(Formato!$AL$76=$C$70,S98,S81) -> 0 | C81: =IF(OR($G$71="",$G$71="N.A."),"",IF(Formato!$AL$76=$C$70,T98,T81)) | D81: =IF(OR($G$71="",$G$71="N.A."),"",IF(Formato!$AL$76=$C$70,V98,V81)) | E81: =IF(Formato!$AL$76=$C$70,-S98,-S81) -> 0 | F81: =IF(Formato!$AL$76=$C$70,AG98,AG81) -> 1 | G81: ='Certificado de calibración'!S135 -> N.A. | H81: =IF(G81="Cumple",F81,"") | I81: =-Q81+P81 -> 9.2338128e-05 | J81: =Q81-P81 -> -9.2338128e-05 | K81: =O81>I81 -> FALSE | L81: =O81<J81 -> FALSE | N81: =Formato!X122 -> 27.00001 | O81: =Formato!AL122 -> 3.514741e-05 | P81: =Formato!AK122 -> 9.2338128e-05 | Q81: =Formato!$G$21 -> 0 | R81: =N81+O81 -> 27.000045 | S81: =Q81 -> 0 | T81: =S81 -> 0 | U81: =N81+S81 -> 27.00001 | V81: =-S81 -> 0 | W81: =N81-S81 -> 27.00001 | X81: =R81 -> 27.000045 | Y81: =P81 -> 9.2338128e-05 | Z81: =Y81/AA81 -> 4.5939367e-05 | AA81: ='Estimación de la Incertidumbre'!O39 -> 2.01 | AB81: =_xlfn.NORM.DIST(U81,X81,Z81,1) -> 0.22211118 | AC81: =_xlfn.NORM.DIST(W81,X81,Z81,1) -> 0.22211118 | AD81: =AB81-AC81 -> 0 | AE81: =AD81 -> 0 | AF81: =1-AD81 -> 1 | AG81: =AF81 -> 1 | AI81: =(U81-X81)/Z81 -> -0.7650826 | AJ81: =_xlfn.NORM.S.DIST(AI81,1) -> 0.22211118 | AK81: =(W81-X81)/Z81 -> -0.7650826 | AL81: =_xlfn.NORM.S.DIST(AK81,1) -> 0.22211118 | AM81: =AJ81-AL81 -> 0 | AN81: =AM81 -> 0 | AO81: =1-AM81 -> 1 | AP81: =AO81 -> 1 | AR81: =(U81-X81)/Z81 -> -0.7650826 | AS81: =NORMSDIST(AR81) -> 0.22211118 | AT81: =(W81-X81)/Z81 -> -0.7650826 | AU81: =NORMSDIST(AT81) -> 0.22211118 | AV81: =AS81-AU81 -> 0 | AW81: =AV81 -> 0 | AX81: =1-AV81 -> 1 | AY81: =AX81 -> 1
A82: 9 | B82: =IF(Formato!$AL$76=$C$70,S99,S82) -> 0 | C82: =IF(OR($G$71="",$G$71="N.A."),"",IF(Formato!$AL$76=$C$70,T99,T82)) | D82: =IF(OR($G$71="",$G$71="N.A."),"",IF(Formato!$AL$76=$C$70,V99,V82)) | E82: =IF(Formato!$AL$76=$C$70,-S99,-S82) -> 0 | F82: =IF(Formato!$AL$76=$C$70,AG99,AG82) -> 1 | G82: ='Certificado de calibración'!S136 -> N.A. | H82: =IF(G82="Cumple",F82,"") | I82: =-Q82+P82 -> 8.1052708e-05 | J82: =Q82-P82 -> -8.1052708e-05 | K82: =O82>I82 -> FALSE | L82: =O82<J82 -> FALSE | N82: =Formato!X127 -> 30.00001 | O82: =Formato!AL127 -> 2.8304511e-06 | P82: =Formato!AK127 -> 8.1052708e-05 | Q82: =Formato!$G$21 -> 0 | R82: =N82+O82 -> 30.000013 | S82: =Q82 -> 0 | T82: =S82 -> 0 | U82: =N82+S82 -> 30.00001 | V82: =-S82 -> 0 | W82: =N82-S82 -> 30.00001 | X82: =R82 -> 30.000013 | Y82: =P82 -> 8.1052708e-05 | Z82: =Y82/AA82 -> 4.032473e-05 | AA82: ='Estimación de la Incertidumbre'!P39 -> 2.01 | AB82: =_xlfn.NORM.DIST(U82,X82,Z82,1) -> 0.47202064 | AC82: =_xlfn.NORM.DIST(W82,X82,Z82,1) -> 0.47202064 | AD82: =AB82-AC82 -> 0 | AE82: =AD82 -> 0 | AF82: =1-AD82 -> 1 | AG82: =AF82 -> 1 | AI82: =(U82-X82)/Z82 -> -0.070191445 | AJ82: =_xlfn.NORM.S.DIST(AI82,1) -> 0.47202064 | AK82: =(W82-X82)/Z82 -> -0.070191445 | AL82: =_xlfn.NORM.S.DIST(AK82,1) -> 0.47202064 | AM82: =AJ82-AL82 -> 0 | AN82: =AM82 -> 0 | AO82: =1-AM82 -> 1 | AP82: =AO82 -> 1 | AR82: =(U82-X82)/Z82 -> -0.070191445 | AS82: =NORMSDIST(AR82) -> 0.47202064 | AT82: =(W82-X82)/Z82 -> -0.070191445 | AU82: =NORMSDIST(AT82) -> 0.47202064 | AV82: =AS82-AU82 -> 0 | AW82: =AV82 -> 0 | AX82: =1-AV82 -> 1 | AY82: =AX82 -> 1
A83: 10 | B83: =IF(Formato!$AL$76=$C$70,S100,S83) -> 0 | C83: =IF(OR($G$71="",$G$71="N.A."),"",IF(Formato!$AL$76=$C$70,T100,T83)) | D83: =IF(OR($G$71="",$G$71="N.A."),"",IF(Formato!$AL$76=$C$70,V100,V83)) | E83: =IF(Formato!$AL$76=$C$70,-S100,-S83) -> 0 | F83: =IF(Formato!$AL$76=$C$70,AG100,AG83) -> 1 | G83: ='Certificado de calibración'!S137 -> N.A. | H83: =IF(G83="Cumple",F83,"") | I83: =-Q83+P83 -> 0.00010577384 | J83: =Q83-P83 -> -0.00010577384 | K83: =O83>I83 -> FALSE | L83: =O83<J83 -> FALSE | N83: =Formato!X133 -> 35.00002 | O83: =Formato!AL133 -> 2.4302195e-05 | P83: =Formato!AK133 -> 0.00010577384 | Q83: =Formato!$G$21 -> 0 | R83: =N83+O83 -> 35.000044 | S83: =Q83 -> 0 | T83: =S83 -> 0 | U83: =N83+S83 -> 35.00002 | V83: =-S83 -> 0 | W83: =N83-S83 -> 35.00002 | X83: =R83 -> 35.000044 | Y83: =P83 -> 0.00010577384 | Z83: =Y83/AA83 -> 5.2623803e-05 | AA83: ='Estimación de la Incertidumbre'!Q39 -> 2.01 | AB83: =_xlfn.NORM.DIST(U83,X83,Z83,1) -> 0.32210882 | AC83: =_xlfn.NORM.DIST(W83,X83,Z83,1) -> 0.32210882 | AD83: =AB83-AC83 -> 0 | AE83: =AD83 -> 0 | AF83: =1-AD83 -> 1 | AG83: =AF83 -> 1 | AI83: =(U83-X83)/Z83 -> -0.46180993 | AJ83: =_xlfn.NORM.S.DIST(AI83,1) -> 0.32210882 | AK83: =(W83-X83)/Z83 -> -0.46180993 | AL83: =_xlfn.NORM.S.DIST(AK83,1) -> 0.32210882 | AM83: =AJ83-AL83 -> 0 | AN83: =AM83 -> 0 | AO83: =1-AM83 -> 1 | AP83: =AO83 -> 1 | AR83: =(U83-X83)/Z83 -> -0.46180993 | AS83: =NORMSDIST(AR83) -> 0.32210882 | AT83: =(W83-X83)/Z83 -> -0.46180993 | AU83: =NORMSDIST(AT83) -> 0.32210882 | AV83: =AS83-AU83 -> 0 | AW83: =AV83 -> 0 | AX83: =1-AV83 -> 1 | AY83: =AX83 -> 1
...

Sheet Formato
S1: CALIBRACIÓN INSTRUMENTOS DE PESAJE DE FUNCIONAMIENTO NO AUTOMATICO, LC-FR-20 V12
S2: CD-372-24
A4: Revisado Director Técnico, 2024-12-17 - Aprobado Gerente General, 2024-12-18
AX5: SI | AZ5: Analógico
AX6: NO | AZ6: Digital
A7: Certificado de calibración No: | I7: TM028-25A | S7: Fecha de calibración: | Y7: 45678 | AX7: N/A
A8: Hora inicio climatización pesas: | I8: 0.58333333 | S8: Hora final climatización pesas: | Y8: =IF(ISBLANK(T52),"",T52) -> 0.60555556
A9: Hora inicio de la calibración: | I9: 0.60763889 | S9: Hora final de la calibración: | Y9: =IF(ISBLANK(AD152),"",AD152) -> 0.62986111 | AX9: Kg/dm3
AX10: g/cm3
A11: Información del cliente
A12: Cliente: | D12: TECSERVICE S.A.S. | M12: Dirección: | P12: Avenida 4 A Norte No. 45 - 56 B / La Flora | X12: Ciudad : | AA12: Cali
A13: Contacto | D13: Jhon Jairo Carabali | M13: Telefono | P13: 315 866 50 13 | X13: Pais: | AA13: Colombia
A14: Información del instrumento
A15: Instrumento: | D15: Equipo de Pesaje | N15: Fabricante: | Q15: Mettler | X15: Modelo: | Z15: AE240
A16: Número de serie: | E16: J75412 | N16: Código interno: | Q16: TEC-MTT-BA-03 | X16: Ubicación: | Z16: Mantenimiento
A17: Tipo indicación: | E17: Digital
BA18: Numero decimales
A19: Características metrológicas del instrumento de pesaje | AX19: =+IF(MID(AE20,5,1)="","--",1) -> 1 | AY19: =+IF(MID(AE20,6,1)="","--",1) -> 1 | AZ19: =+IF(MID(AE20,7,1)="","--",1) -> 1 | BA19: =+COUNT(AH20:AL20) -> 2
A20: Intervalo del Equipo: | E20: 0 | I20: g | J20: Hasta | L20: 200 | N20: =IF(ISBLANK(I20),"",I20) -> g | O20: Intervalos a calibrar: | S20: 0.01 | V20: =IF(ISBLANK(I20),"",I20) -> g | Y20: 40 | AA20: =IF(ISBLANK(I20),"",I20) -> g | AB20: Resolución: | AE20: 1e-05 | AF20: =IF(ISBLANK(I20),"",I20) -> g | AH20: =+IF(MID(AE20,3,1)="","--",1) -> 1 | AI20: =+IF(MID(AE20,4,1)="","--",1) -> 1
A21: Error Maximo Permitido Lineal: | N21: Error Maximo Permitido Repetibilidad: | AA21: Div. de escala: | AF21: =IF(AE21="N.A.","N.A.",AF20) -> g
AF22: =IF(AE20>=1,0,ABS(LEN(AE20)-2)) -> 5
A23: Evaluación visual de las características de funcionamiento y ubicación del instrumento de pesaje
A24: Características a evaluar: | X24: Cumple | Z24: Observaciones
X25: Si | Y25: No
A26: El instrumento esta claramente identificado ? | X26: X
A27: El instrumento esta libre de polvo, sustancias o agentes que alteren el resultado de la medición? | X27: X
A28: La indicación del instrumento es legible? | X28: X
A29: Las condiciones normales de uso (flujo de aire, vibraciones, estabilidad del lugar de pesada, etc.) son apropiados para el instrumento para pesar que se calibrará.? | X29: X
A30: Si aplica, el instrumento esta nivelado ? | X30: X
A31: El cliente ajusta regularmente el instrumento? | X31: X
A32: El instrumento se enciende un período antes de la calibración, p. e., un tiempo apropiado para que el instrumento se caliente, ó el adoptado por el cliente ? | X32: X
I34: Trazabilidad Masas Patron
I35: Código | O35: Descripción | AA35: Fecha Proxima Calibración
H36: =MID(I36,12,2) -> 04 | I36: TEC-LAB-MP-04 | O36: =IF(I36="","",VLOOKUP(I36,AG190:AI202,2,FALSE)) -> KIT DE MASAS PATRON E2 | AA36: =IF(I36="","",VLOOKUP(I36,'Errores Patrones'!AB4:AG25,5,FALSE)) -> 45696 | AE36: =IF(AA36<TODAY(),"Ojo EQ Vencido","") | AX36: =+TODAY() -> 45681
H37: =MID(I37,12,2) | O37: =IF(I37="","",VLOOKUP(I37,AG190:AI202,2,FALSE)) | AA37: =IF(I37="","",VLOOKUP(I37,'Errores Patrones'!AB4:AG25,5,FALSE)) | AE37: =IF(AA37<TODAY(),"Ojo EQ Vencido","") | AL37: =IF(AND(AF20="g",AE20<=0.00001),1,IF(AND(AF20="mg",AE20<=0.01),1,2)) -> 1
H38: =MID(I38,12,2) | O38: =IF(I38="","",VLOOKUP(I38,AG190:AI202,2,FALSE)) | AA38: =IF(I38="","",VLOOKUP(I38,'Errores Patrones'!AB4:AG25,5,FALSE)) | AE38: =IF(AA38<TODAY(),"Ojo EQ Vencido","")
H39: =MID(I39,12,2) | O39: =IF(I39="","",VLOOKUP(I39,AG190:AI202,2,FALSE)) | AA39: =IF(I39="","",VLOOKUP(I39,'Errores Patrones'!AB4:AG25,5,FALSE)) | AE39: =IF(AA39<TODAY(),"Ojo EQ Vencido","")
H40: =MID(I40,12,2) | O40: =IF(I40="","",VLOOKUP(I40,AG190:AI202,2,FALSE)) | AA40: =IF(I40="","",VLOOKUP(I40,'Errores Patrones'!AB4:AG25,5,FALSE)) | AE40: =IF(AA40<TODAY(),"Ojo EQ Vencido","")
H42: Medición de las condiciones ambientales | Y42: CASO PRESENTADO PARA LA CORRECCIÓN POR EFECTO DE EMPUJE: | AE42: B. Instrumento fue ajustado independientemente de la calibración.
H43: Mediciones | L43: Temperatura [°C] | P43: Humedad relativa [% HR] | U43: Presion Atmosferica [hPa] | Y43: Limites Condiciones Ambientales
...

Sheet Certificado de calibración
H1: =Formato!S1 -> CALIBRACIÓN INSTRUMENTOS DE PESAJE DE FUNCIONAMIENTO NO AUTOMATICO, LC-FR-20 V12
W2: =Formato!S2 -> CD-372-24
A4: =Formato!A4 -> Revisado Director Técnico, 2024-12-17 - Aprobado Gerente General, 2024-12-18
A7: CERTIFICADO DE CALIBRACIÓN
A8: Certifícate of calibration
S11: CERTIFICADO No: | U11: =IF(ISBLANK(Formato!I7),"",Formato!I7) -> TM028-25A
S12: Certifícate number
A13: Magnitud: | D13: Masa
A15: Datos Del Cliente:
A16: Solicitante: | D16: =IF(ISBLANK(Formato!D12),"",CONCATENATE(Formato!D12," ",Formato!A13,": "," ",Formato!D13, ", ",Formato!M13,": ",Formato!P13)) -> TECSERVICE S.A.S. Contacto: Jhon Jairo Carabali, Telefono: 315 866 50 13
A17: Dirección:* | D17: =CONCATENATE(Formato!$P$12,","," ",Formato!$AA$12," ",Formato!AA13) -> Avenida 4 A Norte No. 45 - 56 B / La Flora, Cali Colombia
A18: Datos del Instrumento:
A19: Instrumento: | E19: =IF(ISBLANK(Formato!$D$15),"","Equipo de Pesaje") -> Equipo de Pesaje
A20: Fabricante:* | E20: =IF(ISBLANK(Formato!Q15),"",Formato!Q15) -> Mettler | N20: Identificación:* | Q20: =IF(ISBLANK(Formato!Q16),"",Formato!Q16) -> TEC-MTT-BA-03 | AA20: =PROPER(H23)
A21: Modelo:* | E21: =IF(ISBLANK(Formato!$Z$15),"",Formato!$Z$15) -> AE240 | N21: Fecha de recepción: | Q21: =IF(ISBLANK(Formato!$Y$7),"",Formato!$Y$7) -> 45678
A22: Número de serie:* | E22: =IF(ISBLANK(Formato!$E$16),"",Formato!$E$16) -> J75412 | N22: Fecha de calibración: | Q22: =IF(ISBLANK(Formato!$Y$7),"",Formato!$Y$7) -> 45678
A23: Ubicación:* | E23: =IF(ISBLANK(Formato!Z16),"",CONCATENATE(PROPER(Formato!Z16)," ",)) -> Mantenimiento
A26: Características Metrológicas del instrumento de medida
A28: Intervalo de Medición: | E28: =IF(ISBLANK(Formato!E20),"",Formato!E20) -> 0 | G28: =IF(ISBLANK(Formato!I20),"",Formato!I20) -> g | H28: Hasta | I28: =IF(ISBLANK(Formato!L20),"",Formato!L20) -> 200 | K28: =G28 -> g | N28: Intervalo de Calibración: | Q28: =IF(OR(Formato!S20>0,Formato!S20=0,),FIXED(Formato!S20,Formato!$AF$22,TRUE)) -> 0,01000 | R28: =IF(ISBLANK(Formato!V20),"OJO",Formato!V20) -> g | S28: Hasta | T28: =IF(OR(Formato!Y20>0,Formato!Y20=0,),FIXED(Formato!Y20,Formato!$AF$22,TRUE)) -> 40,00000 | U28: =R28 -> g
A29: División de escala: | E29: =IF(ISBLANK(Formato!AE21),"",IF(Formato!AE21>0,FIXED(Formato!AE21,Formato!$AF$22,TRUE))) | G29: =IF(ISBLANK(Formato!AE21),"N.A.",Formato!AF21) -> N.A. | N29: Error Máximo permitido lineal: | T29: =IF(ISBLANK(Formato!G21),"N.I.",Formato!G21) -> N.I. | U29: =IF(ISBLANK(Formato!G21),"",Formato!I20)
A30: Resolución (d): | E30: =IF(ISBLANK(Formato!AE20),"",IF(Formato!AE20>0,FIXED(Formato!AE20,Formato!$AF$22,TRUE))) -> 0,00001 | G30: =G28 -> g | N30: Error Máximo permitido Repetibilidad : | T30: =IF(ISBLANK(Formato!T21),"N.I.",Formato!T21) -> N.I. | U30: =IF(ISBLANK(Formato!T21),"",Formato!I20)
A34: Este certificado expresa fielmente el resultado de las mediciones realizadas única y exclusivamente al instrumento bajo calibración, aquí relacionado. No podrá ser reproducido parcialmente sin la debida autorización del emisor, excepto cuando se reproduce en su totalidad.
A39: Este certificado es emitido de acuerdo con los requerimientos de la norma ISO/IEC 17025:2017 (Requisitos generales para la competencia de los laboratorios de ensayo y calibración). El usuario es responsable de la calibración de sus instrumentos a intervalos apropiados.
A41: Resultado evaluación física
A42: El instrumento a calibrar fue inspeccionado detalladamente para determinar su estado y condición física determinando que puede ser calibrado.
A45: Método de calibración utilizado: Comparación directa con pesas patrón.
A47: Procedimiento de calibración
A48: El método de calibración corresponde a lo recomendado en la Guía para calibración de los instrumentos para pesar de funcionamiento no automático SIM MWG7/cg-01/v.00:2009.
A50: El proceso inicia asegurando que el instrumento de pesaje este en cero, como paso seguido se ubican las pesas sobre el receptor de carga y se registra el resultado de la medición; La calibración incluye las siguientes pruebas: Repetibilidad (5.1), Errores de indicación (5.2) y Excentricidad de carga (5.3). En el caso de instrumentos de pesaje con una división de escala ≤ 1 mg, se realiza la prueba de efecto de interacción magnética (5.4).
A51: Lugar de calibración
A52: =CONCATENATE("Instalaciones de"," ",Formato!D12," ",Formato!Z16) -> Instalaciones de TECSERVICE S.A.S. Mantenimiento
A53: Descripción de la trazabilidad Metrológica
A54: Esta calibración es trazable al Sistema Internacional de Unidades (SI), a través de una cadena ininterrumpida de comparaciones, cada eslabón de la cadena esta documentado y la incertidumbre de medición ha sido estimada en cada paso.
A56: Código | D56: Descripción | J56: Clase | M56: Calibrado por | Q56: Certificado No. | T56: Vigencia de calibración
A57: =IF(ISBLANK(Formato!I36),"",Formato!I36) -> TEC-LAB-MP-04 | D57: =IF(ISBLANK(Formato!O36),"",Formato!O36) -> KIT DE MASAS PATRON E2 | J57: =VLOOKUP(A57,'Errores Patrones'!$AB$4:$AH$25,7,0) -> E2 | M57: =+IF(ISERROR(VLOOKUP(A57,'Errores Patrones'!$AB$4:$AF$25,2,0)),"",VLOOKUP(A57,'Errores Patrones'!$AB$4:$AF$25,2,0)) -> Detecto | Q57: =+IF(ISERROR(VLOOKUP(A57,'Errores Patrones'!$AB$4:$AF$25,3,0)),"",VLOOKUP(A57,'Errores Patrones'!$AB$4:$AF$25,3,0)) -> 58446 C | T57: =IF(ISERROR(VLOOKUP(A57,'Errores Patrones'!$AB$4:$AF$25,5,0)),"",VLOOKUP(A57,'Errores Patrones'!$AB$4:$AF$25,5,0)) -> 45696
A58: =IF(ISBLANK(Formato!I37),"",Formato!I37) | D58: =IF(ISBLANK(Formato!O37),"",Formato!O37) | J58: =VLOOKUP(A58,'Errores Patrones'!$AB$4:$AH$25,7,0) -> #N/A | M58: =+IF(ISERROR(VLOOKUP(A58,'Errores Patrones'!$AB$4:$AF$25,2,0)),"",VLOOKUP(A58,'Errores Patrones'!$AB$4:$AF$25,2,0)) | Q58: =+IF(ISERROR(VLOOKUP(A58,'Errores Patrones'!$AB$4:$AF$25,3,0)),"",VLOOKUP(A58,'Errores Patrones'!$AB$4:$AF$25,3,0)) | T58: =IF(ISERROR(VLOOKUP(A58,'Errores Patrones'!$AB$4:$AF$25,5,0)),"",VLOOKUP(A58,'Errores Patrones'!$AB$4:$AF$25,5,0))
A59: =IF(ISBLANK(Formato!I38),"",Formato!I38) | D59: =IF(ISBLANK(Formato!O38),"",Formato!O38) | J59: =VLOOKUP(A59,'Errores Patrones'!$AB$4:$AH$25,7,0) -> #N/A | M59: =+IF(ISERROR(VLOOKUP(A59,'Errores Patrones'!$AB$4:$AF$25,2,0)),"",VLOOKUP(A59,'Errores Patrones'!$AB$4:$AF$25,2,0)) | Q59: =+IF(ISERROR(VLOOKUP(A59,'Errores Patrones'!$AB$4:$AF$25,3,0)),"",VLOOKUP(A59,'Errores Patrones'!$AB$4:$AF$25,3,0)) | T59: =IF(ISERROR(VLOOKUP(A59,'Errores Patrones'!$AB$4:$AF$25,5,0)),"",VLOOKUP(A59,'Errores Patrones'!$AB$4:$AF$25,5,0)) | AE59: =IF(AND(Formato!L49>Formato!Y45,Formato!P49>Formato!AA45,Formato!U49>Formato!AC45,Formato!F148=1,Formato!R148=1),"No Se Puede Emitir Certificado. ¡ SE DEBE REVISAR LOS DATOS ! ","")
A60: =IF(ISBLANK(Formato!I39),"",Formato!I39) | D60: =IF(ISBLANK(Formato!O39),"",Formato!O39) | J60: =VLOOKUP(A60,'Errores Patrones'!$AB$4:$AH$25,7,0) -> #N/A | M60: =+IF(ISERROR(VLOOKUP(A60,'Errores Patrones'!$AB$4:$AF$25,2,0)),"",VLOOKUP(A60,'Errores Patrones'!$AB$4:$AF$25,2,0)) | Q60: =+IF(ISERROR(VLOOKUP(A60,'Errores Patrones'!$AB$4:$AF$25,3,0)),"",VLOOKUP(A60,'Errores Patrones'!$AB$4:$AF$25,3,0)) | T60: =IF(ISERROR(VLOOKUP(A60,'Errores Patrones'!$AB$4:$AF$25,5,0)),"",VLOOKUP(A60,'Errores Patrones'!$AB$4:$AF$25,5,0)) | AE60: =IF(AND(Formato!F148=1,Formato!R148=1),"No Se Puede Emitir Certificado. ¡ SE DEBE REVISAR LOS DATOS ! ","")
A61: =IF(ISBLANK(Formato!I40),"",Formato!I40) | D61: =IF(ISBLANK(Formato!O40),"",Formato!O40) | J61: =VLOOKUP(A61,'Errores Patrones'!$AB$4:$AH$25,7,0) -> #N/A | M61: =+IF(ISERROR(VLOOKUP(A61,'Errores Patrones'!$AB$4:$AF$25,2,0)),"",VLOOKUP(A61,'Errores Patrones'!$AB$4:$AF$25,2,0)) | Q61: =+IF(ISERROR(VLOOKUP(A61,'Errores Patrones'!$AB$4:$AF$25,3,0)),"",VLOOKUP(A61,'Errores Patrones'!$AB$4:$AF$25,3,0)) | T61: =IF(ISERROR(VLOOKUP(A61,'Errores Patrones'!$AB$4:$AF$25,5,0)),"",VLOOKUP(A61,'Errores Patrones'!$AB$4:$AF$25,5,0))
A63: FIRMAS AUTORIZADAS | J63: =IF(OR(Formato!AE36="Ojo EQ Vencido",Formato!AE37="Ojo EQ Vencido",Formato!AE38="Ojo EQ Vencido",Formato!AE39="Ojo EQ Vencido",Formato!AE40="Ojo EQ Vencido"),"No Se Puede Emitir Certificado. ¡ SE VERIFIQUE VIGENCIA DEL EQUIPO PATRON !","")
...

Sheet Estimación de la Incertidumbre
A1: Plantilla Incertidumbre
A2: CODIGO: | F2: LC-FR-08 | H2: VERSION: | J2: 03 | BS2: =((0.34848*AVERAGE(Formato!U44:U45)+-0.009*AVERAGE(Formato!P44:P45)*EXP(0.061*AVERAGE(Formato!L44:L45)))/(273.15+AVERAGE(Formato!L44:L45)))/1000 -> 0.0010498157 | BZ2: ρkg/m3 | CA2: uρ g/cm3 | CB2: ρ kg/m3 | CC2: uρ g/cm3
A3: Revisó: | F3: ='Certificado de calibración'!D3 -> 0 | H3: Aprobó: | J3: Gerente General | BQ3: ρa | BR3: ƍacal= ( Densidad Aire en Sitio) | BS3: =((0.34848*AVERAGE(Formato!U45)+-0.009*AVERAGE(Formato!P45)*EXP(0.061*AVERAGE(Formato!L45)))/(273.15+AVERAGE(Formato!L45)))/1000 -> 0.0010488867 | BT3: g/cm3 | BU3: Uex | BV3: 2.4e-07 | BW3: =+BT3 -> g/cm3 | BX3: Plata | BZ3: 8600 | CA3: =BZ3/1000 -> 8.6 | CB3: 85 | CC3: =CB3/1000 -> 0.085
A4: Fecha: | F4: 45481 | H4: Fecha: | J4: 45502 | BQ4: ρ0 | BR4: ƍo= ( Densidad Aire Condiciones Ideales) | BS4: =1.2/1000 -> 0.0012 | BT4: =+BT3 -> g/cm3 | BU4: Uex | BV4: =+BV3 -> 2.4e-07 | BW4: =+BT4 -> g/cm3 | BX4: Laton | BZ4: 8400 | CA4: =BZ4/1000 -> 8.4 | CB4: 85 | CC4: =CB4/1000 -> 0.085
BQ5: ρ | BR5: ƍcal= ( Densidad Pesas Utilizadas) | BS5: =+VLOOKUP(Formato!I36,'Errores Patrones'!AB4:AG25,6,0) -> 7.95 | BT5: =+BT4 -> g/cm3 | BU5: Uex | BV5: =VLOOKUP(BS5,CA3:CC8,3,FALSE) -> 0.07 | BW5: =+BW4 -> g/cm3 | BX5: SS | BZ5: 7950 | CA5: =BZ5/1000 -> 7.95 | CB5: 70 | CC5: =CB5/1000 -> 0.07
A6: =CONCATENATE("PRESUPUESTO PARA ",'Certificado de calibración'!A1," ",'Certificado de calibración'!D2," v",'Certificado de calibración'!K2) -> PRESUPUESTO PARA v | AO6: 1 | AP6: 2 | AQ6: 3 | AR6: 4 | AS6: 5 | AT6: 6 | AU6: 7 | AV6: 8 | AW6: 9 | AX6: 10 | AY6: 11 | AZ6: 12 | BC6: 1 | BD6: 2 | BE6: 3 | BF6: 4 | BG6: 5 | BH6: 6 | BI6: 7 | BJ6: 8 | BK6: 9 | BL6: 10 | BM6: 11 | BN6: 12 | BQ6: ρc | BR6: ƍC= ( Densidad Estandar Pesas ) | BS6: 8 | BT6: =+BT5 -> g/cm3 | BU6: Uex | BV6: =70/1000 -> 0.07 | BW6: =+BW5 -> g/cm3 | BX6: Hierro F Blanco | BZ6: 7700 | CA6: =BZ6/1000 -> 7.7 | CB6: 200 | CC6: =CB6/1000 -> 0.2
BX7: Hierro F Gris | BZ7: 7100 | CA7: =BZ7/1000 -> 7.1 | CB7: 300 | CC7: =CB7/1000 -> 0.3
AO8: Carga | BX8: Aluminio | BZ8: 2700 | CA8: =BZ8/1000 -> 2.7 | CB8: 65 | CC8: =CB8/1000 -> 0.065
A9: Fuentes de incertidumbre | H9: =CONCATENATE("Cargas aplicadas"," ","(",Formato!$I$20,")") -> Cargas aplicadas (g) | AO9: =H10 -> 0.01 | AP9: =I10 -> 4 | AQ9: =J10 -> 8 | AR9: =K10 -> 12 | AS9: =L10 -> 15 | AT9: =M10 -> 20 | AU9: =N10 -> 25 | AV9: =O10 -> 27 | ... AY9: =R10 -> 40 | AZ9: 0 | BA9: =Formato!I20 -> g
H10: =IF(ISBLANK(Formato!T87),"",Formato!T87) -> 0.01 | I10: =IF(ISBLANK(Formato!T92),"",Formato!T92) -> 4 | J10: =IF(ISBLANK(Formato!T97),"",Formato!T97) -> 8 | K10: =IF(ISBLANK(Formato!T102),"",Formato!T102) -> 12 | L10: =IF(ISBLANK(Formato!T107),"",Formato!T107) -> 15 | M10: =IF(ISBLANK(Formato!T112),"",Formato!T112) -> 20 | N10: =IF(ISBLANK(Formato!T117),"",Formato!T117) -> 25 | O10: =IF(ISBLANK(Formato!T122),"",Formato!T122) -> 27 | P10: =IF(ISBLANK(Formato!T127),"",Formato!T127) -> 30 | Q10: =IF(ISBLANK(Formato!T133),"",Formato!T133) -> 35 | R10: =IF(ISBLANK(Formato!T139),"",Formato!T139) -> 40 | S10: =IF(ISBLANK(Formato!T82),"",Formato!T82) -> 0 | AO10: =IF(Formato!$I$20="g",AO9,IF(Formato!$I$20="mg",AO9/1000,IF(Formato!$I$20="kg",AO9*1000,))) -> 0.01 | AP10: =IF(Formato!$I$20="g",AP9,IF(Formato!$I$20="mg",AP9/1000,IF(Formato!$I$20="kg",AP9*1000,))) -> 4 | AQ10: =IF(Formato!$I$20="g",AQ9,IF(Formato!$I$20="mg",AQ9/1000,IF(Formato!$I$20="kg",AQ9*1000,))) -> 8 | AR10: =IF(Formato!$I$20="g",AR9,IF(Formato!$I$20="mg",AR9/1000,IF(Formato!$I$20="kg",AR9*1000,))) -> 12 | AS10: =IF(Formato!$I$20="g",AS9,IF(Formato!$I$20="mg",AS9/1000,IF(Formato!$I$20="kg",AS9*1000,))) -> 15 | AT10: =IF(Formato!$I$20="g",AT9,IF(Formato!$I$20="mg",AT9/1000,IF(Formato!$I$20="kg",AT9*1000,))) -> 20 | AU10: =IF(Formato!$I$20="g",AU9,IF(Formato!$I$20="mg",AU9/1000,IF(Formato!$I$20="kg",AU9*1000,))) -> 25 | AV10: =IF(Formato!$I$20="g",AV9,IF(Formato!$I$20="mg",AV9/1000,IF(Formato!$I$20="kg",AV9*1000,))) -> 27 | ... AZ10: =IF(Formato!$I$20="g",AZ9,IF(Formato!$I$20="mg",AZ9/1000,IF(Formato!$I$20="kg",AZ9*1000,))) -> 0 | BA10: g | BY10: 7.95 | BZ10: =VLOOKUP(BY10,CA3:CC8,3,FALSE) -> 0.07
A11: Error de redondeo de la indicación sin carga y con carga | G11: U Exp | H11: =IF(ISBLANK(Formato!AE20),"",Formato!$AE$20) -> 1e-05 | I11: =+H11 -> 1e-05 | J11: =+I11 -> 1e-05 | K11: =+J11 -> 1e-05 | L11: =+K11 -> 1e-05 | M11: =+L11 -> 1e-05 | N11: =+M11 -> 1e-05 | O11: =+N11 -> 1e-05 | P11: =+O11 -> 1e-05 | ... R11: =+Q11 -> 1e-05 | S11: =R11 -> 1e-05 | AI11: (7.1.1) | AJ11: Incertidumbre estándar de la indicación | AM11: Aportante | AN11: Distribucion
G12: K | H12: =IF(Formato!$E$17=Formato!$AZ$6,SQRT(12),SQRT(24)) -> 3.4641016 | I12: =IF(Formato!$E$17=Formato!$AZ$6,SQRT(12),SQRT(24)) -> 3.4641016 | J12: =IF(Formato!$E$17=Formato!$AZ$6,SQRT(12),SQRT(24)) -> 3.4641016 | K12: =IF(Formato!$E$17=Formato!$AZ$6,SQRT(12),SQRT(24)) -> 3.4641016 | L12: =IF(Formato!$E$17=Formato!$AZ$6,SQRT(12),SQRT(24)) -> 3.4641016 | M12: =IF(Formato!$E$17=Formato!$AZ$6,SQRT(12),SQRT(24)) -> 3.4641016 | N12: =IF(Formato!$E$17=Formato!$AZ$6,SQRT(12),SQRT(24)) -> 3.4641016 | O12: =IF(Formato!$E$17=Formato!$AZ$6,SQRT(12),SQRT(24)) -> 3.4641016 | ... S12: =IF(Formato!$E$17=Formato!$AZ$6,SQRT(12),SQRT(24)) -> 3.4641016 | AM12: Resolucion | AO12: =H11 -> 1e-05 | AP12: =I11 -> 1e-05 | AQ12: =J11 -> 1e-05 | AR12: =K11 -> 1e-05 | AS12: =L11 -> 1e-05 | AT12: =M11 -> 1e-05 | AU12: =N11 -> 1e-05 | AV12: =O11 -> 1e-05 | ... AZ12: =S11 -> 1e-05
G13: U estandar | H13: =H11/H12 -> 2.8867513e-06 | I13: =I11/I12 -> 2.8867513e-06 | J13: =J11/J12 -> 2.8867513e-06 | K13: =K11/K12 -> 2.8867513e-06 | L13: =L11/L12 -> 2.8867513e-06 | M13: =M11/M12 -> 2.8867513e-06 | N13: =N11/N12 -> 2.8867513e-06 | O13: =O11/O12 -> 2.8867513e-06 | ... S13: =S11/S12 -> 2.8867513e-06 | T13: =POWER(H13,4)/100 -> 6.9444444e-25 | U13: =POWER(I13,4)/100 -> 6.9444444e-25 | V13: =POWER(J13,4)/100 -> 6.9444444e-25 | W13: =POWER(K13,4)/100 -> 6.9444444e-25 | X13: =POWER(L13,4)/100 -> 6.9444444e-25 | Y13: =POWER(M13,4)/100 -> 6.9444444e-25 | Z13: =POWER(N13,4)/100 -> 6.9444444e-25 | AA13: =POWER(O13,4)/100 -> 6.9444444e-25 | ... AD13: =POWER(R13,4)/100 -> 6.9444444e-25 | AI13: (7.1-2a) | AK13: Redondeo ind con carga | AN13: Retangular | AO13: =AO12/SQRT(12) -> 2.8867513e-06
A14: Error de redondeo de la indicación sin carga y con carga | G14: U Exp | H14: =+H11 -> 1e-05 | I14: =+I11 -> 1e-05 | J14: =+J11 -> 1e-05 | K14: =+K11 -> 1e-05 | L14: =+L11 -> 1e-05 | M14: =+M11 -> 1e-05 | N14: =+N11 -> 1e-05 | O14: =+O11 -> 1e-05 | ... S14: =+S11 -> 1e-05 | AI14: (7.1-2a) | AK14: Redondeo ind sin carga | AN14: Retangular | AO14: =AO12/SQRT(12) -> 2.8867513e-06
G15: K | H15: =+H12 -> 3.4641016 | I15: =+I12 -> 3.4641016 | J15: =+J12 -> 3.4641016 | K15: =+K12 -> 3.4641016 | L15: =+L12 -> 3.4641016 | M15: =+M12 -> 3.4641016 | N15: =+N12 -> 3.4641016 | O15: =+O12 -> 3.4641016 | ... S15: =+S12 -> 3.4641016 | AK15: imperfecta repetibilidad | AM15: desvestd | AO15: =H17 -> 8.3666003e-06
G16: U estandar | H16: =+H13 -> 2.8867513e-06 | I16: =+I13 -> 2.8867513e-06 | J16: =+J13 -> 2.8867513e-06 | K16: =+K13 -> 2.8867513e-06 | L16: =+L13 -> 2.8867513e-06 | M16: =+M13 -> 2.8867513e-06 | N16: =+N13 -> 2.8867513e-06 | O16: =+O13 -> 2.8867513e-06 | ... S16: =+S13 -> 2.8867513e-06 | T16: =POWER(H16,4)/100 -> 6.9444444e-25 | U16: =POWER(I16,4)/100 -> 6.9444444e-25 | V16: =POWER(J16,4)/100 -> 6.9444444e-25 | W16: =POWER(K16,4)/100 -> 6.9444444e-25 | X16: =POWER(L16,4)/100 -> 6.9444444e-25 | Y16: =POWER(M16,4)/100 -> 6.9444444e-25 | Z16: =POWER(N16,4)/100 -> 6.9444444e-25 | AA16: =POWER(O16,4)/100 -> 6.9444444e-25 | ... AD16: =POWER(R16,4)/100 -> 6.9444444e-25 | AI16: (7.1.1-5) | AN16: Normal | AO16: =AO15 -> 8.3666003e-06
A17: Error debido a la imperfecta repetibilidad. | H17: =Formato!$H$95 -> 8.3666003e-06 | I17: =Formato!$H$95 -> 8.3666003e-06 | J17: =Formato!$H$95 -> 8.3666003e-06 | K17: =Formato!$H$95 -> 8.3666003e-06 | L17: =Formato!$H$95 -> 8.3666003e-06 | M17: =Formato!$H$95 -> 8.3666003e-06 | N17: =Formato!$H$95 -> 8.3666003e-06 | O17: =Formato!$H$95 -> 8.3666003e-06 | ... S17: =Formato!$H$95 -> 8.3666003e-06 | AK17: colocación del centro de gravedad de la carga | AM17: ∆i | AO17: =H20 -> 2e-07 | BR17: CASOS A PRESENTARSE GENERALES:
H18: =SQRT(COUNT(Formato!B84:E93)) -> 2.236068 | I18: =SQRT(COUNT(Formato!B84:E93)) -> 2.236068 | J18: =SQRT(COUNT(Formato!B84:E93)) -> 2.236068 | K18: =SQRT(COUNT(Formato!B84:E93)) -> 2.236068 | L18: =SQRT(COUNT(Formato!B84:E93)) -> 2.236068 | M18: =SQRT(COUNT(Formato!B84:E93)) -> 2.236068 | N18: =SQRT(COUNT(Formato!B84:E93)) -> 2.236068 | O18: =SQRT(COUNT(Formato!B84:E93)) -> 2.236068 | P18: =SQRT(COUNT(Formato!B84:E93)) -> 2.236068 | Q18: =SQRT(COUNT(Formato!B84:E93)) -> 2.236068 | R18: =SQRT(COUNT(Formato!B84:E93)) -> 2.236068 | S18: =SQRT(COUNT(Formato!M84:P93)) -> 0 | AM18: Lecc | AO18: =Formato!$K$65 -> 20 | BR18: A. Instrumento fue ajustado inmediatamente antes de la calibración.
G19: U estandar | H19: =H17 -> 8.3666003e-06 | I19: =I17 -> 8.3666003e-06 | J19: =J17 -> 8.3666003e-06 | K19: =K17 -> 8.3666003e-06 | L19: =L17 -> 8.3666003e-06 | M19: =M17 -> 8.3666003e-06 | N19: =N17 -> 8.3666003e-06 | O19: =O17 -> 8.3666003e-06 | ... S19: =S17 -> 8.3666003e-06 | T19: =POWER(H19,4)/4 -> 1.225e-21 | U19: =POWER(I19,4)/4 -> 1.225e-21 | V19: =POWER(J19,4)/4 -> 1.225e-21 | W19: =POWER(K19,4)/4 -> 1.225e-21 | X19: =POWER(L19,4)/4 -> 1.225e-21 | Y19: =POWER(M19,4)/4 -> 1.225e-21 | Z19: =POWER(N19,4)/4 -> 1.225e-21 | AA19: =POWER(O19,4)/4 -> 1.225e-21 | ... AD19: =POWER(R19,4)/4 -> 1.225e-21 | AI19: (7.1.1-10) | AN19: Retangular | AO19: =AO17/(2*AO18)/SQRT(3) -> 2.8867513e-09
A20: Error debido a la colocación del centro de gravedad de la carga de prueba fuera de la posición central del receptor de carga del instrumento. | G20: U Exp | H20: =+IF(H10="","",H10*Formato!$H$75) -> 2e-07 | I20: =+IF(I10="","",I10*Formato!$H$75) -> 8e-05 | J20: =+IF(J10="","",J10*Formato!$H$75) -> 0.00016 | K20: =+IF(K10="","",K10*Formato!$H$75) -> 0.00024 | L20: =+IF(L10="","",L10*Formato!$H$75) -> 0.0003 | M20: =+IF(M10="","",M10*Formato!$H$75) -> 0.0004 | N20: =+IF(N10="","",N10*Formato!$H$75) -> 0.0005 | O20: =+IF(O10="","",O10*Formato!$H$75) -> 0.00054 | ... S20: =+IF(S10="","",S10*Formato!$H$75) -> 0 | AI20: 7.1.2 | AJ20: Incertidumbre estándar de la masa de referencia | AK20: Masa de referencia | AM20: U masa | AO20: =H23 -> 2.7e-06
G21: K | H21: =(2*Formato!$K$65*SQRT(3)) -> 69.282032 | I21: =(2*Formato!$K$65*SQRT(3)) -> 69.282032 | J21: =(2*Formato!$K$65*SQRT(3)) -> 69.282032 | K21: =(2*Formato!$K$65*SQRT(3)) -> 69.282032 | L21: =(2*Formato!$K$65*SQRT(3)) -> 69.282032 | M21: =(2*Formato!$K$65*SQRT(3)) -> 69.282032 | N21: =(2*Formato!$K$65*SQRT(3)) -> 69.282032 | O21: =(2*Formato!$K$65*SQRT(3)) -> 69.282032 | ... S21: =(2*Formato!$K$65*SQRT(3)) -> 69.282032 | AI21: (7.1.2-2) | AN21: Normal | AO21: =AO20/2 -> 1.35e-06 | BR21: B. Instrumento fue ajustado independientemente de la calibración.
G22: U estandar | H22: =H20/H21 -> 2.8867513e-09 | I22: =I20/I21 -> 1.1547005e-06 | J22: =J20/J21 -> 2.3094011e-06 | K22: =K20/K21 -> 3.4641016e-06 | L22: =L20/L21 -> 4.330127e-06 | M22: =M20/M21 -> 5.7735027e-06 | N22: =N20/N21 -> 7.2168784e-06 | O22: =O20/O21 -> 7.7942286e-06 | ... S22: =S20/S21 -> 0 | T22: =POWER(H22,4)/100 -> 6.9444444e-37 | U22: =POWER(I22,4)/100 -> 1.7777778e-26 | V22: =POWER(J22,4)/100 -> 2.8444444e-25 | W22: =POWER(K22,4)/100 -> 1.44e-24 | X22: =POWER(L22,4)/100 -> 3.515625e-24 | Y22: =POWER(M22,4)/100 -> 1.1111111e-23 | Z22: =POWER(N22,4)/100 -> 2.7126736e-23 | AA22: =POWER(O22,4)/100 -> 3.6905625e-23 | ... AD22: =POWER(R22,4)/100 -> 1.7777778e-22 | AK22: Deriva. | AM22: U masa | AO22: =H26 -> 2.7e-06
A23: Incertidumbre por pesas patrón. | F23: mc | G23: U Exp | H23: =+IF(Calculos!I23="","",Calculos!I23) -> 2.7e-06 | I23: =+IF(Calculos!I28="","",Calculos!I28) -> 2.6e-05 | J23: =+IF(Calculos!I33="","",Calculos!I33) -> 4e-05 | K23: =+IF(Calculos!I38="","",Calculos!I38) -> 3.3e-05 | L23: =+IF(Calculos!I43="","",Calculos!I43) -> 3.7e-05 | M23: =+IF(Calculos!I48="","",Calculos!I48) -> 2.7e-05 | N23: =+IF(Calculos!I53="","",Calculos!I53) -> 4.4e-05 | O23: =+IF(Calculos!I58="","",Calculos!I58) -> 5.7e-05 | P23: =+IF(Calculos!I63="","",Calculos!I63) -> 4.7e-05 | Q23: =+IF(Calculos!I69="","",Calculos!I69) -> 6.4e-05 | R23: =+IF(Calculos!I75="","",Calculos!I75) -> 5.4e-05 | S23: 0 | AI23: (7.1.2-10) | AN23: Retangular | AO23: =AO22/SQRT(3) -> 1.5588457e-06
G24: K | H24: =+IF(Calculos!J23="","",Calculos!J23) -> 2 | I24: =+IF(Calculos!J28="","",Calculos!J28) -> 2 | J24: =+IF(Calculos!J33="","",Calculos!J33) -> 2 | K24: =+IF(Calculos!J38="","",Calculos!J38) -> 2 | L24: =+IF(Calculos!J43="","",Calculos!J43) -> 2 | M24: =+IF(Calculos!J48="","",Calculos!J48) -> 2 | N24: =+IF(Calculos!J53="","",Calculos!J53) -> 2 | O24: =+IF(Calculos!J58="","",Calculos!J58) -> 2 | P24: =+IF(Calculos!J63="","",Calculos!J63) -> 2 | Q24: =+IF(Calculos!J69="","",Calculos!J69) -> 2 | R24: =+IF(Calculos!J75="","",Calculos!J75) -> 2 | S24: 2 | AK24: Reproducibilidad | AM24: SR | AO24: =H29 -> 0 | BR24: MASA NOMINAL | BS24: =CONCATENATE("Cargas aplicadas"," ","(",Formato!$I$20,")") -> Cargas aplicadas (g)
G25: U estandar | H25: =IF(H23="N.A", "N.A",H23/H24) -> 1.35e-06 | I25: =IF(I23="N.A", "N.A",I23/I24) -> 1.3e-05 | J25: =IF(J23="N.A", "N.A",J23/J24) -> 2e-05 | K25: =IF(K23="N.A", "N.A",K23/K24) -> 1.65e-05 | L25: =IF(L23="N.A", "N.A",L23/L24) -> 1.85e-05 | M25: =IF(M23="N.A", "N.A",M23/M24) -> 1.35e-05 | N25: =IF(N23="N.A", "N.A",N23/N24) -> 2.2e-05 | O25: =IF(O23="N.A", "N.A",O23/O24) -> 2.85e-05 | ... S25: =IF(S23="N.A", "N.A",S23/S24) -> 0 | T25: =POWER(H25,4)/100 -> 3.3215062e-26 | U25: =POWER(I25,4)/100 -> 2.8561e-22 | V25: =POWER(J25,4)/100 -> 1.6e-21 | W25: =POWER(K25,4)/100 -> 7.4120063e-22 | X25: =POWER(L25,4)/100 -> 1.1713506e-21 | Y25: =POWER(M25,4)/100 -> 3.3215062e-22 | Z25: =POWER(N25,4)/100 -> 2.34256e-21 | AA25: =POWER(O25,4)/100 -> 6.5975006e-21 | ... AD25: =POWER(R25,4)/100 -> 5.31441e-21 | AN25: Normal | AO25: =AO24/1 -> 0 | BS25: ='Estimación de la Incertidumbre'!BX8 -> Aluminio | BT25: ='Estimación de la Incertidumbre'!BY8 -> 0 | BU25: ='Estimación de la Incertidumbre'!BZ8 -> 2700 | BV25: ='Estimación de la Incertidumbre'!CA8 -> 2.7 | BW25: ='Estimación de la Incertidumbre'!CB8 -> 65 | BX25: ='Estimación de la Incertidumbre'!CC8 -> 0.065 | BY25: ='Estimación de la Incertidumbre'!CD8 -> 0 | BZ25: ='Estimación de la Incertidumbre'!CE8 -> 0 | ... CC25: ='Estimación de la Incertidumbre'!CH8 -> 0
