Workbook

Sheet Hoja1 (copia original)
F1: INVENTARIO INSTRUMENTOS DE MEDICIÓN, LC-FR-10 V5
F2: CD389-25
A4: Revisado Director Técnico, 2025-01-23 - Aprobado Gerente General, 2025-01-25
A5: 1+ 4 | B5: 1 | C5: 2 | D5: 3 | E5: 4 | F5: 1 | G5: 2 | H5: 3 | I5: 4 | J5: 5 | K5: 6 | L5: 7 | M5: 8 | N5: 9 | O5: 10 | P5: 11 | Q5: 12 | R5: 13 | S5: 14 | T5: 15 | U5: 16 | V5: 17 | W5: 18 | X5: 19 | Y5: 20 | Z5: 21 | AA5: 22 | AB5: 23 | AC5: 24 | AD5: 25 | AE5: 26 | AF5: 27 | AG5: 28 | AH5: 29
F6: Código | G6: Instrumento / patrón /material de referencia | H6: Ubicación | I6: Fabricante | J6: Modelo | K6: Serie/Lote/ Distintivo | L6: Intervalo de medición / Valor nominal | M6: División de escala | N6: Error maximo permitido | O6: Accuracy | P6: INCERTIDUMBRE (mg) | Q6: Estabilidad | R6: NUMERO DE MASAS / # SENSORES | S6: Uniformidad | T6: Escalón de verificación/Puntos a Calibrar/Intervalo de Calibracion | U6: Clase | V6: Frecuencia de calibración (meses) | W6: Frecuencia de Mtto (meses) | X6: Frecuencia de Verificacion (meses) | Y6: Tipo de calibración | Z6: Estado | AA6: Número del último certificado de calibración | AB6: Calibrado por | AC6: Fecha de la último mantenimiento/ Inicio uso para MRC | AD6: Fecha de la proximo mantenimiento / Inicio uso para MRC | AE6: Fecha de la última calibración | AF6: Fecha próxima calibración /Vencimiento | AG6: Observaciones | AH6: Dias Vigencia | AJ6: Observaciones 2 | AK6: Observaciones 3 | AL6: Frecuencia Inicial | AM6: Frcuencia actual Calculada | AN6: Fcal | AO6: F_Inicio | AP6: Frec Vintermedia en Meses | AQ6: Verif 1 | AR6: Verif 2 | AS6: Verif 3 | AT6: Verif 4 | AU6: Verif 5 | AW6: Frec Vintermedia en Meses | AX6: Verif 1 | AY6: Verif 2 | AZ6: Verif 3 | BA6: Verif 4 | BB6: Verif 5
A7: =IF(D7="Masa",CONCATENATE(F7,"_",L7,"_",K7),F7) -> TEC-LAB-MP-01a_5kg, 10kg,20Kg (615 kg)_01 Hasta 32 | B7: =AA7 -> 61804 C | C7: Acreditado | D7: Masa | E7: Patron | F7: TEC-LAB-MP-01a | G7: Juego de Pesas | H7: Extension Laboratorio calibracion | I7: Lexus. | J7: Paralelépipedo | K7: 01 Hasta 32 | L7: 5kg, 10kg,20Kg (615 kg) | M7: N.A | N7: Según NTC 1848 | O7: N.A | P7: 8 mg a 36 mg | R7: 32 | T7: N.A | U7: OIML M1 | V7: 12 | W7: 12 | X7: 4 | Y7: Externa | Z7: En Servicio | AA7: 61804 C | AB7: Detecto de Colombia S.A. | AC7: 45254 | AE7: 45671 | AF7: =EDATE(AE7,(V7)) -> 46036 | AH7: =DAYS360(TODAY(),AF7) -> -103 | AI7: =IF(Z7="Fuera de servicio","Fuera de servicio",IF(TODAY()-AF7>0,"OJO EQUIPO VENCIDO",DAYS360(TODAY(),AF7)&" DIAS RESTANTES")) -> OJO EQUIPO VENCIDO | AJ7: Solicitud compra Calibracion 2024-11-14 | AK7: Cambiar color a Negro, autorizado por Don Hector | AL7: =VLOOKUP(A7,#REF!,21,FALSE) -> #REF! | AM7: =VLOOKUP(A7,#REF!,23,FALSE) -> #REF! | AN7: =AE7 -> 45671 | AO7: 45671 | AP7: =X7 -> 4 | AQ7: =EDATE(AE7,0) -> 45671 | AR7: =IF(COUNT(AQ7)<AP7,EDATE(AE7,X7),"N/A") -> 45791 | AS7: =IF(COUNT(AQ7:AR7)<AP7,EDATE(AR7,X7),"N/A") -> 45914 | AT7: =IF(COUNT(AQ7:AS7)<AP7,EDATE(AS7,X7),"N/A") -> 46036 | AU7: =IF(COUNT(AQ7:AT7)<AP7,EDATE(AT7,X7),"N/A") -> N/A | AW7: =X7 -> 4 | AX7: =EDATE(AO7,0) -> 45671 | AY7: =IF(COUNT(AX7)<AW7,EDATE(AO7,X7),"N/A") -> 45791 | AZ7: =IF(COUNT(AX7:AY7)<AW7,EDATE(AY7,X7),"N/A") -> 45914 | BA7: =IF(COUNT(AX7:AZ7)<AW7,EDATE(AZ7,X7),"N/A") -> 46036 | BB7: =IF(COUNT(AX7:BA7)<AW7,EDATE(BA7,X7),"N/A") -> N/A
A8: =IF(D8="Masa",CONCATENATE(F8,"_",L8,"_",K8),F8) -> TEC-LAB-MP-01_5Kg_01 | B8: =AA8 -> 61804 C | C8: Acreditado | D8: Masa | E8: Patron | F8: TEC-LAB-MP-01 | G8: Pesa | H8: Extension Laboratorio calibracion | I8: Lexus. | J8: Paralelépipedo | K8: 01 | L8: 5Kg | M8: N.A | N8: Según NTC 1848 | O8: N.A | P8: 8 mg | R8: 1 | T8: N.A | U8: OIML M1 | V8: 12 | W8: 12 | X8: 4 | Y8: Externa | Z8: En Servicio | AA8: 61804 C | AB8: Detecto de Colombia S.A. | AC8: 45254 | AE8: 45671 | AF8: =EDATE(AE8,(V8)) -> 46036 | AH8: =DAYS360(TODAY(),AF8) -> -103 | AI8: =IF(Z8="Fuera de servicio","Fuera de servicio",IF(TODAY()-AF8>0,"OJO EQUIPO VENCIDO",DAYS360(TODAY(),AF8)&" DIAS RESTANTES")) -> OJO EQUIPO VENCIDO | AJ8: Solicitud compra Calibracion 2024-11-14 | AK8: =AK7 -> Cambiar color a Negro, autorizado por Don Hector | AL8: =VLOOKUP(A8,#REF!,21,FALSE) -> #REF! | AM8: =VLOOKUP(A8,#REF!,23,FALSE) -> #REF! | AN8: =AE8 -> 45671 | AO8: 45671 | AP8: =X8 -> 4 | AQ8: =EDATE(AE8,0) -> 45671 | AR8: =IF(COUNT(AQ8)<AP8,EDATE(AE8,X8),"N/A") -> 45791 | AS8: =IF(COUNT(AQ8:AR8)<AP8,EDATE(AR8,X8),"N/A") -> 45914 | AT8: =IF(COUNT(AQ8:AS8)<AP8,EDATE(AS8,X8),"N/A") -> 46036 | AU8: =IF(COUNT(AQ8:AT8)<AP8,EDATE(AT8,X8),"N/A") -> N/A | AW8: =X8 -> 4 | AX8: =EDATE(AO8,0) -> 45671 | AY8: =IF(COUNT(AX8)<AW8,EDATE(AO8,X8),"N/A") -> 45791 | AZ8: =IF(COUNT(AX8:AY8)<AW8,EDATE(AY8,X8),"N/A") -> 45914 | BA8: =IF(COUNT(AX8:AZ8)<AW8,EDATE(AZ8,X8),"N/A") -> 46036 | BB8: =IF(COUNT(AX8:BA8)<AW8,EDATE(BA8,X8),"N/A") -> N/A
A9: =IF(D9="Masa",CONCATENATE(F9,"_",L9,"_",K9),F9) -> TEC-LAB-MP-01_10Kg_02 | B9: =AA9 -> 61804 C | C9: Acreditado | D9: Masa | E9: Patron | F9: TEC-LAB-MP-01 | G9: Pesa | H9: Extension Laboratorio calibracion | I9: Lexus. | J9: Paralelépipedo | K9: 02 | L9: 10Kg | M9: N.A | N9: Según NTC 1848 | O9: N.A | P9: 16 mg | R9: 1 | T9: N.A | U9: OIML M1 | V9: 12 | W9: 12 | X9: 4 | Y9: Externa | Z9: En Servicio | AA9: 61804 C | AB9: Detecto de Colombia S.A. | AC9: 45254 | AE9: 45671 | AF9: =EDATE(AE9,(V9)) -> 46036 | AH9: =DAYS360(TODAY(),AF9) -> -103 | AI9: =IF(Z9="Fuera de servicio","Fuera de servicio",IF(TODAY()-AF9>0,"OJO EQUIPO VENCIDO",DAYS360(TODAY(),AF9)&" DIAS RESTANTES")) -> OJO EQUIPO VENCIDO | AJ9: Solicitud compra Calibracion 2024-11-14 | AK9: =AK8 -> Cambiar color a Negro, autorizado por Don Hector | AL9: =VLOOKUP(A9,#REF!,21,FALSE) -> #REF! | AM9: =VLOOKUP(A9,#REF!,23,FALSE) -> #REF! | AN9: =AE9 -> 45671 | AO9: 45671 | AP9: =X9 -> 4 | AQ9: =EDATE(AE9,0) -> 45671 | AR9: =IF(COUNT(AQ9)<AP9,EDATE(AE9,X9),"N/A") -> 45791 | AS9: =IF(COUNT(AQ9:AR9)<AP9,EDATE(AR9,X9),"N/A") -> 45914 | AT9: =IF(COUNT(AQ9:AS9)<AP9,EDATE(AS9,X9),"N/A") -> 46036 | AU9: =IF(COUNT(AQ9:AT9)<AP9,EDATE(AT9,X9),"N/A") -> N/A | AW9: =X9 -> 4 | AX9: =EDATE(AO9,0) -> 45671 | AY9: =IF(COUNT(AX9)<AW9,EDATE(AO9,X9),"N/A") -> 45791 | AZ9: =IF(COUNT(AX9:AY9)<AW9,EDATE(AY9,X9),"N/A") -> 45914 | BA9: =IF(COUNT(AX9:AZ9)<AW9,EDATE(AZ9,X9),"N/A") -> 46036 | BB9: =IF(COUNT(AX9:BA9)<AW9,EDATE(BA9,X9),"N/A") -> N/A
A10: =IF(D10="Masa",CONCATENATE(F10,"_",L10,"_",K10),F10) -> TEC-LAB-MP-01_20Kg_03 HASTA 32 | B10: =AA10 -> 61804 C | C10: Acreditado | D10: Masa | E10: Patron | F10: TEC-LAB-MP-01 | G10: Pesa | H10: Extension Laboratorio calibracion | I10: Lexus. | J10: Paralelépipedo | K10: 03 HASTA 32 | L10: 20Kg | M10: N.A | N10: Según NTC 1848 | O10: N.A | P10: 33 mg | R10: 30 | T10: N.A | U10: OIML M1 | V10: 12 | W10: 12 | X10: 4 | Y10: Externa | Z10: En Servicio | AA10: 61804 C | AB10: Detecto de Colombia S.A. | AC10: 45254 | AE10: 45671 | AF10: =EDATE(AE10,(V10)) -> 46036 | AH10: =DAYS360(TODAY(),AF10) -> -103 | AI10: =IF(Z10="Fuera de servicio","Fuera de servicio",IF(TODAY()-AF10>0,"OJO EQUIPO VENCIDO",DAYS360(TODAY(),AF10)&" DIAS RESTANTES")) -> OJO EQUIPO VENCIDO | AJ10: Solicitud compra Calibracion 2024-11-14 | AK10: =AK9 -> Cambiar color a Negro, autorizado por Don Hector | AL10: =VLOOKUP(A10,#REF!,21,FALSE) -> #REF! | AM10: =VLOOKUP(A10,#REF!,23,FALSE) -> #REF! | AN10: =AE10 -> 45671 | AO10: 45671 | AP10: =X10 -> 4 | AQ10: =EDATE(AE10,0) -> 45671 | AR10: =IF(COUNT(AQ10)<AP10,EDATE(AE10,X10),"N/A") -> 45791 | AS10: =IF(COUNT(AQ10:AR10)<AP10,EDATE(AR10,X10),"N/A") -> 45914 | AT10: =IF(COUNT(AQ10:AS10)<AP10,EDATE(AS10,X10),"N/A") -> 46036 | AU10: =IF(COUNT(AQ10:AT10)<AP10,EDATE(AT10,X10),"N/A") -> N/A | AW10: =X10 -> 4 | AX10: =EDATE(AO10,0) -> 45671 | AY10: =IF(COUNT(AX10)<AW10,EDATE(AO10,X10),"N/A") -> 45791 | AZ10: =IF(COUNT(AX10:AY10)<AW10,EDATE(AY10,X10),"N/A") -> 45914 | BA10: =IF(COUNT(AX10:AZ10)<AW10,EDATE(AZ10,X10),"N/A") -> 46036 | BB10: =IF(COUNT(AX10:BA10)<AW10,EDATE(BA10,X10),"N/A") -> N/A
A11: =IF(D11="Masa",CONCATENATE(F11,"_",L11,"_",K11),F11) -> TEC-LAB-MP-02a_5Kg, 10 kg,20kg (615 kg)_33_35 y 37 hasta 66 | B11: =AA11 -> 61791 C | C11: Acreditado | D11: Masa | E11: Patron | F11: TEC-LAB-MP-02a | G11: Juego de Pesas | H11: Extension Laboratorio calibracion | I11: Lexus. | J11: Paralelépipedo | K11: 33_35 y 37 hasta 66 | L11: 5Kg, 10 kg,20kg (615 kg) | M11: N.A | N11: Según NTC 1848 | O11: N.A | P11: 8 mg a 36 mg | R11: 32 | T11: N.A | U11: OIML M1 | V11: 12 | W11: 12 | X11: 4 | Y11: Externa | Z11: En Servicio | AA11: 61791 C | AB11: Detecto de Colombia S.A. | AC11: 45275 | AE11: 45665 | AF11: =EDATE(AE11,(V11)) -> 46030 | AH11: =DAYS360(TODAY(),AF11) -> -109 | AI11: =IF(Z11="Fuera de servicio","Fuera de servicio",IF(TODAY()-AF11>0,"OJO EQUIPO VENCIDO",DAYS360(TODAY(),AF11)&" DIAS RESTANTES")) -> OJO EQUIPO VENCIDO | AJ11: Solicitud compra Calibracion 2024-11-19 | AK11: =AK10 -> Cambiar color a Negro, autorizado por Don Hector | AL11: =VLOOKUP(A11,#REF!,21,FALSE) -> #REF! | AM11: =VLOOKUP(A11,#REF!,23,FALSE) -> #REF! | AN11: =AE11 -> 45665 | AO11: 45665 | AP11: =X11 -> 4 | AQ11: =EDATE(AE11,0) -> 45665 | AR11: =IF(COUNT(AQ11)<AP11,EDATE(AE11,X11),"N/A") -> 45785 | AS11: =IF(COUNT(AQ11:AR11)<AP11,EDATE(AR11,X11),"N/A") -> 45908 | AT11: =IF(COUNT(AQ11:AS11)<AP11,EDATE(AS11,X11),"N/A") -> 46030 | AU11: =IF(COUNT(AQ11:AT11)<AP11,EDATE(AT11,X11),"N/A") -> N/A | AW11: =X11 -> 4 | AX11: =EDATE(AO11,0) -> 45665 | AY11: =IF(COUNT(AX11)<AW11,EDATE(AO11,X11),"N/A") -> 45785 | AZ11: =IF(COUNT(AX11:AY11)<AW11,EDATE(AY11,X11),"N/A") -> 45908 | BA11: =IF(COUNT(AX11:AZ11)<AW11,EDATE(AZ11,X11),"N/A") -> 46030 | BB11: =IF(COUNT(AX11:BA11)<AW11,EDATE(BA11,X11),"N/A") -> N/A
A12: =IF(D12="Masa",CONCATENATE(F12,"_",L12,"_",K12),F12) -> TEC-LAB-MP-02_5Kg_33 | B12: =AA12 -> 61791 C | C12: Acreditado | D12: Masa | E12: Patron | F12: TEC-LAB-MP-02 | G12: Pesa | H12: Extension Laboratorio calibracion | I12: Lexus. | J12: Paralelépipedo | K12: 33 | L12: 5Kg | M12: N.A | N12: Según NTC 1848 | O12: N.A | P12: 8 mg | R12: 1 | T12: N.A | U12: OIML M1 | V12: 12 | W12: 12 | X12: 4 | Y12: Externa | Z12: En Servicio | AA12: 61791 C | AB12: Detecto de Colombia S.A. | AC12: 45281 | AE12: 45665 | AF12: =EDATE(AE12,(V12)) -> 46030 | AH12: =DAYS360(TODAY(),AF12) -> -109 | AI12: =IF(Z12="Fuera de servicio","Fuera de servicio",IF(TODAY()-AF12>0,"OJO EQUIPO VENCIDO",DAYS360(TODAY(),AF12)&" DIAS RESTANTES")) -> OJO EQUIPO VENCIDO | AJ12: Solicitud compra Calibracion 2024-11-19 | AK12: Cambiar color a Negro, autorizado por Don Hector | AL12: =VLOOKUP(A12,#REF!,21,FALSE) -> #REF! | AM12: =VLOOKUP(A12,#REF!,23,FALSE) -> #REF! | AN12: =AE12 -> 45665 | AO12: 45665 | AP12: =X12 -> 4 | AQ12: =EDATE(AE12,0) -> 45665 | AR12: =IF(COUNT(AQ12)<AP12,EDATE(AE12,X12),"N/A") -> 45785 | AS12: =IF(COUNT(AQ12:AR12)<AP12,EDATE(AR12,X12),"N/A") -> 45908 | AT12: =IF(COUNT(AQ12:AS12)<AP12,EDATE(AS12,X12),"N/A") -> 46030 | AU12: =IF(COUNT(AQ12:AT12)<AP12,EDATE(AT12,X12),"N/A") -> N/A | AW12: =X12 -> 4 | AX12: =EDATE(AO12,0) -> 45665 | AY12: =IF(COUNT(AX12)<AW12,EDATE(AO12,X12),"N/A") -> 45785 | AZ12: =IF(COUNT(AX12:AY12)<AW12,EDATE(AY12,X12),"N/A") -> 45908 | BA12: =IF(COUNT(AX12:AZ12)<AW12,EDATE(AZ12,X12),"N/A") -> 46030 | BB12: =IF(COUNT(AX12:BA12)<AW12,EDATE(BA12,X12),"N/A") -> N/A
A13: =IF(D13="Masa",CONCATENATE(F13,"_",L13,"_",K13),F13) -> TEC-LAB-MP-02_10Kg_35 | B13: =AA13 -> 61791 C | C13: Acreditado | D13: Masa | E13: Patron | F13: TEC-LAB-MP-02 | G13: Pesa | H13: Extension Laboratorio calibracion | I13: Lexus. | J13: Paralelépipedo | K13: 35 | L13: 10Kg | M13: N.A | N13: Según NTC 1848 | O13: N.A | P13: 16 mg | R13: 1 | T13: N.A | U13: OIML M1 | V13: 12 | W13: 12 | X13: 4 | Y13: Externa | Z13: En Servicio | AA13: 61791 C | AB13: Detecto de Colombia S.A. | AC13: 45281 | AE13: 45665 | AF13: =EDATE(AE13,(V13)) -> 46030 | AH13: =DAYS360(TODAY(),AF13) -> -109 | AI13: =IF(Z13="Fuera de servicio","Fuera de servicio",IF(TODAY()-AF13>0,"OJO EQUIPO VENCIDO",DAYS360(TODAY(),AF13)&" DIAS RESTANTES")) -> OJO EQUIPO VENCIDO | AJ13: Solicitud compra Calibracion 2024-11-19 | AK13: Cambiar color a Negro, autorizado por Don Hector | AL13: =VLOOKUP(A13,#REF!,21,FALSE) -> #REF! | AM13: =VLOOKUP(A13,#REF!,23,FALSE) -> #REF! | AN13: =AE13 -> 45665 | AO13: 45665 | AP13: =X13 -> 4 | AQ13: =EDATE(AE13,0) -> 45665 | AR13: =IF(COUNT(AQ13)<AP13,EDATE(AE13,X13),"N/A") -> 45785 | AS13: =IF(COUNT(AQ13:AR13)<AP13,EDATE(AR13,X13),"N/A") -> 45908 | AT13: =IF(COUNT(AQ13:AS13)<AP13,EDATE(AS13,X13),"N/A") -> 46030 | AU13: =IF(COUNT(AQ13:AT13)<AP13,EDATE(AT13,X13),"N/A") -> N/A | AW13: =X13 -> 4 | AX13: =EDATE(AO13,0) -> 45665 | AY13: =IF(COUNT(AX13)<AW13,EDATE(AO13,X13),"N/A") -> 45785 | AZ13: =IF(COUNT(AX13:AY13)<AW13,EDATE(AY13,X13),"N/A") -> 45908 | BA13: =IF(COUNT(AX13:AZ13)<AW13,EDATE(AZ13,X13),"N/A") -> 46030 | BB13: =IF(COUNT(AX13:BA13)<AW13,EDATE(BA13,X13),"N/A") -> N/A
A14: =IF(D14="Masa",CONCATENATE(F14,"_",L14,"_",K14),F14) -> TEC-LAB-MP-02_20Kg_37 HASTA 66 | B14: =AA14 -> 61791 C | C14: Acreditado | D14: Masa | E14: Patron | F14: TEC-LAB-MP-02 | G14: Pesa | H14: Extension Laboratorio calibracion | I14: Lexus. | J14: Paralelépipedo | K14: 37 HASTA 66 | L14: 20Kg | M14: N.A | N14: Según NTC 1848 | O14: N.A | P14: 33 mg | R14: 30 | T14: N.A | U14: OIML M1 | V14: 12 | W14: 12 | X14: 4 | Y14: Externa | Z14: En Servicio | AA14: 61791 C | AB14: Detecto de Colombia S.A. | AC14: 45281 | AE14: 45665 | AF14: =EDATE(AE14,(V14)) -> 46030 | AH14: =DAYS360(TODAY(),AF14) -> -109 | AI14: =IF(Z14="Fuera de servicio","Fuera de servicio",IF(TODAY()-AF14>0,"OJO EQUIPO VENCIDO",DAYS360(TODAY(),AF14)&" DIAS RESTANTES")) -> OJO EQUIPO VENCIDO | AJ14: Solicitud compra Calibracion 2024-11-19 | AK14: Cambiar color a Negro, autorizado por Don Hector | AL14: =VLOOKUP(A14,#REF!,21,FALSE) -> #REF! | AM14: =VLOOKUP(A14,#REF!,23,FALSE) -> #REF! | AN14: =AE14 -> 45665 | AO14: 45665 | AP14: =X14 -> 4 | AQ14: =EDATE(AE14,0) -> 45665 | AR14: =IF(COUNT(AQ14)<AP14,EDATE(AE14,X14),"N/A") -> 45785 | AS14: =IF(COUNT(AQ14:AR14)<AP14,EDATE(AR14,X14),"N/A") -> 45908 | AT14: =IF(COUNT(AQ14:AS14)<AP14,EDATE(AS14,X14),"N/A") -> 46030 | AU14: =IF(COUNT(AQ14:AT14)<AP14,EDATE(AT14,X14),"N/A") -> N/A | AW14: =X14 -> 4 | AX14: =EDATE(AO14,0) -> 45665 | AY14: =IF(COUNT(AX14)<AW14,EDATE(AO14,X14),"N/A") -> 45785 | AZ14: =IF(COUNT(AX14:AY14)<AW14,EDATE(AY14,X14),"N/A") -> 45908 | BA14: =IF(COUNT(AX14:AZ14)<AW14,EDATE(AZ14,X14),"N/A") -> 46030 | BB14: =IF(COUNT(AX14:BA14)<AW14,EDATE(BA14,X14),"N/A") -> N/A
A15: =IF(D15="Masa",CONCATENATE(F15,"_",L15,"_",K15),F15) -> TEC-LAB-MP-03a_5kg, 10kg,20Kg (315 kg)_34_ 36 y 67 HASTA 81 | B15: =AA15 -> 61792 C | C15: Acreditado | D15: Masa | E15: Patron | F15: TEC-LAB-MP-03a | G15: Juego de Pesas | H15: Extension Laboratorio calibracion | I15: Lexus. | J15: Paralelépipedo | K15: 34_ 36 y 67 HASTA 81 | L15: 5kg, 10kg,20Kg (315 kg) | M15: N.A | N15: Según NTC 1848 | O15: N.A | P15: 33 mg | R15: 15 | T15: N.A | U15: OIML M1 | V15: 12 | W15: 12 | X15: 4 | Y15: Externa | Z15: En Servicio | AA15: 61792 C | AB15: Detecto de Colombia S.A. | AC15: 45275 | AE15: 45665 | AF15: =EDATE(AE15,(V15)) -> 46030 | AH15: =DAYS360(TODAY(),AF15) -> -109 | AI15: =IF(Z15="Fuera de servicio","Fuera de servicio",IF(TODAY()-AF15>0,"OJO EQUIPO VENCIDO",DAYS360(TODAY(),AF15)&" DIAS RESTANTES")) -> OJO EQUIPO VENCIDO | AJ15: Solicitud compra Calibracion 2024-11-19 | AK15: Cambiar color a Negro, autorizado por Don Hector | AL15: =VLOOKUP(A15,#REF!,21,FALSE) -> #REF! | AM15: =VLOOKUP(A15,#REF!,23,FALSE) -> #REF! | AN15: =AE15 -> 45665 | AO15: 45665 | AP15: =X15 -> 4 | AQ15: =EDATE(AE15,0) -> 45665 | AR15: =IF(COUNT(AQ15)<AP15,EDATE(AE15,X15),"N/A") -> 45785 | AS15: =IF(COUNT(AQ15:AR15)<AP15,EDATE(AR15,X15),"N/A") -> 45908 | AT15: =IF(COUNT(AQ15:AS15)<AP15,EDATE(AS15,X15),"N/A") -> 46030 | AU15: =IF(COUNT(AQ15:AT15)<AP15,EDATE(AT15,X15),"N/A") -> N/A | AW15: =X15 -> 4 | AX15: =EDATE(AO15,0) -> 45665 | AY15: =IF(COUNT(AX15)<AW15,EDATE(AO15,X15),"N/A") -> 45785 | AZ15: =IF(COUNT(AX15:AY15)<AW15,EDATE(AY15,X15),"N/A") -> 45908 | BA15: =IF(COUNT(AX15:AZ15)<AW15,EDATE(AZ15,X15),"N/A") -> 46030 | BB15: =IF(COUNT(AX15:BA15)<AW15,EDATE(BA15,X15),"N/A") -> N/A
A16: =IF(D16="Masa",CONCATENATE(F16,"_",L16,"_",K16),F16) -> TEC-LAB-MP-03_5Kg_34 | B16: =AA16 -> 61972 C | C16: Acreditado | D16: Masa | E16: Patron | F16: TEC-LAB-MP-03 | G16: Pesa | H16: Extension Laboratorio calibracion | I16: Lexus. | J16: Paralelépipedo | K16: 34 | L16: 5Kg | M16: N.A | N16: Según NTC 1848 | O16: N.A | P16: 8 mg | R16: 1 | T16: N.A | U16: OIML M1 | V16: 12 | W16: 12 | X16: 4 | Y16: Externa | Z16: En Servicio | AA16: 61972 C | AB16: Detecto de Colombia S.A. | AC16: 45281 | AE16: 45665 | AF16: =EDATE(AE16,(V16)) -> 46030 | AH16: =DAYS360(TODAY(),AF16) -> -109 | AI16: =IF(Z16="Fuera de servicio","Fuera de servicio",IF(TODAY()-AF16>0,"OJO EQUIPO VENCIDO",DAYS360(TODAY(),AF16)&" DIAS RESTANTES")) -> OJO EQUIPO VENCIDO | AJ16: Solicitud compra Calibracion 2024-11-19 | AK16: Cambiar color a Negro, autorizado por Don Hector | AL16: =VLOOKUP(A16,#REF!,21,FALSE) -> #REF! | AM16: =VLOOKUP(A16,#REF!,23,FALSE) -> #REF! | AN16: =AE16 -> 45665 | AO16: 45665 | AP16: =X16 -> 4 | AQ16: =EDATE(AE16,0) -> 45665 | AR16: =IF(COUNT(AQ16)<AP16,EDATE(AE16,X16),"N/A") -> 45785 | AS16: =IF(COUNT(AQ16:AR16)<AP16,EDATE(AR16,X16),"N/A") -> 45908 | AT16: =IF(COUNT(AQ16:AS16)<AP16,EDATE(AS16,X16),"N/A") -> 46030 | AU16: =IF(COUNT(AQ16:AT16)<AP16,EDATE(AT16,X16),"N/A") -> N/A | AW16: =X16 -> 4 | AX16: =EDATE(AO16,0) -> 45665 | AY16: =IF(COUNT(AX16)<AW16,EDATE(AO16,X16),"N/A") -> 45785 | AZ16: =IF(COUNT(AX16:AY16)<AW16,EDATE(AY16,X16),"N/A") -> 45908 | BA16: =IF(COUNT(AX16:AZ16)<AW16,EDATE(AZ16,X16),"N/A") -> 46030 | BB16: =IF(COUNT(AX16:BA16)<AW16,EDATE(BA16,X16),"N/A") -> N/A
A17: =IF(D17="Masa",CONCATENATE(F17,"_",L17,"_",K17),F17) -> TEC-LAB-MP-03_10Kg_36 | B17: =AA17 -> 61972 C | C17: Acreditado | D17: Masa | E17: Patron | F17: TEC-LAB-MP-03 | G17: Pesa | H17: Extension Laboratorio calibracion | I17: Lexus. | J17: Paralelépipedo | K17: 36 | L17: 10Kg | M17: N.A | N17: Según NTC 1848 | O17: N.A | P17: 16 mg | R17: 1 | T17: N.A | U17: OIML M1 | V17: 12 | W17: 12 | X17: 4 | Y17: Externa | Z17: En Servicio | AA17: 61972 C | AB17: Detecto de Colombia S.A. | AC17: 45281 | AE17: 45665 | AF17: =EDATE(AE17,(V17)) -> 46030 | AH17: =DAYS360(TODAY(),AF17) -> -109 | AI17: =IF(Z17="Fuera de servicio","Fuera de servicio",IF(TODAY()-AF17>0,"OJO EQUIPO VENCIDO",DAYS360(TODAY(),AF17)&" DIAS RESTANTES")) -> OJO EQUIPO VENCIDO | AJ17: Solicitud compra Calibracion 2024-11-19 | AK17: Cambiar color a Negro, autorizado por Don Hector | AL17: =VLOOKUP(A17,#REF!,21,FALSE) -> #REF! | AM17: =VLOOKUP(A17,#REF!,23,FALSE) -> #REF! | AN17: =AE17 -> 45665 | AO17: 45665 | AP17: =X17 -> 4 | AQ17: =EDATE(AE17,0) -> 45665 | AR17: =IF(COUNT(AQ17)<AP17,EDATE(AE17,X17),"N/A") -> 45785 | AS17: =IF(COUNT(AQ17:AR17)<AP17,EDATE(AR17,X17),"N/A") -> 45908 | AT17: =IF(COUNT(AQ17:AS17)<AP17,EDATE(AS17,X17),"N/A") -> 46030 | AU17: =IF(COUNT(AQ17:AT17)<AP17,EDATE(AT17,X17),"N/A") -> N/A | AW17: =X17 -> 4 | AX17: =EDATE(AO17,0) -> 45665 | AY17: =IF(COUNT(AX17)<AW17,EDATE(AO17,X17),"N/A") -> 45785 | AZ17: =IF(COUNT(AX17:AY17)<AW17,EDATE(AY17,X17),"N/A") -> 45908 | BA17: =IF(COUNT(AX17:AZ17)<AW17,EDATE(AZ17,X17),"N/A") -> 46030 | BB17: =IF(COUNT(AX17:BA17)<AW17,EDATE(BA17,X17),"N/A") -> N/A
A18: =IF(D18="Masa",CONCATENATE(F18,"_",L18,"_",K18),F18) -> TEC-LAB-MP-03_20Kg_67 HASTA 81 | B18: =AA18 -> 61972 C | C18: Acreditado | D18: Masa | E18: Patron | F18: TEC-LAB-MP-03 | G18: Pesa | H18: Extension Laboratorio calibracion | I18: Lexus. | J18: Paralelépipedo | K18: 67 HASTA 81 | L18: 20Kg | M18: N.A | N18: Según NTC 1848 | O18: N.A | P18: 33 mg | R18: 15 | T18: N.A | U18: OIML M1 | V18: 12 | W18: 12 | X18: 4 | Y18: Externa | Z18: En Servicio | AA18: 61972 C | AB18: Detecto de Colombia S.A. | AC18: 45281 | AE18: 45665 | AF18: =EDATE(AE18,(V18)) -> 46030 | AH18: =DAYS360(TODAY(),AF18) -> -109 | AI18: =IF(Z18="Fuera de servicio","Fuera de servicio",IF(TODAY()-AF18>0,"OJO EQUIPO VENCIDO",DAYS360(TODAY(),AF18)&" DIAS RESTANTES")) -> OJO EQUIPO VENCIDO | AJ18: Solicitud compra Calibracion 2024-11-19 | AK18: Cambiar color a Negro, autorizado por Don Hector | AL18: =VLOOKUP(A18,#REF!,21,FALSE) -> #REF! | AM18: =VLOOKUP(A18,#REF!,23,FALSE) -> #REF! | AN18: =AE18 -> 45665 | AO18: 45665 | AP18: =X18 -> 4 | AQ18: =EDATE(AE18,0) -> 45665 | AR18: =IF(COUNT(AQ18)<AP18,EDATE(AE18,X18),"N/A") -> 45785 | AS18: =IF(COUNT(AQ18:AR18)<AP18,EDATE(AR18,X18),"N/A") -> 45908 | AT18: =IF(COUNT(AQ18:AS18)<AP18,EDATE(AS18,X18),"N/A") -> 46030 | AU18: =IF(COUNT(AQ18:AT18)<AP18,EDATE(AT18,X18),"N/A") -> N/A | AW18: =X18 -> 4 | AX18: =EDATE(AO18,0) -> 45665 | AY18: =IF(COUNT(AX18)<AW18,EDATE(AO18,X18),"N/A") -> 45785 | AZ18: =IF(COUNT(AX18:AY18)<AW18,EDATE(AY18,X18),"N/A") -> 45908 | BA18: =IF(COUNT(AX18:AZ18)<AW18,EDATE(AZ18,X18),"N/A") -> 46030 | BB18: =IF(COUNT(AX18:BA18)<AW18,EDATE(BA18,X18),"N/A") -> N/A
A19: =IF(D19="Masa",CONCATENATE(F19,"_",L19,"_",K19),F19) -> TEC-LAB-MP-04a_0,001g a 200g_N.I. | B19: =AA19 -> 62119 C | C19: Acreditado | D19: Masa | E19: Patron | F19: TEC-LAB-MP-04a | G19: Juego de Pesas | H19: Laboratorio de calibracion - Patrones | I19: Accurate Ltd | J19: Láminas | K19: N.I. | L19: 0,001g a 200g | M19: N.A | N19: Según NTC 1848 | O19: N.A | P19: 0,0020mg a 0,1mg | R19: 23 | T19: N.A | U19: OIML E2 | V19: 12 | W19: 12 | X19: 4 | Y19: Externa | Z19: En Servicio | AA19: 62119 C | AB19: Detecto de Colombia S.A. | AC19: 45318 | AE19: 45701 | AF19: =EDATE(AE19,(V19)) -> 46066 | AG19: EQ enviado a calibracion 2025-02-05 , retornado 2025-02-20 | AH19: =DAYS360(TODAY(),AF19) -> -74 | AI19: =IF(Z19="Fuera de servicio","Fuera de servicio",IF(TODAY()-AF19>0,"OJO EQUIPO VENCIDO",DAYS360(TODAY(),AF19)&" DIAS RESTANTES")) -> OJO EQUIPO VENCIDO | AJ19: Se solicito cotizacion 2025-01-16 | AK19: Se envia a calibracion 2025-02-05 | AL19: =VLOOKUP(A19,#REF!,21,FALSE) -> #REF! | AM19: =VLOOKUP(A19,#REF!,23,FALSE) -> #REF! | AN19: =AE19 -> 45701 | AO19: 45701 | AP19: =X19 -> 4 | AQ19: =EDATE(AE19,0) -> 45701 | AR19: =IF(COUNT(AQ19)<AP19,EDATE(AE19,X19),"N/A") -> 45821 | AS19: =IF(COUNT(AQ19:AR19)<AP19,EDATE(AR19,X19),"N/A") -> 45943 | AT19: =IF(COUNT(AQ19:AS19)<AP19,EDATE(AS19,X19),"N/A") -> 46066 | AU19: =IF(COUNT(AQ19:AT19)<AP19,EDATE(AT19,X19),"N/A") -> N/A | AW19: =X19 -> 4 | AX19: =EDATE(AO19,0) -> 45701 | AY19: =IF(COUNT(AX19)<AW19,EDATE(AO19,X19),"N/A") -> 45821 | AZ19: =IF(COUNT(AX19:AY19)<AW19,EDATE(AY19,X19),"N/A") -> 45943 | BA19: =IF(COUNT(AX19:AZ19)<AW19,EDATE(AZ19,X19),"N/A") -> 46066 | BB19: =IF(COUNT(AX19:BA19)<AW19,EDATE(BA19,X19),"N/A") -> N/A
A20: =IF(D20="Masa",CONCATENATE(F20,"_",L20,"_",K20),F20) -> TEC-LAB-MP-04_0,001g_N.I. | B20: =AA20 -> 62119 C | C20: Acreditado | D20: Masa | E20: Patron | F20: TEC-LAB-MP-04 | G20: Pesa | H20: Laboratorio de calibracion - Patrones | I20: Accurate Ltd | J20: Láminas | K20: N.I. | L20: 0,001g | M20: N.A | N20: 0,006mg | P20: 0,0020 mg | R20: 1 | T20: N.A | U20: OIML E2 | V20: 12 | W20: 12 | X20: 4 | Y20: Externa | Z20: En Servicio | AA20: 62119 C | AB20: Detecto de Colombia S.A. | AC20: 45318 | AE20: 45701 | AF20: =EDATE(AE20,(V20)) -> 46066 | AH20: =DAYS360(TODAY(),AF20) -> -74 | AI20: =IF(Z20="Fuera de servicio","Fuera de servicio",IF(TODAY()-AF20>0,"OJO EQUIPO VENCIDO",DAYS360(TODAY(),AF20)&" DIAS RESTANTES")) -> OJO EQUIPO VENCIDO | AL20: =VLOOKUP(A20,#REF!,21,FALSE) -> #REF! | AM20: =VLOOKUP(A20,#REF!,23,FALSE) -> #REF! | AN20: =AE20 -> 45701 | AO20: 45701 | AP20: =X20 -> 4 | AQ20: =EDATE(AE20,0) -> 45701 | AR20: =IF(COUNT(AQ20)<AP20,EDATE(AE20,X20),"N/A") -> 45821 | AS20: =IF(COUNT(AQ20:AR20)<AP20,EDATE(AR20,X20),"N/A") -> 45943 | AT20: =IF(COUNT(AQ20:AS20)<AP20,EDATE(AS20,X20),"N/A") -> 46066 | AU20: =IF(COUNT(AQ20:AT20)<AP20,EDATE(AT20,X20),"N/A") -> N/A | AW20: =X20 -> 4 | AX20: =EDATE(AO20,0) -> 45701 | AY20: =IF(COUNT(AX20)<AW20,EDATE(AO20,X20),"N/A") -> 45821 | AZ20: =IF(COUNT(AX20:AY20)<AW20,EDATE(AY20,X20),"N/A") -> 45943 | BA20: =IF(COUNT(AX20:AZ20)<AW20,EDATE(AZ20,X20),"N/A") -> 46066 | BB20: =IF(COUNT(AX20:BA20)<AW20,EDATE(BA20,X20),"N/A") -> N/A
A21: =IF(D21="Masa",CONCATENATE(F21,"_",L21,"_",K21),F21) -> TEC-LAB-MP-04_0,002g_N.I. | B21: =AA21 -> 62119 C | C21: Acreditado | D21: Masa | E21: Patron | F21: TEC-LAB-MP-04 | G21: Pesa | H21: Laboratorio de calibracion - Patrones | I21: Accurate Ltd | J21: Láminas | K21: N.I. | L21: 0,002g | M21: N.A | N21: 0,006mg | P21: 0,0020 mg | R21: 1 | T21: N.A | U21: OIML E2 | V21: 12 | W21: 12 | X21: 4 | Y21: Externa | Z21: En Servicio | AA21: 62119 C | AB21: Detecto de Colombia S.A. | AC21: 45318 | AE21: 45701 | AF21: =EDATE(AE21,(V21)) -> 46066 | AH21: =DAYS360(TODAY(),AF21) -> -74 | AI21: =IF(Z21="Fuera de servicio","Fuera de servicio",IF(TODAY()-AF21>0,"OJO EQUIPO VENCIDO",DAYS360(TODAY(),AF21)&" DIAS RESTANTES")) -> OJO EQUIPO VENCIDO | AL21: =VLOOKUP(A21,#REF!,21,FALSE) -> #REF! | AM21: =VLOOKUP(A21,#REF!,23,FALSE) -> #REF! | AN21: =AE21 -> 45701 | AO21: 45701 | AP21: =X21 -> 4 | AQ21: =EDATE(AE21,0) -> 45701 | AR21: =IF(COUNT(AQ21)<AP21,EDATE(AE21,X21),"N/A") -> 45821 | AS21: =IF(COUNT(AQ21:AR21)<AP21,EDATE(AR21,X21),"N/A") -> 45943 | AT21: =IF(COUNT(AQ21:AS21)<AP21,EDATE(AS21,X21),"N/A") -> 46066 | AU21: =IF(COUNT(AQ21:AT21)<AP21,EDATE(AT21,X21),"N/A") -> N/A | AW21: =X21 -> 4 | AX21: =EDATE(AO21,0) -> 45701 | AY21: =IF(COUNT(AX21)<AW21,EDATE(AO21,X21),"N/A") -> 45821 | AZ21: =IF(COUNT(AX21:AY21)<AW21,EDATE(AY21,X21),"N/A") -> 45943 | BA21: =IF(COUNT(AX21:AZ21)<AW21,EDATE(AZ21,X21),"N/A") -> 46066 | BB21: =IF(COUNT(AX21:BA21)<AW21,EDATE(BA21,X21),"N/A") -> N/A
A22: =IF(D22="Masa",CONCATENATE(F22,"_",L22,"_",K22),F22) -> TEC-LAB-MP-04_0,002g_PUNTO | B22: =AA22 -> 62119 C | C22: Acreditado | D22: Masa | E22: Patron | F22: TEC-LAB-MP-04 | G22: Pesa | H22: Laboratorio de calibracion - Patrones | I22: Accurate Ltd | J22: Láminas | K22: PUNTO | L22: 0,002g | M22: N.A | N22: 0,006mg | P22: 0,0020 mg | R22: 1 | T22: N.A | U22: OIML E2 | V22: 12 | W22: 12 | X22: 4 | Y22: Externa | Z22: En Servicio | AA22: 62119 C | AB22: Detecto de Colombia S.A. | AC22: 45318 | AE22: 45701 | AF22: =EDATE(AE22,(V22)) -> 46066 | AH22: =DAYS360(TODAY(),AF22) -> -74 | AI22: =IF(Z22="Fuera de servicio","Fuera de servicio",IF(TODAY()-AF22>0,"OJO EQUIPO VENCIDO",DAYS360(TODAY(),AF22)&" DIAS RESTANTES")) -> OJO EQUIPO VENCIDO | AL22: =VLOOKUP(A22,#REF!,21,FALSE) -> #REF! | AM22: =VLOOKUP(A22,#REF!,23,FALSE) -> #REF! | AN22: =AE22 -> 45701 | AO22: 45701 | AP22: =X22 -> 4 | AQ22: =EDATE(AE22,0) -> 45701 | AR22: =IF(COUNT(AQ22)<AP22,EDATE(AE22,X22),"N/A") -> 45821 | AS22: =IF(COUNT(AQ22:AR22)<AP22,EDATE(AR22,X22),"N/A") -> 45943 | AT22: =IF(COUNT(AQ22:AS22)<AP22,EDATE(AS22,X22),"N/A") -> 46066 | AU22: =IF(COUNT(AQ22:AT22)<AP22,EDATE(AT22,X22),"N/A") -> N/A | AW22: =X22 -> 4 | AX22: =EDATE(AO22,0) -> 45701 | AY22: =IF(COUNT(AX22)<AW22,EDATE(AO22,X22),"N/A") -> 45821 | AZ22: =IF(COUNT(AX22:AY22)<AW22,EDATE(AY22,X22),"N/A") -> 45943 | BA22: =IF(COUNT(AX22:AZ22)<AW22,EDATE(AZ22,X22),"N/A") -> 46066 | BB22: =IF(COUNT(AX22:BA22)<AW22,EDATE(BA22,X22),"N/A") -> N/A
A23: =IF(D23="Masa",CONCATENATE(F23,"_",L23,"_",K23),F23) -> TEC-LAB-MP-04_0,005g_N.I. | B23: =AA23 -> 62119 C | C23: Acreditado | D23: Masa | E23: Patron | F23: TEC-LAB-MP-04 | G23: Pesa | H23: Laboratorio de calibracion - Patrones | I23: Accurate Ltd | J23: Láminas | K23: N.I. | L23: 0,005g | M23: N.A | N23: 0,006mg | P23: 0,0020 mg | R23: 1 | T23: N.A | U23: OIML E2 | V23: 12 | W23: 12 | X23: 4 | Y23: Externa | Z23: En Servicio | AA23: 62119 C | AB23: Detecto de Colombia S.A. | AC23: 45318 | AE23: 45701 | AF23: =EDATE(AE23,(V23)) -> 46066 | AH23: =DAYS360(TODAY(),AF23) -> -74 | AI23: =IF(Z23="Fuera de servicio","Fuera de servicio",IF(TODAY()-AF23>0,"OJO EQUIPO VENCIDO",DAYS360(TODAY(),AF23)&" DIAS RESTANTES")) -> OJO EQUIPO VENCIDO | AL23: =VLOOKUP(A23,#REF!,21,FALSE) -> #REF! | AM23: =VLOOKUP(A23,#REF!,23,FALSE) -> #REF! | AN23: =AE23 -> 45701 | AO23: 45701 | AP23: =X23 -> 4 | AQ23: =EDATE(AE23,0) -> 45701 | AR23: =IF(COUNT(AQ23)<AP23,EDATE(AE23,X23),"N/A") -> 45821 | AS23: =IF(COUNT(AQ23:AR23)<AP23,EDATE(AR23,X23),"N/A") -> 45943 | AT23: =IF(COUNT(AQ23:AS23)<AP23,EDATE(AS23,X23),"N/A") -> 46066 | AU23: =IF(COUNT(AQ23:AT23)<AP23,EDATE(AT23,X23),"N/A") -> N/A | AW23: =X23 -> 4 | AX23: =EDATE(AO23,0) -> 45701 | AY23: =IF(COUNT(AX23)<AW23,EDATE(AO23,X23),"N/A") -> 45821 | AZ23: =IF(COUNT(AX23:AY23)<AW23,EDATE(AY23,X23),"N/A") -> 45943 | BA23: =IF(COUNT(AX23:AZ23)<AW23,EDATE(AZ23,X23),"N/A") -> 46066 | BB23: =IF(COUNT(AX23:BA23)<AW23,EDATE(BA23,X23),"N/A") -> N/A
A24: =IF(D24="Masa",CONCATENATE(F24,"_",L24,"_",K24),F24) -> TEC-LAB-MP-04_0,01g_N.I. | B24: =AA24 -> 62119 C | C24: Acreditado | D24: Masa | E24: Patron | F24: TEC-LAB-MP-04 | G24: Pesa | H24: Laboratorio de calibracion - Patrones | I24: Accurate Ltd | J24: Láminas | K24: N.I. | L24: 0,01g | M24: N.A | N24: 0,008mg | P24: 0,0027 mg | R24: 1 | T24: N.A | U24: OIML E2 | V24: 12 | W24: 12 | X24: 4 | Y24: Externa | Z24: En Servicio | AA24: 62119 C | AB24: Detecto de Colombia S.A. | AC24: 45318 | AE24: 45701 | AF24: =EDATE(AE24,(V24)) -> 46066 | AH24: =DAYS360(TODAY(),AF24) -> -74 | AI24: =IF(Z24="Fuera de servicio","Fuera de servicio",IF(TODAY()-AF24>0,"OJO EQUIPO VENCIDO",DAYS360(TODAY(),AF24)&" DIAS RESTANTES")) -> OJO EQUIPO VENCIDO | AL24: =VLOOKUP(A24,#REF!,21,FALSE) -> #REF! | AM24: =VLOOKUP(A24,#REF!,23,FALSE) -> #REF! | AN24: =AE24 -> 45701 | AO24: 45701 | AP24: =X24 -> 4 | AQ24: =EDATE(AE24,0) -> 45701 | AR24: =IF(COUNT(AQ24)<AP24,EDATE(AE24,X24),"N/A") -> 45821 | AS24: =IF(COUNT(AQ24:AR24)<AP24,EDATE(AR24,X24),"N/A") -> 45943 | AT24: =IF(COUNT(AQ24:AS24)<AP24,EDATE(AS24,X24),"N/A") -> 46066 | AU24: =IF(COUNT(AQ24:AT24)<AP24,EDATE(AT24,X24),"N/A") -> N/A | AW24: =X24 -> 4 | AX24: =EDATE(AO24,0) -> 45701 | AY24: =IF(COUNT(AX24)<AW24,EDATE(AO24,X24),"N/A") -> 45821 | AZ24: =IF(COUNT(AX24:AY24)<AW24,EDATE(AY24,X24),"N/A") -> 45943 | BA24: =IF(COUNT(AX24:AZ24)<AW24,EDATE(AZ24,X24),"N/A") -> 46066 | BB24: =IF(COUNT(AX24:BA24)<AW24,EDATE(BA24,X24),"N/A") -> N/A
A25: =IF(D25="Masa",CONCATENATE(F25,"_",L25,"_",K25),F25) -> TEC-LAB-MP-04_0,02g_N.I. | B25: =AA25 -> 62119 C | C25: Acreditado | D25: Masa | E25: Patron | F25: TEC-LAB-MP-04 | G25: Pesa | H25: Laboratorio de calibracion - Patrones | I25: Accurate Ltd | J25: Láminas | K25: N.I. | L25: 0,02g | M25: N.A | N25: 0,01mg | P25: 0,0033 mg | R25: 1 | T25: N.A | U25: OIML E2 | V25: 12 | W25: 12 | X25: 4 | Y25: Externa | Z25: En Servicio | AA25: 62119 C | AB25: Detecto de Colombia S.A. | AC25: 45318 | AE25: 45701 | AF25: =EDATE(AE25,(V25)) -> 46066 | AH25: =DAYS360(TODAY(),AF25) -> -74 | AI25: =IF(Z25="Fuera de servicio","Fuera de servicio",IF(TODAY()-AF25>0,"OJO EQUIPO VENCIDO",DAYS360(TODAY(),AF25)&" DIAS RESTANTES")) -> OJO EQUIPO VENCIDO | AL25: =VLOOKUP(A25,#REF!,21,FALSE) -> #REF! | AM25: =VLOOKUP(A25,#REF!,23,FALSE) -> #REF! | AN25: =AE25 -> 45701 | AO25: 45701 | AP25: =X25 -> 4 | AQ25: =EDATE(AE25,0) -> 45701 | AR25: =IF(COUNT(AQ25)<AP25,EDATE(AE25,X25),"N/A") -> 45821 | AS25: =IF(COUNT(AQ25:AR25)<AP25,EDATE(AR25,X25),"N/A") -> 45943 | AT25: =IF(COUNT(AQ25:AS25)<AP25,EDATE(AS25,X25),"N/A") -> 46066 | AU25: =IF(COUNT(AQ25:AT25)<AP25,EDATE(AT25,X25),"N/A") -> N/A | AW25: =X25 -> 4 | AX25: =EDATE(AO25,0) -> 45701 | AY25: =IF(COUNT(AX25)<AW25,EDATE(AO25,X25),"N/A") -> 45821 | AZ25: =IF(COUNT(AX25:AY25)<AW25,EDATE(AY25,X25),"N/A") -> 45943 | BA25: =IF(COUNT(AX25:AZ25)<AW25,EDATE(AZ25,X25),"N/A") -> 46066 | BB25: =IF(COUNT(AX25:BA25)<AW25,EDATE(BA25,X25),"N/A") -> N/A
A26: =IF(D26="Masa",CONCATENATE(F26,"_",L26,"_",K26),F26) -> TEC-LAB-MP-04_0,02g_PUNTO | B26: =AA26 -> 62119 C | C26: Acreditado | D26: Masa | E26: Patron | F26: TEC-LAB-MP-04 | G26: Pesa | H26: Laboratorio de calibracion - Patrones | I26: Accurate Ltd | J26: Láminas | K26: PUNTO | L26: 0,02g | M26: N.A | N26: 0,01mg | P26: 0,0033 mg | R26: 1 | T26: N.A | U26: OIML E2 | V26: 12 | W26: 12 | X26: 4 | Y26: Externa | Z26: En Servicio | AA26: 62119 C | AB26: Detecto de Colombia S.A. | AC26: 45318 | AE26: 45701 | AF26: =EDATE(AE26,(V26)) -> 46066 | AH26: =DAYS360(TODAY(),AF26) -> -74 | AI26: =IF(Z26="Fuera de servicio","Fuera de servicio",IF(TODAY()-AF26>0,"OJO EQUIPO VENCIDO",DAYS360(TODAY(),AF26)&" DIAS RESTANTES")) -> OJO EQUIPO VENCIDO | AL26: =VLOOKUP(A26,#REF!,21,FALSE) -> #REF! | AM26: =VLOOKUP(A26,#REF!,23,FALSE) -> #REF! | AN26: =AE26 -> 45701 | AO26: 45701 | AP26: =X26 -> 4 | AQ26: =EDATE(AE26,0) -> 45701 | AR26: =IF(COUNT(AQ26)<AP26,EDATE(AE26,X26),"N/A") -> 45821 | AS26: =IF(COUNT(AQ26:AR26)<AP26,EDATE(AR26,X26),"N/A") -> 45943 | AT26: =IF(COUNT(AQ26:AS26)<AP26,EDATE(AS26,X26),"N/A") -> 46066 | AU26: =IF(COUNT(AQ26:AT26)<AP26,EDATE(AT26,X26),"N/A") -> N/A | AW26: =X26 -> 4 | AX26: =EDATE(AO26,0) -> 45701 | AY26: =IF(COUNT(AX26)<AW26,EDATE(AO26,X26),"N/A") -> 45821 | AZ26: =IF(COUNT(AX26:AY26)<AW26,EDATE(AY26,X26),"N/A") -> 45943 | BA26: =IF(COUNT(AX26:AZ26)<AW26,EDATE(AZ26,X26),"N/A") -> 46066 | BB26: =IF(COUNT(AX26:BA26)<AW26,EDATE(BA26,X26),"N/A") -> N/A
A27: =IF(D27="Masa",CONCATENATE(F27,"_",L27,"_",K27),F27) -> TEC-LAB-MP-04_0,05g_N.I. | B27: =AA27 -> 62119 C | C27: Acreditado | D27: Masa | E27: Patron | F27: TEC-LAB-MP-04 | G27: Pesa | H27: Laboratorio de calibracion - Patrones | I27: Accurate Ltd | J27: Láminas | K27: N.I. | L27: 0,05g | M27: N.A | N27: 0,012mg | P27: 0,0040 mg | R27: 1 | T27: N.A | U27: OIML E2 | V27: 12 | W27: 12 | X27: 4 | Y27: Externa | Z27: En Servicio | AA27: 62119 C | AB27: Detecto de Colombia S.A. | AC27: 45318 | AE27: 45701 | AF27: =EDATE(AE27,(V27)) -> 46066 | AH27: =DAYS360(TODAY(),AF27) -> -74 | AI27: =IF(Z27="Fuera de servicio","Fuera de servicio",IF(TODAY()-AF27>0,"OJO EQUIPO VENCIDO",DAYS360(TODAY(),AF27)&" DIAS RESTANTES")) -> OJO EQUIPO VENCIDO | AL27: =VLOOKUP(A27,#REF!,21,FALSE) -> #REF! | AM27: =VLOOKUP(A27,#REF!,23,FALSE) -> #REF! | AN27: =AE27 -> 45701 | AO27: 45701 | AP27: =X27 -> 4 | AQ27: =EDATE(AE27,0) -> 45701 | AR27: =IF(COUNT(AQ27)<AP27,EDATE(AE27,X27),"N/A") -> 45821 | AS27: =IF(COUNT(AQ27:AR27)<AP27,EDATE(AR27,X27),"N/A") -> 45943 | AT27: =IF(COUNT(AQ27:AS27)<AP27,EDATE(AS27,X27),"N/A") -> 46066 | AU27: =IF(COUNT(AQ27:AT27)<AP27,EDATE(AT27,X27),"N/A") -> N/A | AW27: =X27 -> 4 | AX27: =EDATE(AO27,0) -> 45701 | AY27: =IF(COUNT(AX27)<AW27,EDATE(AO27,X27),"N/A") -> 45821 | AZ27: =IF(COUNT(AX27:AY27)<AW27,EDATE(AY27,X27),"N/A") -> 45943 | BA27: =IF(COUNT(AX27:AZ27)<AW27,EDATE(AZ27,X27),"N/A") -> 46066 | BB27: =IF(COUNT(AX27:BA27)<AW27,EDATE(BA27,X27),"N/A") -> N/A
A28: =IF(D28="Masa",CONCATENATE(F28,"_",L28,"_",K28),F28) -> TEC-LAB-MP-04_0,1g_N.I. | B28: =AA28 -> 62119 C | C28: Acreditado | D28: Masa | E28: Patron | F28: TEC-LAB-MP-04 | G28: Pesa | H28: Laboratorio de calibracion - Patrones | I28: Accurate Ltd | J28: Láminas | K28: N.I. | L28: 0,1g | M28: N.A | N28: 0,016mg | P28: 0,0053 mg | R28: 1 | T28: N.A | U28: OIML E2 | V28: 12 | W28: 12 | X28: 4 | Y28: Externa | Z28: En Servicio | AA28: 62119 C | AB28: Detecto de Colombia S.A. | AC28: 45318 | AE28: 45701 | AF28: =EDATE(AE28,(V28)) -> 46066 | AH28: =DAYS360(TODAY(),AF28) -> -74 | AI28: =IF(Z28="Fuera de servicio","Fuera de servicio",IF(TODAY()-AF28>0,"OJO EQUIPO VENCIDO",DAYS360(TODAY(),AF28)&" DIAS RESTANTES")) -> OJO EQUIPO VENCIDO | AL28: =VLOOKUP(A28,#REF!,21,FALSE) -> #REF! | AM28: =VLOOKUP(A28,#REF!,23,FALSE) -> #REF! | AN28: =AE28 -> 45701 | AO28: 45701 | AP28: =X28 -> 4 | AQ28: =EDATE(AE28,0) -> 45701 | AR28: =IF(COUNT(AQ28)<AP28,EDATE(AE28,X28),"N/A") -> 45821 | AS28: =IF(COUNT(AQ28:AR28)<AP28,EDATE(AR28,X28),"N/A") -> 45943 | AT28: =IF(COUNT(AQ28:AS28)<AP28,EDATE(AS28,X28),"N/A") -> 46066 | AU28: =IF(COUNT(AQ28:AT28)<AP28,EDATE(AT28,X28),"N/A") -> N/A | AW28: =X28 -> 4 | AX28: =EDATE(AO28,0) -> 45701 | AY28: =IF(COUNT(AX28)<AW28,EDATE(AO28,X28),"N/A") -> 45821 | AZ28: =IF(COUNT(AX28:AY28)<AW28,EDATE(AY28,X28),"N/A") -> 45943 | BA28: =IF(COUNT(AX28:AZ28)<AW28,EDATE(AZ28,X28),"N/A") -> 46066 | BB28: =IF(COUNT(AX28:BA28)<AW28,EDATE(BA28,X28),"N/A") -> N/A
A29: =IF(D29="Masa",CONCATENATE(F29,"_",L29,"_",K29),F29) -> TEC-LAB-MP-04_0,2g_N.I. | B29: =AA29 -> 62119 C | C29: Acreditado | D29: Masa | E29: Patron | F29: TEC-LAB-MP-04 | G29: Pesa | H29: Laboratorio de calibracion - Patrones | I29: Accurate Ltd | J29: Láminas | K29: N.I. | L29: 0,2g | M29: N.A | N29: 0,02mg | P29: 0,0067 mg | R29: 1 | T29: N.A | U29: OIML E2 | V29: 12 | W29: 12 | X29: 4 | Y29: Externa | Z29: En Servicio | AA29: 62119 C | AB29: Detecto de Colombia S.A. | AC29: 45318 | AE29: 45701 | AF29: =EDATE(AE29,(V29)) -> 46066 | AH29: =DAYS360(TODAY(),AF29) -> -74 | AI29: =IF(Z29="Fuera de servicio","Fuera de servicio",IF(TODAY()-AF29>0,"OJO EQUIPO VENCIDO",DAYS360(TODAY(),AF29)&" DIAS RESTANTES")) -> OJO EQUIPO VENCIDO | AL29: =VLOOKUP(A29,#REF!,21,FALSE) -> #REF! | AM29: =VLOOKUP(A29,#REF!,23,FALSE) -> #REF! | AN29: =AE29 -> 45701 | AO29: 45701 | AP29: =X29 -> 4 | AQ29: =EDATE(AE29,0) -> 45701 | AR29: =IF(COUNT(AQ29)<AP29,EDATE(AE29,X29),"N/A") -> 45821 | AS29: =IF(COUNT(AQ29:AR29)<AP29,EDATE(AR29,X29),"N/A") -> 45943 | AT29: =IF(COUNT(AQ29:AS29)<AP29,EDATE(AS29,X29),"N/A") -> 46066 | AU29: =IF(COUNT(AQ29:AT29)<AP29,EDATE(AT29,X29),"N/A") -> N/A | AW29: =X29 -> 4 | AX29: =EDATE(AO29,0) -> 45701 | AY29: =IF(COUNT(AX29)<AW29,EDATE(AO29,X29),"N/A") -> 45821 | AZ29: =IF(COUNT(AX29:AY29)<AW29,EDATE(AY29,X29),"N/A") -> 45943 | BA29: =IF(COUNT(AX29:AZ29)<AW29,EDATE(AZ29,X29),"N/A") -> 46066 | BB29: =IF(COUNT(AX29:BA29)<AW29,EDATE(BA29,X29),"N/A") -> N/A
A30: =IF(D30="Masa",CONCATENATE(F30,"_",L30,"_",K30),F30) -> TEC-LAB-MP-04_0,2g_PUNTO | B30: =AA30 -> 62119 C | C30: Acreditado | D30: Masa | E30: Patron | F30: TEC-LAB-MP-04 | G30: Pesa | H30: Laboratorio de calibracion - Patrones | I30: Accurate Ltd | J30: Láminas | K30: PUNTO | L30: 0,2g | M30: N.A | N30: 0,02mg | P30: 0,0067 mg | R30: 1 | T30: N.A | U30: OIML E2 | V30: 12 | W30: 12 | X30: 4 | Y30: Externa | Z30: En Servicio | AA30: 62119 C | AB30: Detecto de Colombia S.A. | AC30: 45318 | AE30: 45701 | AF30: =EDATE(AE30,(V30)) -> 46066 | AH30: =DAYS360(TODAY(),AF30) -> -74 | AI30: =IF(Z30="Fuera de servicio","Fuera de servicio",IF(TODAY()-AF30>0,"OJO EQUIPO VENCIDO",DAYS360(TODAY(),AF30)&" DIAS RESTANTES")) -> OJO EQUIPO VENCIDO | AL30: =VLOOKUP(A30,#REF!,21,FALSE) -> #REF! | AM30: =VLOOKUP(A30,#REF!,23,FALSE) -> #REF! | AN30: =AE30 -> 45701 | AO30: 45701 | AP30: =X30 -> 4 | AQ30: =EDATE(AE30,0) -> 45701 | AR30: =IF(COUNT(AQ30)<AP30,EDATE(AE30,X30),"N/A") -> 45821 | AS30: =IF(COUNT(AQ30:AR30)<AP30,EDATE(AR30,X30),"N/A") -> 45943 | AT30: =IF(COUNT(AQ30:AS30)<AP30,EDATE(AS30,X30),"N/A") -> 46066 | AU30: =IF(COUNT(AQ30:AT30)<AP30,EDATE(AT30,X30),"N/A") -> N/A | AW30: =X30 -> 4 | AX30: =EDATE(AO30,0) -> 45701 | AY30: =IF(COUNT(AX30)<AW30,EDATE(AO30,X30),"N/A") -> 45821 | AZ30: =IF(COUNT(AX30:AY30)<AW30,EDATE(AY30,X30),"N/A") -> 45943 | BA30: =IF(COUNT(AX30:AZ30)<AW30,EDATE(AZ30,X30),"N/A") -> 46066 | BB30: =IF(COUNT(AX30:BA30)<AW30,EDATE(BA30,X30),"N/A") -> N/A
A31: =IF(D31="Masa",CONCATENATE(F31,"_",L31,"_",K31),F31) -> TEC-LAB-MP-04_0,5g_N.I. | B31: =AA31 -> 62119 C | C31: Acreditado | D31: Masa | E31: Patron | F31: TEC-LAB-MP-04 | G31: Pesa | H31: Laboratorio de calibracion - Patrones | I31: Accurate Ltd | J31: Láminas | K31: N.I. | L31: 0,5g | M31: N.A | N31: 0,025mg | P31: 0,0083 mg | R31: 1 | T31: N.A | U31: OIML E2 | V31: 12 | W31: 12 | X31: 4 | Y31: Externa | Z31: En Servicio | AA31: 62119 C | AB31: Detecto de Colombia S.A. | AC31: 45318 | AE31: 45701 | AF31: =EDATE(AE31,(V31)) -> 46066 | AH31: =DAYS360(TODAY(),AF31) -> -74 | AI31: =IF(Z31="Fuera de servicio","Fuera de servicio",IF(TODAY()-AF31>0,"OJO EQUIPO VENCIDO",DAYS360(TODAY(),AF31)&" DIAS RESTANTES")) -> OJO EQUIPO VENCIDO | AL31: =VLOOKUP(A31,#REF!,21,FALSE) -> #REF! | AM31: =VLOOKUP(A31,#REF!,23,FALSE) -> #REF! | AN31: =AE31 -> 45701 | AO31: 45701 | AP31: =X31 -> 4 | AQ31: =EDATE(AE31,0) -> 45701 | AR31: =IF(COUNT(AQ31)<AP31,EDATE(AE31,X31),"N/A") -> 45821 | AS31: =IF(COUNT(AQ31:AR31)<AP31,EDATE(AR31,X31),"N/A") -> 45943 | AT31: =IF(COUNT(AQ31:AS31)<AP31,EDATE(AS31,X31),"N/A") -> 46066 | AU31: =IF(COUNT(AQ31:AT31)<AP31,EDATE(AT31,X31),"N/A") -> N/A | AW31: =X31 -> 4 | AX31: =EDATE(AO31,0) -> 45701 | AY31: =IF(COUNT(AX31)<AW31,EDATE(AO31,X31),"N/A") -> 45821 | AZ31: =IF(COUNT(AX31:AY31)<AW31,EDATE(AY31,X31),"N/A") -> 45943 | BA31: =IF(COUNT(AX31:AZ31)<AW31,EDATE(AZ31,X31),"N/A") -> 46066 | BB31: =IF(COUNT(AX31:BA31)<AW31,EDATE(BA31,X31),"N/A") -> N/A
... A39: =IF(D39="Masa",CONCATENATE(F39,"_",L39,"_",K39),F39) -> TEC-LAB-MP-04_50g_N.I. | B39: =AA39 -> 62119 C | C39: Acreditado | D39: Masa | E39: Patron | F39: TEC-LAB-MP-04 | G39: Pesa | H39: Laboratorio de calibracion - Patrones | I39: Accurate Ltd | J39: Láminas/Cilíndricas | K39: N.I. | L39: 50g | M39: N.A | N39: 0,1mg | P39: 0,033 mg | R39: 1 | T39: N.A | U39: OIML E2 | V39: 12 | W39: 12 | X39: 4 | Y39: Externa | Z39: En Servicio | AA39: 62119 C | AB39: Detecto de Colombia S.A. | AC39: 45318 | AE39: 45701 | AF39: =EDATE(AE39,(V39)) -> 46066 | AH39: =DAYS360(TODAY(),AF39) -> -74 | AI39: =IF(Z39="Fuera de servicio","Fuera de servicio",IF(TODAY()-AF39>0,"OJO EQUIPO VENCIDO",DAYS360(TODAY(),AF39)&" DIAS RESTANTES")) -> OJO EQUIPO VENCIDO | AL39: =VLOOKUP(A39,#REF!,21,FALSE) -> #REF! | AM39: =VLOOKUP(A39,#REF!,23,FALSE) -> #REF! | AN39: =AE39 -> 45701 | AO39: 45701 | AP39: =X39 -> 4 | AQ39: =EDATE(AE39,0) -> 45701 | AR39: =IF(COUNT(AQ39)<AP39,EDATE(AE39,X39),"N/A") -> 45821 | AS39: =IF(COUNT(AQ39:AR39)<AP39,EDATE(AR39,X39),"N/A") -> 45943 | AT39: =IF(COUNT(AQ39:AS39)<AP39,EDATE(AS39,X39),"N/A") -> 46066 | AU39: =IF(COUNT(AQ39:AT39)<AP39,EDATE(AT39,X39),"N/A") -> N/A | AW39: =X39 -> 4 | AX39: =EDATE(AO39,0) -> 45701 | AY39: =IF(COUNT(AX39)<AW39,EDATE(AO39,X39),"N/A") -> 45821 | AZ39: =IF(COUNT(AX39:AY39)<AW39,EDATE(AY39,X39),"N/A") -> 45943 | BA39: =IF(COUNT(AX39:AZ39)<AW39,EDATE(AZ39,X39),"N/A") -> 46066 | BB39: =IF(COUNT(AX39:BA39)<AW39,EDATE(BA39,X39),"N/A") -> N/A
A40: =IF(D40="Masa",CONCATENATE(F40,"_",L40,"_",K40),F40) -> TEC-LAB-MP-04_100g_N.I. | B40: =AA40 -> 62119 C | C40: Acreditado | D40: Masa | E40: Patron | F40: TEC-LAB-MP-04 | G40: Pesa | H40: Laboratorio de calibracion - Patrones | I40: Accurate Ltd | J40: Láminas/Cilíndricas | K40: N.I. | L40: 100g | M40: N.A | N40: 0,16mg | P40: 0,053 mg | R40: 1 | T40: N.A | U40: OIML E2 | V40: 12 | W40: 12 | X40: 4 | Y40: Externa | Z40: En Servicio | AA40: 62119 C | AB40: Detecto de Colombia S.A. | AC40: 45318 | AE40: 45701 | AF40: =EDATE(AE40,(V40)) -> 46066 | AH40: =DAYS360(TODAY(),AF40) -> -74 | AI40: =IF(Z40="Fuera de servicio","Fuera de servicio",IF(TODAY()-AF40>0,"OJO EQUIPO VENCIDO",DAYS360(TODAY(),AF40)&" DIAS RESTANTES")) -> OJO EQUIPO VENCIDO | AJ40: Masa Nueva, reemplaza masa original del kit de calibracion. La masa entra en uso a partir de mes de Enero, se adjusta fecha para ser calibrada junto con el resto de masas del Kit. | AL40: =VLOOKUP(A40,#REF!,21,FALSE) -> #REF! | AM40: =VLOOKUP(A40,#REF!,23,FALSE) -> #REF! | AN40: =AE40 -> 45701 | AO40: 45701 | AP40: =X40 -> 4 | AQ40: =EDATE(AE40,0) -> 45701 | AR40: =IF(COUNT(AQ40)<AP40,EDATE(AE40,X40),"N/A") -> 45821 | AS40: =IF(COUNT(AQ40:AR40)<AP40,EDATE(AR40,X40),"N/A") -> 45943 | AT40: =IF(COUNT(AQ40:AS40)<AP40,EDATE(AS40,X40),"N/A") -> 46066 | AU40: =IF(COUNT(AQ40:AT40)<AP40,EDATE(AT40,X40),"N/A") -> N/A | AW40: =X40 -> 4 | AX40: =EDATE(AO40,0) -> 45701 | AY40: =IF(COUNT(AX40)<AW40,EDATE(AO40,X40),"N/A") -> 45821 | AZ40: =IF(COUNT(AX40:AY40)<AW40,EDATE(AY40,X40),"N/A") -> 45943 | BA40: =IF(COUNT(AX40:AZ40)<AW40,EDATE(AZ40,X40),"N/A") -> 46066 | BB40: =IF(COUNT(AX40:BA40)<AW40,EDATE(BA40,X40),"N/A") -> N/A
A41: =IF(D41="Masa",CONCATENATE(F41,"_",L41,"_",K41),F41) -> TEC-LAB-MP-04_200g_N.I. | B41: =AA41 -> 62119 C | C41: Acreditado | D41: Masa | E41: Patron | F41: TEC-LAB-MP-04 | G41: Pesa | H41: Laboratorio de calibracion - Patrones | I41: Accurate Ltd | J41: Láminas/Cilíndricas | K41: N.I. | L41: 200g | M41: N.A | N41: 0,3mg | P41: 0,10 mg | R41: 1 | T41: N.A | U41: OIML E2 | V41: 12 | W41: 12 | X41: 4 | Y41: Externa | Z41: En Servicio | AA41: 62119 C | AB41: Detecto de Colombia S.A. | AC41: 45318 | AE41: 45701 | AF41: =EDATE(AE41,(V41)) -> 46066 | AH41: =DAYS360(TODAY(),AF41) -> -74 | AI41: =IF(Z41="Fuera de servicio","Fuera de servicio",IF(TODAY()-AF41>0,"OJO EQUIPO VENCIDO",DAYS360(TODAY(),AF41)&" DIAS RESTANTES")) -> OJO EQUIPO VENCIDO | AL41: =VLOOKUP(A41,#REF!,21,FALSE) -> #REF! | AM41: =VLOOKUP(A41,#REF!,23,FALSE) -> #REF! | AN41: =AE41 -> 45701 | AO41: 45701 | AP41: =X41 -> 4 | AQ41: =EDATE(AE41,0) -> 45701 | AR41: =IF(COUNT(AQ41)<AP41,EDATE(AE41,X41),"N/A") -> 45821 | AS41: =IF(COUNT(AQ41:AR41)<AP41,EDATE(AR41,X41),"N/A") -> 45943 | AT41: =IF(COUNT(AQ41:AS41)<AP41,EDATE(AS41,X41),"N/A") -> 46066 | AU41: =IF(COUNT(AQ41:AT41)<AP41,EDATE(AT41,X41),"N/A") -> N/A | AW41: =X41 -> 4 | AX41: =EDATE(AO41,0) -> 45701 | AY41: =IF(COUNT(AX41)<AW41,EDATE(AO41,X41),"N/A") -> 45821 | AZ41: =IF(COUNT(AX41:AY41)<AW41,EDATE(AY41,X41),"N/A") -> 45943 | BA41: =IF(COUNT(AX41:AZ41)<AW41,EDATE(AZ41,X41),"N/A") -> 46066 | BB41: =IF(COUNT(AX41:BA41)<AW41,EDATE(BA41,X41),"N/A") -> N/A
A42: =IF(D42="Masa",CONCATENATE(F42,"_",L42,"_",K42),F42) -> TEC-LAB-MP-04_200g_PUNTO | B42: =AA42 -> 62119 C | C42: Acreditado | D42: Masa | E42: Patron | F42: TEC-LAB-MP-04 | G42: Pesa | H42: Laboratorio de calibracion - Patrones | I42: Accurate Ltd | J42: Láminas/Cilíndricas | K42: PUNTO | L42: 200g | M42: N.A | N42: 0,3mg | P42: 0,10 mg | R42: 1 | T42: N.A | U42: OIML E2 | V42: 12 | W42: 12 | X42: 4 | Y42: Externa | Z42: En Servicio | AA42: 62119 C | AB42: Detecto de Colombia S.A. | AC42: 45318 | AE42: 45701 | AF42: =EDATE(AE42,(V42)) -> 46066 | AH42: =DAYS360(TODAY(),AF42) -> -74 | AI42: =IF(Z42="Fuera de servicio","Fuera de servicio",IF(TODAY()-AF42>0,"OJO EQUIPO VENCIDO",DAYS360(TODAY(),AF42)&" DIAS RESTANTES")) -> OJO EQUIPO VENCIDO | AL42: =VLOOKUP(A42,#REF!,21,FALSE) -> #REF! | AM42: =VLOOKUP(A42,#REF!,23,FALSE) -> #REF! | AN42: =AE42 -> 45701 | AO42: 45701 | AP42: =X42 -> 4 | AQ42: =EDATE(AE42,0) -> 45701 | AR42: =IF(COUNT(AQ42)<AP42,EDATE(AE42,X42),"N/A") -> 45821 | AS42: =IF(COUNT(AQ42:AR42)<AP42,EDATE(AR42,X42),"N/A") -> 45943 | AT42: =IF(COUNT(AQ42:AS42)<AP42,EDATE(AS42,X42),"N/A") -> 46066 | AU42: =IF(COUNT(AQ42:AT42)<AP42,EDATE(AT42,X42),"N/A") -> N/A | AW42: =X42 -> 4 | AX42: =EDATE(AO42,0) -> 45701 | AY42: =IF(COUNT(AX42)<AW42,EDATE(AO42,X42),"N/A") -> 45821 | AZ42: =IF(COUNT(AX42:AY42)<AW42,EDATE(AY42,X42),"N/A") -> 45943 | BA42: =IF(COUNT(AX42:AZ42)<AW42,EDATE(AZ42,X42),"N/A") -> 46066 | BB42: =IF(COUNT(AX42:BA42)<AW42,EDATE(BA42,X42),"N/A") -> N/A
A43: =IF(D43="Masa",CONCATENATE(F43,"_",L43,"_",K43),F43) -> TEC-LAB-MP-07_20Kg_No indica | B43: =AA43 -> CAP-1468-24 | C43: Acreditado | D43: Masa | E43: Patron | F43: TEC-LAB-MP-07 | G43: Pesa | H43: Lab.de calibracion - Patrones | I43: Accurate Ltd | J43: Cilíndrica | K43: No indica | L43: 20Kg | M43: N.A | N43: Según NTC 1848 | O43: N.A | P43: 9,9 mg | R43: 1 | T43: N.A | U43: OIML F1 | V43: 19 | W43: 19 | X43: 4 | Y43: Externa | Z43: En Servicio | AA43: CAP-1468-24 | AB43: WR S.A.S | AC43: 44996 | AE43: 45640 | AF43: =EDATE(AE43,(V43)) -> 46217 | AG43: Se rev F quedo en 19 meses | AH43: =DAYS360(TODAY(),AF43) -> 77 | AI43: =IF(Z43="Fuera de servicio","Fuera de servicio",IF(TODAY()-AF43>0,"OJO EQUIPO VENCIDO",DAYS360(TODAY(),AF43)&" DIAS RESTANTES")) -> 77 DIAS RESTANTES | AJ43: Se solicito cotizacion a WR, detecto y colmetro | AL43: =VLOOKUP(A43,#REF!,21,FALSE) -> #REF! | AM43: =VLOOKUP(A43,#REF!,23,FALSE) -> #REF! | AN43: =AE43 -> 45640 | AO43: 45672 | AP43: =X43 -> 4 | AQ43: =EDATE(AE43,0) -> 45640 | AR43: =IF(COUNT(AQ43)<AP43,EDATE(AE43,X43),"N/A") -> 45761 | AS43: =IF(COUNT(AQ43:AR43)<AP43,EDATE(AR43,X43),"N/A") -> 45883 | AT43: =IF(COUNT(AQ43:AS43)<AP43,EDATE(AS43,X43),"N/A") -> 46005 | AU43: =IF(COUNT(AQ43:AT43)<AP43,EDATE(AT43,X43),"N/A") -> N/A | AW43: =X43 -> 4 | AX43: =EDATE(AO43,0) -> 45672 | AY43: =IF(COUNT(AX43)<AW43,EDATE(AO43,X43),"N/A") -> 45792 | AZ43: =IF(COUNT(AX43:AY43)<AW43,EDATE(AY43,X43),"N/A") -> 45915 | BA43: =IF(COUNT(AX43:AZ43)<AW43,EDATE(AZ43,X43),"N/A") -> 46037 | BB43: =IF(COUNT(AX43:BA43)<AW43,EDATE(BA43,X43),"N/A") -> N/A
A44: =IF(D44="Masa",CONCATENATE(F44,"_",L44,"_",K44),F44) -> TEC-LAB-MP-05a_1g a 5kg_No indica | B44: =AA44 -> ALM-228-24 | C44: Acreditado | D44: Masa | E44: Patron | F44: TEC-LAB-MP-05a | G44: Juego de Pesas | H44: Laboratorio de calibracion - Patrones | I44: Detecto | J44: Cilíndrica | K44: No indica | L44: 1g a 5kg | M44: N.A | N44: Según NTC 1848 | O44: N.A | P44: 0,03 mg | R44: 16 | T44: N.A | U44: OIML F1 | V44: 12 | W44: 12 | X44: 4 | Y44: Externa | Z44: Fuera de Servicio En calibración | AA44: ALM-228-24 | AB44: Alpha | AC44: 45129 | AE44: 45514 | AF44: =EDATE(AE44,(V44)) -> 45879 | AG44: Se solicito compra en 2025-06-19 | AH44: =DAYS360(TODAY(),AF44) -> -257 | AI44: =IF(Z44="Fuera de servicio","Fuera de servicio",IF(TODAY()-AF44>0,"OJO EQUIPO VENCIDO",DAYS360(TODAY(),AF44)&" DIAS RESTANTES")) -> OJO EQUIPO VENCIDO | AJ44: Se solicta cotizacion a Avanza 2024-07-15 | AK44: Entregadas a recepcion para despacho a calibracion en Avanza 2024-07-31_ se envio el 2025-08-12 | AL44: =VLOOKUP(A44,#REF!,21,FALSE) -> #REF! | AM44: =VLOOKUP(A44,#REF!,23,FALSE) -> #REF! | AN44: =AE44 -> 45514 | AO44: 45762 | AP44: =X44 -> 4 | AQ44: =EDATE(AE44,0) -> 45514 | AR44: =IF(COUNT(AQ44)<AP44,EDATE(AE44,X44),"N/A") -> 45636 | AS44: =IF(COUNT(AQ44:AR44)<AP44,EDATE(AR44,X44),"N/A") -> 45757 | AT44: =IF(COUNT(AQ44:AS44)<AP44,EDATE(AS44,X44),"N/A") -> 45879 | AU44: =IF(COUNT(AQ44:AT44)<AP44,EDATE(AT44,X44),"N/A") -> N/A | AW44: =X44 -> 4 | AX44: =EDATE(AO44,0) -> 45762 | AY44: =IF(COUNT(AX44)<AW44,EDATE(AO44,X44),"N/A") -> 45884 | AZ44: =IF(COUNT(AX44:AY44)<AW44,EDATE(AY44,X44),"N/A") -> 46006 | BA44: =IF(COUNT(AX44:AZ44)<AW44,EDATE(AZ44,X44),"N/A") -> 46127 | BB44: =IF(COUNT(AX44:BA44)<AW44,EDATE(BA44,X44),"N/A") -> N/A
A45: =IF(D45="Masa",CONCATENATE(F45,"_",L45,"_",K45),F45) -> TEC-LAB-MP-05_1g_No indica | B45: =AA45 -> ALM-228-24 | C45: Acreditado | D45: Masa | E45: Patron | F45: TEC-LAB-MP-05 | G45: Pesa | H45: Laboratorio de calibracion - Patrones | I45: Detecto | J45: Cilíndrica | K45: No indica | L45: 1g | M45: N.A | N45: 0,01mg | P45: 0,03 mg | R45: 1 | T45: N.A | U45: OIML F1 | V45: 12 | W45: 12 | X45: 4 | Y45: Externa | Z45: Fuera de Servicio En calibración | AA45: ALM-228-24 | AB45: Alpha | AC45: 45129 | AE45: 45514 | AF45: =EDATE(AE45,(V45)) -> 45879 | AH45: =DAYS360(TODAY(),AF45) -> -257 | AI45: =IF(Z45="Fuera de servicio","Fuera de servicio",IF(TODAY()-AF45>0,"OJO EQUIPO VENCIDO",DAYS360(TODAY(),AF45)&" DIAS RESTANTES")) -> OJO EQUIPO VENCIDO | AJ45: Se solicta cotizacion a Avanza 2024-07-15 | AK45: Entregadas a recepcion para despacho a calibracion en Avanza 2024-07-31 | AL45: =VLOOKUP(A45,#REF!,21,FALSE) -> #REF! | AM45: =VLOOKUP(A45,#REF!,23,FALSE) -> #REF! | AN45: =AE45 -> 45514 | AO45: 45762 | AP45: =X45 -> 4 | AQ45: =EDATE(AE45,0) -> 45514 | AR45: =IF(COUNT(AQ45)<AP45,EDATE(AE45,X45),"N/A") -> 45636 | AS45: =IF(COUNT(AQ45:AR45)<AP45,EDATE(AR45,X45),"N/A") -> 45757 | AT45: =IF(COUNT(AQ45:AS45)<AP45,EDATE(AS45,X45),"N/A") -> 45879 | AU45: =IF(COUNT(AQ45:AT45)<AP45,EDATE(AT45,X45),"N/A") -> N/A | AW45: =X45 -> 4 | AX45: =EDATE(AO45,0) -> 45762 | AY45: =IF(COUNT(AX45)<AW45,EDATE(AO45,X45),"N/A") -> 45884 | AZ45: =IF(COUNT(AX45:AY45)<AW45,EDATE(AY45,X45),"N/A") -> 46006 | BA45: =IF(COUNT(AX45:AZ45)<AW45,EDATE(AZ45,X45),"N/A") -> 46127 | BB45: =IF(COUNT(AX45:BA45)<AW45,EDATE(BA45,X45),"N/A") -> N/A
A46: =IF(D46="Masa",CONCATENATE(F46,"_",L46,"_",K46),F46) -> TEC-LAB-MP-05_2g_No indica | B46: =AA46 -> ALM-228-24 | C46: Acreditado | D46: Masa | E46: Patron | F46: TEC-LAB-MP-05 | G46: Pesa | H46: Laboratorio de calibracion - Patrones | I46: Detecto | J46: Cilíndrica | K46: No indica | L46: 2g | M46: N.A | N46: 0,01mg | P46: 0,04 mg | R46: 1 | T46: N.A | U46: OIML F1 | V46: 12 | W46: 12 | X46: 4 | Y46: Externa | Z46: Fuera de Servicio En calibración | AA46: ALM-228-24 | AB46: Alpha | AC46: 45129 | AE46: 45514 | AF46: =EDATE(AE46,(V46)) -> 45879 | AH46: =DAYS360(TODAY(),AF46) -> -257 | AI46: =IF(Z46="Fuera de servicio","Fuera de servicio",IF(TODAY()-AF46>0,"OJO EQUIPO VENCIDO",DAYS360(TODAY(),AF46)&" DIAS RESTANTES")) -> OJO EQUIPO VENCIDO | AJ46: Se solicta cotizacion a Avanza 2024-07-15 | AK46: Entregadas a recepcion para despacho a calibracion en Avanza 2024-07-31 | AL46: =VLOOKUP(A46,#REF!,21,FALSE) -> #REF! | AM46: =VLOOKUP(A46,#REF!,23,FALSE) -> #REF! | AN46: =AE46 -> 45514 | AO46: 45762 | AP46: =X46 -> 4 | AQ46: =EDATE(AE46,0) -> 45514 | AR46: =IF(COUNT(AQ46)<AP46,EDATE(AE46,X46),"N/A") -> 45636 | AS46: =IF(COUNT(AQ46:AR46)<AP46,EDATE(AR46,X46),"N/A") -> 45757 | AT46: =IF(COUNT(AQ46:AS46)<AP46,EDATE(AS46,X46),"N/A") -> 45879 | AU46: =IF(COUNT(AQ46:AT46)<AP46,EDATE(AT46,X46),"N/A") -> N/A | AW46: =X46 -> 4 | AX46: =EDATE(AO46,0) -> 45762 | AY46: =IF(COUNT(AX46)<AW46,EDATE(AO46,X46),"N/A") -> 45884 | AZ46: =IF(COUNT(AX46:AY46)<AW46,EDATE(AY46,X46),"N/A") -> 46006 | BA46: =IF(COUNT(AX46:AZ46)<AW46,EDATE(AZ46,X46),"N/A") -> 46127 | BB46: =IF(COUNT(AX46:BA46)<AW46,EDATE(BA46,X46),"N/A") -> N/A
A47: =IF(D47="Masa",CONCATENATE(F47,"_",L47,"_",K47),F47) -> TEC-LAB-MP-05_2g_PUNTO | B47: =AA47 -> ALM-228-24 | C47: Acreditado | D47: Masa | E47: Patron | F47: TEC-LAB-MP-05 | G47: Pesa | H47: Laboratorio de calibracion - Patrones | I47: Detecto | J47: Cilíndrica | K47: PUNTO | L47: 2g | M47: N.A | N47: 0,025mg | P47: 0,04 mg | R47: 1 | T47: N.A | U47: OIML F1 | V47: 12 | W47: 12 | X47: 4 | Y47: Externa | Z47: Fuera de Servicio En calibración | AA47: ALM-228-24 | AB47: Alpha | AC47: 45129 | AE47: 45514 | AF47: =EDATE(AE47,(V47)) -> 45879 | AH47: =DAYS360(TODAY(),AF47) -> -257 | AI47: =IF(Z47="Fuera de servicio","Fuera de servicio",IF(TODAY()-AF47>0,"OJO EQUIPO VENCIDO",DAYS360(TODAY(),AF47)&" DIAS RESTANTES")) -> OJO EQUIPO VENCIDO | AJ47: Se solicta cotizacion a Avanza 2024-07-15 | AK47: Entregadas a recepcion para despacho a calibracion en Avanza 2024-07-31 | AL47: =VLOOKUP(A47,#REF!,21,FALSE) -> #REF! | AM47: =VLOOKUP(A47,#REF!,23,FALSE) -> #REF! | AN47: =AE47 -> 45514 | AO47: 45762 | AP47: =X47 -> 4 | AQ47: =EDATE(AE47,0) -> 45514 | AR47: =IF(COUNT(AQ47)<AP47,EDATE(AE47,X47),"N/A") -> 45636 | AS47: =IF(COUNT(AQ47:AR47)<AP47,EDATE(AR47,X47),"N/A") -> 45757 | AT47: =IF(COUNT(AQ47:AS47)<AP47,EDATE(AS47,X47),"N/A") -> 45879 | AU47: =IF(COUNT(AQ47:AT47)<AP47,EDATE(AT47,X47),"N/A") -> N/A | AW47: =X47 -> 4 | AX47: =EDATE(AO47,0) -> 45762 | AY47: =IF(COUNT(AX47)<AW47,EDATE(AO47,X47),"N/A") -> 45884 | AZ47: =IF(COUNT(AX47:AY47)<AW47,EDATE(AY47,X47),"N/A") -> 46006 | BA47: =IF(COUNT(AX47:AZ47)<AW47,EDATE(AZ47,X47),"N/A") -> 46127 | BB47: =IF(COUNT(AX47:BA47)<AW47,EDATE(BA47,X47),"N/A") -> N/A
A48: =IF(D48="Masa",CONCATENATE(F48,"_",L48,"_",K48),F48) -> TEC-LAB-MP-05_5g_No indica | B48: =AA48 -> ALM-228-24 | C48: Acreditado | D48: Masa | E48: Patron | F48: TEC-LAB-MP-05 | G48: Pesa | H48: Laboratorio de calibracion - Patrones | I48: Detecto | J48: Cilíndrica | K48: No indica | L48: 5g | M48: N.A | N48: 0,1mg | P48: 0,05 mg | R48: 1 | T48: N.A | U48: OIML F1 | V48: 12 | W48: 12 | X48: 4 | Y48: Externa | Z48: Fuera de Servicio En calibración | AA48: ALM-228-24 | AB48: Alpha | AC48: 45129 | AE48: 45514 | AF48: =EDATE(AE48,(V48)) -> 45879 | AH48: =DAYS360(TODAY(),AF48) -> -257 | AI48: =IF(Z48="Fuera de servicio","Fuera de servicio",IF(TODAY()-AF48>0,"OJO EQUIPO VENCIDO",DAYS360(TODAY(),AF48)&" DIAS RESTANTES")) -> OJO EQUIPO VENCIDO | AJ48: Se solicta cotizacion a Avanza 2024-07-15 | AK48: Entregadas a recepcion para despacho a calibracion en Avanza 2024-07-31 | AL48: =VLOOKUP(A48,#REF!,21,FALSE) -> #REF! | AM48: =VLOOKUP(A48,#REF!,23,FALSE) -> #REF! | AN48: =AE48 -> 45514 | AO48: 45762 | AP48: =X48 -> 4 | AQ48: =EDATE(AE48,0) -> 45514 | AR48: =IF(COUNT(AQ48)<AP48,EDATE(AE48,X48),"N/A") -> 45636 | AS48: =IF(COUNT(AQ48:AR48)<AP48,EDATE(AR48,X48),"N/A") -> 45757 | AT48: =IF(COUNT(AQ48:AS48)<AP48,EDATE(AS48,X48),"N/A") -> 45879 | AU48: =IF(COUNT(AQ48:AT48)<AP48,EDATE(AT48,X48),"N/A") -> N/A | AW48: =X48 -> 4 | AX48: =EDATE(AO48,0) -> 45762 | AY48: =IF(COUNT(AX48)<AW48,EDATE(AO48,X48),"N/A") -> 45884 | AZ48: =IF(COUNT(AX48:AY48)<AW48,EDATE(AY48,X48),"N/A") -> 46006 | BA48: =IF(COUNT(AX48:AZ48)<AW48,EDATE(AZ48,X48),"N/A") -> 46127 | BB48: =IF(COUNT(AX48:BA48)<AW48,EDATE(BA48,X48),"N/A") -> N/A
...

Sheet Hoja1
F1: INVENTARIO INSTRUMENTOS DE MEDICIÓN, LC-FR-10 V5
F2: CD389-25
A4: Revisado Director Técnico, 2025-01-23 - Aprobado Gerente General, 2025-01-25
A5: 1+ 4 | B5: 1 | C5: 2 | D5: 3 | E5: 4 | F5: 1 | G5: 2 | H5: 3 | I5: 4 | J5: 5 | K5: 6 | L5: 7 | M5: 8 | N5: 9 | O5: 10 | P5: 11 | Q5: 12 | R5: 13 | S5: 14 | T5: 15 | U5: 16 | V5: 17 | W5: 18 | X5: 19 | Y5: 20 | Z5: 21 | AA5: 22 | AB5: 23 | AC5: 24 | AD5: 25 | AE5: 26 | AF5: 27 | AG5: 28 | AH5: 29
F6: Código | G6: Instrumento / patrón /material de referencia | H6: Ubicación | I6: Fabricante | J6: Modelo | K6: Serie/Lote/ Distintivo | L6: Intervalo de medición / Valor nominal | M6: División de escala | N6: Error maximo permitido | O6: Accuracy | P6: INCERTIDUMBRE (mg) | Q6: Estabilidad | R6: NUMERO DE MASAS / # SENSORES | S6: Uniformidad | T6: Escalón de verificación/Puntos a Calibrar/Intervalo de Calibracion | U6: Clase | V6: Frecuencia de calibración (meses) | W6: Frecuencia de Mtto (meses) | X6: Frecuencia de Verificacion (meses) | Y6: Tipo de calibración | Z6: Estado | AA6: Número del último certificado de calibración | AB6: Calibrado por | AC6: Fecha de la último mantenimiento/ Inicio uso para MRC | AD6: Fecha de la proximo mantenimiento / Inicio uso para MRC | AE6: Fecha de la última calibración | AF6: Fecha próxima calibración /Vencimiento | AG6: Observaciones | AH6: Dias Vigencia | AJ6: Observaciones 2 | AK6: Observaciones 3 | AL6: Frecuencia Inicial | AM6: Frcuencia actual Calculada | AN6: Fcal | AO6: F_Inicio | AP6: Frec Vintermedia en Meses | AQ6: Verif 1 | AR6: Verif 2 | AS6: Verif 3 | AT6: Verif 4 | AU6: Verif 5 | AW6: Frec Vintermedia en Meses | AX6: Verif 1 | AY6: Verif 2 | AZ6: Verif 3 | BA6: Verif 4 | BB6: Verif 5 | BC6: Magnitud
A7: =IF(D7="Masa",CONCATENATE(F7,"_",L7,"_",K7),F7) -> TEC-LAB-BA-03 | B7: =AA7 -> TM461-25A_ TM462-25A | C7: Acreditado | D7: EPFNA | E7: Patron | F7: TEC-LAB-BA-03 | G7: Balanza de precisión | H7: Laboratorio de Volumen | I7: Mettler Toledo | J7: XS205DU | K7: 1128153844 | L7: 0 g a 81 g _ 81 g a 220 g | M7: 0,01 mg_0,1 mg | N7: 0,2 mg | O7: Linealidad: 0,2 mg _ Repetibilidad: 0,01 mg | P7: 0,015 mg | R7: N.A | T7: N.A | U7: 1 | V7: 12 | W7: 12 | X7: 4 | Y7: Interna | Z7: En Servicio | AA7: TM461-25A_ TM462-25A | AB7: TECSERVICE S.A.S | AE7: 45832 | AF7: =EDATE(AE7,(V7)) -> 46197 | AG7: TDNR 9.6.3.411.203 | AH7: =DAYS360(TODAY(),AF7) -> 57 | AI7: =IF(Z7="Fuera de servicio","Fuera de servicio",IF(TODAY()-AF7>0,"OJO EQUIPO VENCIDO",DAYS360(TODAY(),AF7)&" DIAS RESTANTES")) -> 57 DIAS RESTANTES | AJ7: Pendiente Calibracion | AL7: =VLOOKUP(A7,#REF!,21,FALSE) -> #REF! | AM7: =VLOOKUP(A7,#REF!,23,FALSE) -> #REF! | AN7: =AE7 -> 45832 | AO7: 45832 | AP7: =X7 -> 4 | AQ7: =EDATE(AE7,0) -> 45832 | AR7: =IF(COUNT(AQ7)<AP7,EDATE(AE7,X7),"N/A") -> 45954 | AS7: =IF(COUNT(AQ7:AR7)<AP7,EDATE(AR7,X7),"N/A") -> 46077 | AT7: =IF(COUNT(AQ7:AS7)<AP7,EDATE(AS7,X7),"N/A") -> 46197 | AU7: =IF(COUNT(AQ7:AT7)<AP7,EDATE(AT7,X7),"N/A") -> N/A | AW7: =X7 -> 4 | AX7: =EDATE(AO7,0) -> 45832 | AY7: =IF(COUNT(AX7)<AW7,EDATE(AO7,X7),"N/A") -> 45954 | AZ7: =IF(COUNT(AX7:AY7)<AW7,EDATE(AY7,X7),"N/A") -> 46077 | BA7: =IF(COUNT(AX7:AZ7)<AW7,EDATE(AZ7,X7),"N/A") -> 46197 | BB7: =IF(COUNT(AX7:BA7)<AW7,EDATE(BA7,X7),"N/A") -> N/A | BC7: Volumen
